Workbook

Sheet Carátula
C4: REPORTE MENSUAL ENCUBIERTO DISMAC
C12: FEBRERO 2025

Sheet Dimensiones y Pesos
C2: Dimensiones y Pesos
B4: El índice de calidad de Dismac, esta compuesto por una seis dimensiones. Estas a su vez, están conformadas por subdimesiones que paralelamente se descomponen en atributos.
B6: DIMENSIONES | D6: SUBDIMENSIONES | E6: PESOS DIMENSIONES | F6: PESOS ATRIBUTOS | G6: ATRIBUTOS
B8: Atención del Vendedor | C8: 0.42 | D8: PRIMER CONTACTO | E8: 0.25 | F8: 0.3 | G8: El vendedor/a se percató de la presencia del cliente y se aproximó para atenderlo (si tiene otro cliente, no aplica, indique).
F9: 0.3 | G9: El vendedor/a lo saludó amablemente o pregunto en modo de bienvenida (Inicie la conversación)
F10: 0.2 | G10: El vendedor/a pregunta al cliente lo que busca o sus preferencias.
F11: 0.2 | G11: El vendedor/a dirige al cliente a donde debe, según su necesidad
D12: GESTION DE VENTA | E12: 0.4 | F12: 0.06 | G12: El vendedor/a mostró el producto solicitado de forma rápida y sin hacer esperar mucho tiempo al cliente.
F13: 0.07 | G13: El vendedor/a en caso de no disponer del producto en tienda, utilizó la página ecommerce de DISMAC para ofrecer otras opciones al cliente.
F14: 0.06 | G14: El vendedor/a demostró tener conocimiento del producto y proporcionó toda la información (garantía) y especificaciones del mismo.
F15: 0.06 | G15: El vendedor/a mostró diferentes opciones de productos e hizo recomendaciones de acuerdo a sus necesidades.
F16: 0.07 | G16: El vendedor/a le comunicó que Dismac tiene los precios más bajos del mercado y explicó la garantía de precios
F17: 0.06 | G17: El vendedor/a le comunicó sobre las promociones especiales, productos en combo o lanzamientos.
F18: 0.07 | G18: El vendedor/a explicó de qué trata la garantía extendida y sus beneficios
F19: 0.06 | G19: El vendedor/a se esmeró en brindar argumentos para incentivar la compra del producto. (Ej.: Buena calidad, diseño, última tecnología, etc.)
F20: 0.05 | G20: El vendedor/a cerró la venta?
F21: 0.07 | G21: El vendedor/a ofreció y explicó los beneficios del servicio de entrega gratuita, tiempo de entrega, áreas de cobertura.
F22: 0.07 | G22: El vendedor/a ofreció y explicó los beneficios del servicio de instalación garantizada.
F23: 0.07 | G23: El vendedor/a explicó los beneficios de la política de cambios y devoluciones.
F24: 0.06 | G24: El vendedor/a tuvo la capacidad/ habilidad de ofrecer productos ADICIONALES diferentes al que solicitó.
... F27: 0.05 | G27: En caso de interrupción durante la venta, el vendedor le pidió disculpas por la interrupción.
D28: INFORMACIÓN SOBRE LA ENTREGA E INSTALACIÓN DE PRODUCTOS | E28: 0.15 | F28: 0.3333 | G28: El vendedor/a coordinó y programó la entrega a domicilio del producto
F29: 0.3333 | G29: El vendedor/a coordinó y programó la instalación del producto
F30: 0.3333 | G30: El vendedor/a informó y explicó los requisitos previos de instalación del producto
D31: DESPEDIDA | E31: 0.1 | F31: 0.3333 | G31: El vendedor/a le solicitó sus datos personales y en caso de no estar registrado en su sistema, lo registró
F32: 0.3333 | G32: El vendedor/a lo dirigió a caja para efectuar el pago.
F33: 0.3333 | G33: El vendedor/a se despidió amablemente y lo invito a visitar nuevamente la tienda
D34: PRESENTACIÓN PERSONAL DEL VENDEDOR/A | E34: 0.1 | F34: 0.5 | G34: El vendedor/a se encontraba con el uniforme de la empresa.
F35: 0.5 | G35: El vendedor/a tenía buena presencia (El cabello no está en su rostro, está limpio y prolijo)
D36: DISMAC CLUB | E36: 0 | G36: El vendedor/a explicó de qué trata el Dismaclub
B37: Atención en Caja | C37: 0.22 | D37: ATENCIÓN EN CAJA | E37: 0.4 | F37: 0.1429 | G37: El cajero/a saludó amablemente. "Buenos días" "Buen día, en qué puedo ayudarle" "Cómo está"
F38: 0.1429 | G38: El cajero/a respetó el orden de llegada.
F39: 0.1429 | G39: El cajero/a le comunicó sobre el monto a pagar y realizó el proceso de facturación (Pide NIT y explica la implementación de la facturación electrónica, es decir pide los datos al cliente, explica que la factura le llegará por correo o a su teléfono (opcional) y efectivamente la factura le llegó por uno de estos medios).
F40: 0.1429 | G40: El cajero/a entregó la garantía del producto. (Aplica solo en caso de refrigeradores, cocinas, freezers, lavadoras, microondas y Aires Acondicionados)
F41: 0.1429 | G41: El cajero/a lo dirigió o le indicó quien es el encargado de hacer la entrega
F42: 0.1429 | G42: El cajero/a lo atendió con rapidez en el cobro, facturación.
F43: 0.1429 | G43: El cajero agradecio la compra, se despidió amablemente "Hasta luego" "Que tenga un buen día" "Que le vaya bien" y lo invitó a visitar la tienda nuevamente
D44: INFORMACIÓN SOBRE LA ENTREGA E INSTALACIÓN DE PRODUCTOS | E44: 0.2 | F44: 0.25 | G44: El cajero/a validó la fecha de entrega a domicilio del producto
F45: 0.25 | G45: El cajero/a validó la fecha de instalación del producto
F46: 0.25 | G46: El cajero/a validó que el vendedor explicó los requisitos previos de instalacion del producto, que el cliente entiende estos requisitos, y el cajero entregó los requisitos impresos al cliente.
...

Sheet Ficha Metodológica
D2: FICHA METODOLÓGICA
B5: Objetivo General: Auditar la calidad del servicio, productos e infraestructura en las agencias de Dismac. El fin último de la investigación es saber dónde hay que hacer cambios para conseguir mejoras.
B8: MUESTRA | D8: VISITAS | E8: %
B9: Santa Cruz | D9: 26 | E9: =+D9/$D$14 -> 0.52
B10: La Paz | D10: 14 | E10: =+D10/$D$14 -> 0.28
B11: Cochabamba | D11: =SUM(D37:D39) -> 6 | E11: =+D11/$D$14 -> 0.12
B12: Sucre | D12: 2 | E12: =+D12/$D$14 -> 0.04
B13: Tarija | D13: 2 | E13: =+D13/$D$14 -> 0.04
B14: TOTAL | D14: =SUM(D9:D13) -> 50 | E14: =SUM(E9:E13) -> 1
B16: Sucursales Visitadas | D16: Visitas
B17: DISMAC | C17: Cristobal de Mendoza #1055 | D17: 2
C18: Doble Vía entre 5to y 6to anillo | D18: 2
C19: Isabel 1 | D19: 2
C20: Pampa de la Isla | D20: 2
C21: Show Room (P.I.) | D21: 2
C22: Villa 1ero de Mayo | D22: 2
C23: 4to anillo e Isuto | D23: 2
C24: Plan 3000 | D24: 2
C25: Omar Chávez | D25: 2
C26: Av. Cristo Redentor entre 5to y 6to anillo | D26: 2
C27: Montero | D27: 2
C28: Av. Santos Dumont | D28: 2
C29: Isabel 2 | D29: 2
... C41: Tarija | D41: 2
B42: Visitas Totales | D42: =SUM(D17:D41) -> 50

Sheet Reporte General
G2: Reporte Febrero 2025 - Visitas encubiertas DISMAC
G3: Nivel de cumplimiento de protocolos - Bolivia
F7: DIMENSIONES EVALUADAS | G7: SANTA CRUZ | H7: LA PAZ | I7: COCHABAMBA | J7: SUCRE | K7: TARIJA | L7: BOLIVIA | N7: VARIACIÓN (Febrero - Diciembre) | P7: ASPECTOS DE MEJORA
F8: Atención del vendedor | G8: 0.88597891 | H8: 0.75184435 | I8: 0.8615345 | J8: 0.87855787 | K8: 0.91354724 | L8: 0.83311926 | N8: -0.024324675
F9: Atención en caja | G9: 0.91153846 | H9: 0.82857143 | I9: 0.93333333 | J9: 1 | K9: 1 | L9: 0.89114774 | N9: -0.011034799
F10: Atención post pago | G10: 0.95445455 | H10: 0.93326 | I10: 0.74995 | J10: 1 | K10: 1 | L10: 0.87922152 | N10: -0.12067848
F11: Ambiente de la tienda | G11: 0.99358974 | H11: 0.76190476 | I11: 1 | J11: 1 | K11: 1 | L11: 0.91849817 | N11: -0.066124847
F12: Delivery | G12: 1 | H12: 1 | I12: 1 | J12: n/a | K12: n/a | L12: 1 | N12: 0.083333333
F13: Devolución | G13: 1 | H13: 0.97619048 | I13: 1 | J13: 1 | K13: 1 | L13: 0.99206349 | N13: -0.0033068783
F14: Medidas de bioseguridad | G14: n/a | H14: n/a | I14: 0 | J14: 0 | K14: 0 | L14: 0 | N14: n/a
F15: ÍNDICES GENERALES FEBRERO | G15: 0.92665767 | H15: 0.80846731 | I15: 0.90511423 | J15: 0.94899431 | K15: 0.96368984 | L15: 0.88007974 | N15: -0.033043607
F16: ÍNDICES GENERALES DICIEMBRE | G16: 0.94008842 | H16: 0.91086333 | I16: 0.88841828 | J16: 0.94234194 | K16: 0.83623977 | L16: 0.91312334 | N16: -
F17: VARIACIÓN (Diciembre - Noviembre) | G17: -0.013430755 | H17: -0.10239602 | I17: 0.016695956 | J17: 0.0066523662 | K17: 0.12745007 | L17: -0.033043607 | N17: -
F18: CASOS | G18: 26 | H18: 14 | I18: 6 | J18: 2 | K18: 2 | L18: 50 | N18: -
F20: Nota: En rojo los valores más bajos por dimensión. En el caso de Cochabamba y La Paz, el Delivery no pondera la nota. La nota general de Bolivia, no toma en cuenta las notas de Sucre y Tarija en su promedio.
B21: Delivery | C21: 1
B22: Devolución | C22: 0.99206349
B23: Ambiente de la tienda | C23: 0.91849817
B24: Atención en caja | C24: 0.89114774
B25: ÍNDICES GENERALES | C25: 0.88007974
B26: Atención post pago | C26: 0.87922152
B27: Atención del vendedor | C27: 0.83311926
B28: Medidas de bioseguridad | C28: 0
B40: TARIJA | C40: 0.96368984
B41: SUCRE | C41: 0.94899431
B42: SANTA CRUZ | C42: 0.92665767
B43: COCHABAMBA | C43: 0.90511423
... B45: LA PAZ | C45: 0.80846731

Sheet Indices Generales
AE2: Reporte Febrero 2025 - Visitas encubiertas DISMAC
AE3: Índices generales de evaluación
AF5: SANTA CRUZ | AY5: LA PAZ | BJ5: COCHABAMBA | BO5: SUCRE | BP5: TARIJA | BQ5: COMPETENCIA | BW5: ÍNDICES GENERALES
AC7: PESOS | AE7: DIMENSIONES EVALUADAS | AF7: Cristobal de Mendoza #1055 | AG7: Doble Vía entre 5to y 6to anillo | AH7: Grigota 2 | AI7: Isabel 1 | AJ7: Isabel 4 | AK7: Isabel10 | AL7: Montero | AM7: Pampa de la Isla | AN7: Pico de Monte (Piraí) | AO7: Show Room (P.I.) | AP7: Viedma | AQ7: Villa 1ero de Mayo | AR7: 4to anillo e Isuto | AS7: Plan 3000 | AT7: Omar Chávez | AU7: Av. Cristo Redentor | AV7: Av. Santos Dumont | AW7: Doble Vía km13 | AX7: Isabel 2 | AY7: Calacoto Av. Ballivian 1305 | AZ7: E. Salmon 1053 | BA7: El Alto 4 | BB7: El Alto 5 | BC7: L. Barra 617 | BD7: Leon de la B. 743 | BE7: Socabaya | BF7: Obrajes | BG7: Multicine Río Seco | BH7: El Alto Satélite | BI7: El Alto Cruce Villa Adela | BJ7: Av.Pando #1377 | BK7: Nataniel Aguirre 310 | BL7: Ayacucho | BM7: Av. América #459 | BN7: Quillacollo | BO7: Sucre | BP7: Tarija | BQ7: 1er Anillo Brasil (Competencia) | BR7: 4to anillo Equipetrol (Competencia) | BS7: Santos Dumont (Competencia) | BT7: Villa 1ro de mayo (Competencia) | BU7: Pampa de la Isla (Competencia) | BW7: Santa Cruz | BX7: La Paz | BY7: Cochabamba | BZ7: Bolivia
AF8: % | AG8: % | AH8: % | AI8: % | AJ8: % | AK8: % | AL8: % | AM8: % | AN8: % | AO8: % | AP8: % | AQ8: % | AR8: % | AS8: % | AT8: % | AU8: % | AV8: % | AW8: % | AX8: % | AY8: % | AZ8: % | BA8: % | BB8: % | BC8: % | BD8: % | BE8: % | BF8: % | BG8: % | BH8: % | BI8: % | BJ8: % | BK8: % | BL8: % | BM8: % | BN8: % | BO8: % | BP8: % | BQ8: % | BR8: % | BS8: % | BT8: % | BU8: % | BW8: % | BX8: % | BY8: % | BZ8: %
AE10: ÍNDICE GENERAL | AF10: 0.97792679 | AG10: 0.9228767 | AH10: n/a | AI10: 0.93471667 | AJ10: n/a | AK10: n/a | AL10: 0.97661139 | AM10: 0.90143113 | AN10: n/a | AO10: 0.99175371 | AP10: n/a | AQ10: 0.74431765 | AR10: 0.88286524 | AS10: 0.97332429 | AT10: 0.89185959 | AU10: 0.92857143 | AV10: 0.92720076 | AW10: n/a | AX10: 0.99309434 | AY10: 0.73410958 | AZ10: 0.76637353 | BA10: 0.86791248 | BB10: n/a | BC10: n/a | BD10: n/a | BE10: 0.82028938 | BF10: n/a | BG10: 0.73114643 | BH10: 0.89099782 | BI10: 0.84844194 | BJ10: n/a | BK10: n/a | BL10: 0.87619545 | BM10: 0.89836568 | BN10: 0.94078157 | BO10: 0.94899431 | BP10: 0.96368984 | BQ10: n/a | BR10: n/a | BS10: n/a | BT10: n/a | BU10: n/a | BW10: 0.92665767 | BX10: 0.80846731 | BY10: 0.90511423 | BZ10: 0.88007974
AC12: 0.42 | AE12: ATENCIÓN DEL VENDEDOR | AF12: 0.95322581 | AG12: 0.81639929 | AH12: n/a | AI12: 0.84458969 | AJ12: n/a | AK12: n/a | AL12: 0.94433903 | AM12: 0.76533839 | AN12: n/a | AO12: 0.98039216 | AP12: n/a | AQ12: 0.65313725 | AR12: 0.92691622 | AS12: 0.96627451 | AT12: 0.74254902 | AU12: 0.98333333 | AV12: 0.95764706 | AW12: n/a | AX12: 0.98358413 | AY12: 0.6702957 | AZ12: 0.70862745 | BA12: 0.80938596 | BB12: n/a | BC12: n/a | BD12: n/a | BE12: 0.76261994 | BF12: n/a | BG12: 0.6376677 | BH12: 0.81490196 | BI12: 0.85941176 | BJ12: n/a | BK12: n/a | BL12: 0.83617963 | BM12: 0.88939394 | BN12: 0.85902993 | BO12: 0.87855787 | BP12: 0.91354724 | BQ12: n/a | BR12: n/a | BS12: 0 | BT12: 0 | BU12: n/a | BW12: 0.88597891 | BX12: 0.75184435 | BY12: 0.8615345 | BZ12: 0.83311926
AC13: 0.25 | AE13: PRIMER CONTACTO | AF13: 1 | AG13: 1 | AH13: n/a | AI13: 1 | AJ13: n/a | AK13: n/a | AL13: 1 | AM13: 1 | AN13: n/a | AO13: 1 | AP13: n/a | AQ13: 0.85 | AR13: 1 | AS13: 1 | AT13: 0.85 | AU13: 1 | AV13: 1 | AW13: n/a | AX13: 1 | AY13: 0.55 | AZ13: 0.7 | BA13: 0.7 | BB13: n/a | BC13: n/a | BD13: n/a | BE13: 0.7 | BF13: n/a | BG13: 0.6 | BH13: 1 | BI13: 0.85 | BJ13: n/a | BK13: n/a | BL13: 1 | BM13: 1 | BN13: 1 | BO13: 1 | BP13: 1 | BQ13: n/a | BR13: n/a | BS13: n/a | BT13: n/a | BU13: n/a | BW13: 0.97692308 | BX13: 0.72857143 | BY13: 1 | BZ13: 0.9018315
U14: n/a | V14: n/a | W14: n/a | X14: 0.375 | Y14: 0.5 | Z14: 0.42857143 | AA14: n/a | AB14: 0.375 | AC14: 0.3 | AE14: El vendedor/a se percató de la presencia del cliente y se aproximó para atenderlo | AF14: 1 | AG14: 1 | AH14: n/a | AI14: 1 | AJ14: n/a | AK14: n/a | AL14: 1 | AM14: 1 | AN14: n/a | AO14: 1 | AP14: n/a | AQ14: 1 | AR14: 1 | AS14: 1 | AT14: 1 | AU14: 1 | AV14: 1 | AW14: n/a | AX14: 1 | AY14: 0 | AZ14: 0 | BA14: 0.5 | BB14: n/a | BC14: n/a | BD14: n/a | BE14: 0.5 | BF14: n/a | BG14: 0.5 | BH14: 1 | BI14: 0.5 | BJ14: n/a | BK14: n/a | BL14: 1 | BM14: 1 | BN14: 1 | BO14: 1 | BP14: 1 | BQ14: n/a | BR14: n/a | BS14: n/a | BT14: n/a | BU14: n/a | BW14: 1 | BX14: 0.42857143 | BY14: 1 | BZ14: 0.80952381
U15: 0.6 | V15: 0.6 | W15: n/a | X15: 0.375 | Y15: 0.5 | Z15: n/a | AA15: 0.42857143 | AB15: 0.375 | AC15: 0.3 | AE15: El vendedor/a lo saludó amablemente o pregunto en modo de bienvenida | AF15: 1 | AG15: 1 | AH15: n/a | AI15: 1 | AJ15: n/a | AK15: n/a | AL15: 1 | AM15: 1 | AN15: n/a | AO15: 1 | AP15: n/a | AQ15: 0.5 | AR15: 1 | AS15: 1 | AT15: 0.5 | AU15: 1 | AV15: 1 | AW15: n/a | AX15: 1 | AY15: 0.5 | AZ15: 1 | BA15: 0.5 | BB15: n/a | BC15: n/a | BD15: n/a | BE15: 0.5 | BF15: n/a | BG15: 0.5 | BH15: 1 | BI15: 1 | BJ15: n/a | BK15: n/a | BL15: 1 | BM15: 1 | BN15: 1 | BO15: 1 | BP15: 1 | BQ15: n/a | BR15: n/a | BS15: n/a | BT15: n/a | BU15: n/a | BW15: 0.92307692 | BX15: 0.71428571 | BY15: 1 | BZ15: 0.87912088
U16: n/a | V16: 0.4 | W16: 0.5 | X16: 0.25 | Y16: n/a | Z16: 0.28571429 | AA16: 0.28571429 | AB16: n/a | AC16: 0.2 | AE16: El vendedor/a pregunta al cliente lo que busca o sus preferencias. | AF16: 1 | AG16: 1 | AH16: n/a | AI16: 1 | AJ16: n/a | AK16: n/a | AL16: 1 | AM16: 1 | AN16: n/a | AO16: 1 | AP16: n/a | AQ16: 1 | AR16: 1 | AS16: 1 | AT16: 1 | AU16: 1 | AV16: 1 | AW16: n/a | AX16: 1 | AY16: 1 | AZ16: 1 | BA16: 1 | BB16: n/a | BC16: n/a | BD16: n/a | BE16: 1 | BF16: n/a | BG16: 0.5 | BH16: 1 | BI16: 1 | BJ16: n/a | BK16: n/a | BL16: 1 | BM16: 1 | BN16: 1 | BO16: 1 | BP16: 1 | BQ16: n/a | BR16: n/a | BS16: n/a | BT16: n/a | BU16: n/a | BW16: 1 | BX16: 0.92857143 | BY16: 1 | BZ16: 0.97619048
U17: 0.4 | V17: n/a | W17: 0.5 | X17: n/a | Y17: n/a | Z17: 0.28571429 | AA17: 0.28571429 | AB17: 0.25 | AC17: 0.2 | AE17: El vendedor/a dirige al cliente a donde debe, según su necesidad | AF17: 1 | AG17: 1 | AH17: n/a | AI17: 1 | AJ17: n/a | AK17: n/a | AL17: 1 | AM17: 1 | AN17: n/a | AO17: 1 | AP17: n/a | AQ17: 1 | AR17: 1 | AS17: 1 | AT17: 1 | AU17: 1 | AV17: 1 | AW17: n/a | AX17: 1 | AY17: 1 | AZ17: 1 | BA17: 1 | BB17: n/a | BC17: n/a | BD17: n/a | BE17: 1 | BF17: n/a | BG17: 1 | BH17: 1 | BI17: 1 | BJ17: n/a | BK17: n/a | BL17: 1 | BM17: 1 | BN17: 1 | BO17: 1 | BP17: 1 | BQ17: n/a | BR17: n/a | BS17: n/a | BT17: n/a | BU17: n/a | BW17: 1 | BX17: 1 | BY17: 1 | BZ17: 1
AC18: 0.3 | AE18: GESTION DE VENTA | AF18: 0.92473118 | AG18: 0.69318182 | AH18: n/a | AI18: 0.75308642 | AJ18: n/a | AK18: n/a | AL18: 0.88172043 | AM18: 0.54301075 | AN18: n/a | AO18: 1 | AP18: n/a | AQ18: 0.44 | AR18: 0.88636364 | AS18: 0.97 | AT18: 0.63 | AU18: 1 | AV18: 0.91 | AW18: n/a | AX18: 0.96511628 | AY18: 0.62365591 | AZ18: 0.61 | BA18: 0.75263158 | BB18: n/a | BC18: n/a | BD18: n/a | BE18: 0.78723404 | BF18: n/a | BG18: 0.58421053 | BH18: 0.69 | BI18: 0.795 | BJ18: n/a | BK18: n/a | BL18: 0.69354839 | BM18: 0.80681818 | BN18: 0.74210526 | BO18: 0.74193548 | BP18: 0.92045455 | BQ18: 0 | BR18: 0 | BS18: 0 | BT18: 0 | BU18: 0 | BW18: 0.81517004 | BX18: 0.69181887 | BY18: 0.74749061 | BZ18: 0.75149317
A19: 0.068965517 | B19: 0.075 | C19: 0.068181818 | D19: 0.075949367 | E19: 0.08 | F19: 0.073170732 | G19: 0.074074074 | H19: 0.069767442 | I19: 0.074074074 | J19: 0.081081081 | K19: 0.069767442 | L19: 0.068181818 | M19: 0.064516129 | N19: 0.069767442 | O19: n/a | P19: n/a | Q19: 0.06741573 | R19: 0.064516129 | S19: 0.068181818 | T19: n/a | U19: 0.063157895 | V19: 0.063157895 | W19: 0.063829787 | X19: 0.064516129 | Y19: n/a | Z19: 0.073170732 | AA19: 0.068181818 | AB19: 0.064516129 | AC19: 0.06 | AE19: El vendedor/a mostró el producto solicitado de forma rápida y sin hacer esperar mucho tiempo al cliente. | AF19: 1 | AG19: 1 | AH19: n/a | AI19: 1 | AJ19: n/a | AK19: n/a | AL19: 1 | AM19: 1 | AN19: n/a | AO19: 1 | AP19: n/a | AQ19: 1 | AR19: 1 | AS19: 1 | AT19: 1 | AU19: 1 | AV19: 1 | AW19: n/a | AX19: 1 | AY19: 1 | AZ19: 1 | BA19: 1 | BB19: n/a | BC19: n/a | BD19: n/a | BE19: 1 | BF19: n/a | BG19: 1 | BH19: 1 | BI19: 1 | BJ19: n/a | BK19: n/a | BL19: 1 | BM19: 1 | BN19: 1 | BO19: 1 | BP19: 1 | BQ19: n/a | BR19: n/a | BS19: n/a | BT19: n/a | BU19: n/a | BW19: 1 | BX19: 1 | BY19: 1 | BZ19: 1
A20: n/a | B20: n/a | C20: 0.079545455 | D20: n/a | E20: n/a | F20: n/a | G20: 0.086419753 | H20: 0.081395349 | I20: n/a | J20: n/a | K20: n/a | L20: n/a | M20: n/a | N20: 0.081395349 | O20: 0.079545455 | P20: 0.085365854 | Q20: 0.078651685 | R20: 0.075268817 | S20: 0.079545455 | T20: 0.078651685 | U20: 0.073684211 | V20: 0.073684211 | W20: 0.074468085 | X20: 0.075268817 | Y20: 0.074468085 | Z20: 0.085365854 | AA20: 0.079545455 | AB20: 0.075268817 | AC20: 0.07 | AE20: El vendedor/a en caso de no disponer del producto en tienda, utilizó la página ecommerce de DISMAC para ofrecer otras opciones al cliente. | AF20: n/a | AG20: 1 | AH20: n/a | AI20: n/a | AJ20: n/a | AK20: n/a | AL20: n/a | AM20: n/a | AN20: n/a | AO20: 1 | AP20: n/a | AQ20: 1 | AR20: 1 | AS20: 1 | AT20: 1 | AU20: n/a | AV20: 1 | AW20: n/a | AX20: n/a | AY20: n/a | AZ20: 1 | BA20: 0.5 | BB20: n/a | BC20: n/a | BD20: n/a | BE20: 1 | BF20: n/a | BG20: 0 | BH20: 0 | BI20: 1 | BJ20: n/a | BK20: n/a | BL20: n/a | BM20: n/a | BN20: 1 | BO20: 1 | BP20: 1 | BQ20: n/a | BR20: n/a | BS20: n/a | BT20: n/a | BU20: n/a | BW20: 1 | BX20: 0.58333333 | BY20: 1 | BZ20: 0.86111111
A21: 0.068965517 | B21: 0.075 | C21: 0.068181818 | D21: 0.075949367 | E21: 0.08 | F21: 0.073170732 | G21: 0.074074074 | H21: 0.069767442 | I21: 0.074074074 | J21: 0.081081081 | K21: 0.069767442 | L21: 0.068181818 | M21: 0.064516129 | N21: 0.069767442 | O21: 0.068181818 | P21: 0.073170732 | Q21: 0.06741573 | R21: 0.064516129 | S21: 0.068181818 | T21: 0.06741573 | U21: 0.063157895 | V21: 0.063157895 | W21: 0.063829787 | X21: 0.064516129 | Y21: 0.063829787 | Z21: 0.073170732 | AA21: 0.068181818 | AB21: 0.064516129 | AC21: 0.06 | AE21: El vendedor/a demostró tener conocimiento del producto y proporcionó toda la información (garantía) y especificaciones del mismo. | AF21: 1 | AG21: 1 | AH21: n/a | AI21: 1 | AJ21: n/a | AK21: n/a | AL21: 1 | AM21: 1 | AN21: n/a | AO21: 1 | AP21: n/a | AQ21: 1 | AR21: 1 | AS21: 1 | AT21: 1 | AU21: 1 | AV21: 1 | AW21: n/a | AX21: 1 | AY21: 1 | AZ21: 1 | BA21: 0.5 | BB21: n/a | BC21: n/a | BD21: n/a | BE21: 1 | BF21: n/a | BG21: 0 | BH21: 1 | BI21: 1 | BJ21: n/a | BK21: n/a | BL21: 1 | BM21: 1 | BN21: 1 | BO21: 1 | BP21: 1 | BQ21: n/a | BR21: n/a | BS21: n/a | BT21: n/a | BU21: n/a | BW21: 1 | BX21: 0.78571429 | BY21: 1 | BZ21: 0.92857143
A22: 0.068965517 | B22: 0.075 | C22: 0.068181818 | D22: 0.075949367 | E22: 0.08 | F22: 0.073170732 | G22: 0.074074074 | H22: 0.069767442 | I22: 0.074074074 | J22: 0.081081081 | K22: 0.069767442 | L22: 0.068181818 | M22: 0.064516129 | N22: 0.069767442 | O22: 0.068181818 | P22: 0.073170732 | Q22: 0.06741573 | R22: 0.064516129 | S22: 0.068181818 | T22: 0.06741573 | U22: 0.063157895 | V22: 0.063157895 | W22: 0.063829787 | X22: 0.064516129 | Y22: 0.063829787 | Z22: 0.073170732 | AA22: 0.068181818 | AB22: 0.064516129 | AC22: 0.06 | AE22: El vendedor/a mostró diferentes opciones de productos e hizo recomendaciones de acuerdo a sus necesidades. | AF22: 1 | AG22: 1 | AH22: n/a | AI22: 1 | AJ22: n/a | AK22: n/a | AL22: 0.5 | AM22: 0.5 | AN22: n/a | AO22: 1 | AP22: n/a | AQ22: 1 | AR22: 1 | AS22: 1 | AT22: 1 | AU22: 1 | AV22: 1 | AW22: n/a | AX22: 1 | AY22: 1 | AZ22: 1 | BA22: 1 | BB22: n/a | BC22: n/a | BD22: n/a | BE22: 1 | BF22: n/a | BG22: 1 | BH22: 1 | BI22: 1 | BJ22: n/a | BK22: n/a | BL22: 0.5 | BM22: 1 | BN22: 1 | BO22: 1 | BP22: 1 | BQ22: n/a | BR22: n/a | BS22: n/a | BT22: n/a | BU22: n/a | BW22: 0.92307692 | BX22: 1 | BY22: 0.83333333 | BZ22: 0.91880342
A23: 0.08045977 | B23: 0.0875 | C23: 0.079545455 | D23: 0.088607595 | E23: 0.093333333 | F23: 0.085365854 | G23: 0.086419753 | H23: 0.081395349 | I23: 0.086419753 | J23: 0.094594595 | K23: 0.081395349 | L23: 0.079545455 | M23: 0.075268817 | N23: 0.081395349 | O23: 0.079545455 | P23: 0.085365854 | Q23: 0.078651685 | R23: 0.075268817 | S23: 0.079545455 | T23: 0.078651685 | U23: 0.073684211 | V23: 0.073684211 | W23: 0.074468085 | X23: n/a | Y23: 0.074468085 | Z23: 0.085365854 | AA23: 0.079545455 | AB23: 0.075268817 | AC23: 0.07 | AE23: El vendedor/a le comunicó que Dismac tiene los precios más bajos del mercado y explicó la garantía de precios | AF23: 1 | AG23: 0.5 | AH23: n/a | AI23: 0.5 | AJ23: n/a | AK23: n/a | AL23: 1 | AM23: 0.5 | AN23: n/a | AO23: 1 | AP23: n/a | AQ23: 0 | AR23: 1 | AS23: 1 | AT23: 0.5 | AU23: 1 | AV23: 1 | AW23: n/a | AX23: 1 | AY23: 0.5 | AZ23: 0 | BA23: 0.5 | BB23: n/a | BC23: n/a | BD23: n/a | BE23: 0.5 | BF23: n/a | BG23: 0 | BH23: 0.5 | BI23: 0.5 | BJ23: n/a | BK23: n/a | BL23: 0.5 | BM23: 0.5 | BN23: 0.5 | BO23: 0 | BP23: 0.5 | BQ23: n/a | BR23: n/a | BS23: n/a | BT23: n/a | BU23: n/a | BW23: 0.76923077 | BX23: 0.35714286 | BY23: 0.5 | BZ23: 0.54212454
A24: 0.068965517 | B24: 0.075 | C24: 0.068181818 | D24: 0.075949367 | E24: 0.08 | F24: 0.073170732 | G24: 0.074074074 | H24: 0.069767442 | I24: 0.074074074 | J24: 0.081081081 | K24: 0.069767442 | L24: 0.068181818 | M24: 0.064516129 | N24: 0.069767442 | O24: 0.068181818 | P24: 0.073170732 | Q24: 0.06741573 | R24: 0.064516129 | S24: 0.068181818 | T24: 0.06741573 | U24: 0.063157895 | V24: 0.063157895 | W24: 0.063829787 | X24: 0.064516129 | Y24: 0.063829787 | Z24: 0.073170732 | AA24: 0.068181818 | AB24: 0.064516129 | AC24: 0.06 | AE24: El vendedor/a le comunicó sobre las promociones especiales, productos en combo, descuentos o lanzamientos. | AF24: 1 | AG24: 0.5 | AH24: n/a | AI24: 1 | AJ24: n/a | AK24: n/a | AL24: 1 | AM24: 0.5 | AN24: n/a | AO24: 1 | AP24: n/a | AQ24: 0.5 | AR24: 1 | AS24: 1 | AT24: 0.5 | AU24: 1 | AV24: 1 | AW24: n/a | AX24: 1 | AY24: 0.5 | AZ24: 0.5 | BA24: 0.5 | BB24: n/a | BC24: n/a | BD24: n/a | BE24: 0.5 | BF24: n/a | BG24: 0.5 | BH24: 0.5 | BI24: 0.5 | BJ24: n/a | BK24: n/a | BL24: 0.5 | BM24: 1 | BN24: 1 | BO24: 0.5 | BP24: 1 | BQ24: n/a | BR24: n/a | BS24: n/a | BT24: n/a | BU24: n/a | BW24: 0.84615385 | BX24: 0.5 | BY24: 0.83333333 | BZ24: 0.72649573
A25: 0.08045977 | B25: 0.0875 | C25: 0.079545455 | D25: 0.088607595 | E25: 0.093333333 | F25: 0.085365854 | G25: 0.086419753 | H25: 0.081395349 | I25: 0.086419753 | J25: 0.094594595 | K25: 0.081395349 | L25: 0.079545455 | M25: 0.075268817 | N25: 0.081395349 | O25: 0.079545455 | P25: 0.085365854 | Q25: 0.078651685 | R25: 0.075268817 | S25: 0.079545455 | T25: 0.078651685 | U25: 0.073684211 | V25: 0.073684211 | W25: 0.074468085 | X25: 0.075268817 | Y25: 0.074468085 | Z25: 0.085365854 | AA25: 0.079545455 | AB25: 0.075268817 | AC25: 0.07 | AE25: El vendedor/a explicó de qué trata la garantía extendida y sus beneficios | AF25: 0.5 | AG25: 0.5 | AH25: n/a | AI25: 0.5 | AJ25: n/a | AK25: n/a | AL25: 1 | AM25: 0.5 | AN25: n/a | AO25: 1 | AP25: n/a | AQ25: 0 | AR25: 0.5 | AS25: 1 | AT25: 0.5 | AU25: 1 | AV25: 0.5 | AW25: n/a | AX25: 1 | AY25: 0.5 | AZ25: 0.5 | BA25: 0.5 | BB25: n/a | BC25: n/a | BD25: n/a | BE25: 1 | BF25: n/a | BG25: 0 | BH25: 0.5 | BI25: 0 | BJ25: n/a | BK25: n/a | BL25: 1 | BM25: 1 | BN25: 0.5 | BO25: 0.5 | BP25: 1 | BQ25: n/a | BR25: n/a | BS25: n/a | BT25: n/a | BU25: n/a | BW25: 0.65384615 | BX25: 0.42857143 | BY25: 0.83333333 | BZ25: 0.63858364
A26: 0.068965517 | B26: 0.075 | C26: 0.068181818 | D26: 0.075949367 | E26: 0.08 | F26: 0.073170732 | G26: 0.074074074 | H26: 0.069767442 | I26: 0.074074074 | J26: 0.081081081 | K26: 0.069767442 | L26: 0.068181818 | M26: 0.064516129 | N26: 0.069767442 | O26: 0.068181818 | P26: 0.073170732 | Q26: 0.06741573 | R26: 0.064516129 | S26: 0.068181818 | T26: 0.06741573 | U26: 0.063157895 | V26: 0.063157895 | W26: 0.063829787 | X26: 0.064516129 | Y26: 0.063829787 | Z26: 0.073170732 | AA26: 0.068181818 | AB26: 0.064516129 | AC26: 0.06 | AE26: El vendedor/a se esmeró en brindar argumentos para incentivar la compra del producto. | AF26: 1 | AG26: 1 | AH26: n/a | AI26: 1 | AJ26: n/a | AK26: n/a | AL26: 1 | AM26: 0.5 | AN26: n/a | AO26: 1 | AP26: n/a | AQ26: 1 | AR26: 0.5 | AS26: 0.5 | AT26: 0.5 | AU26: 1 | AV26: 1 | AW26: n/a | AX26: 1 | AY26: 1 | AZ26: 0.5 | BA26: 1 | BB26: n/a | BC26: n/a | BD26: n/a | BE26: 0.5 | BF26: n/a | BG26: 1 | BH26: 1 | BI26: 1 | BJ26: n/a | BK26: n/a | BL26: 0.5 | BM26: 1 | BN26: 1 | BO26: 1 | BP26: 1 | BQ26: n/a | BR26: n/a | BS26: n/a | BT26: n/a | BU26: n/a | BW26: 0.84615385 | BX26: 0.85714286 | BY26: 0.83333333 | BZ26: 0.84554335
A27: 0.057471264 | B27: 0.0625 | C27: 0.056818182 | D27: 0.063291139 | E27: 0.066666667 | F27: 0.06097561 | G27: 0.061728395 | H27: 0.058139535 | I27: 0.061728395 | J27: 0.067567568 | K27: 0.058139535 | L27: 0.056818182 | M27: 0.053763441 | N27: 0.058139535 | O27: 0.056818182 | P27: 0.06097561 | Q27: 0.056179775 | R27: 0.053763441 | S27: 0.056818182 | T27: 0.056179775 | U27: 0.052631579 | V27: 0.052631579 | W27: 0.053191489 | X27: 0.053763441 | Y27: 0.053191489 | Z27: 0.06097561 | AA27: 0.056818182 | AB27: 0.053763441 | AC27: 0.05 | AE27: El vendedor/a cerró la venta | AF27: 1 | AG27: 1 | AH27: n/a | AI27: 1 | AJ27: n/a | AK27: n/a | AL27: 1 | AM27: 1 | AN27: n/a | AO27: 1 | AP27: n/a | AQ27: 1 | AR27: 1 | AS27: 1 | AT27: 1 | AU27: 1 | AV27: 1 | AW27: n/a | AX27: 1 | AY27: 1 | AZ27: 1 | BA27: 1 | BB27: n/a | BC27: n/a | BD27: n/a | BE27: 1 | BF27: n/a | BG27: 1 | BH27: 1 | BI27: 1 | BJ27: n/a | BK27: n/a | BL27: 1 | BM27: 1 | BN27: 1 | BO27: 1 | BP27: 1 | BQ27: n/a | BR27: n/a | BS27: n/a | BT27: n/a | BU27: n/a | BW27: 1 | BX27: 1 | BY27: 1 | BZ27: 1
A28: 0.08045977 | B28: 0.0875 | C28: n/a | D28: n/a | E28: 0.093333333 | F28: 0.085365854 | G28: n/a | H28: n/a | I28: 0.086419753 | J28: n/a | K28: 0.081395349 | L28: 0.079545455 | M28: 0.075268817 | N28: n/a | O28: 0.079545455 | P28: 0.085365854 | Q28: 0.078651685 | R28: 0.075268817 | S28: 0.079545455 | T28: 0.078651685 | U28: 0.073684211 | V28: 0.073684211 | W28: 0.074468085 | X28: 0.075268817 | Y28: 0.074468085 | Z28: 0.085365854 | AA28: 0.079545455 | AB28: 0.075268817 | AC28: 0.07 | AE28: El vendedor/a ofreció y explicó los beneficios del servicio de entrega gratuita, tiempo de entrega, áreas de cobertura. | AF28: 1 | AG28: 0 | AH28: n/a | AI28: 1 | AJ28: n/a | AK28: n/a | AL28: 1 | AM28: 0 | AN28: n/a | AO28: 1 | AP28: n/a | AQ28: 0 | AR28: 1 | AS28: 1 | AT28: 0 | AU28: 1 | AV28: 1 | AW28: n/a | AX28: 1 | AY28: 1 | AZ28: 1 | BA28: 1 | BB28: n/a | BC28: n/a | BD28: n/a | BE28: 1 | BF28: n/a | BG28: 1 | BH28: 1 | BI28: 1 | BJ28: n/a | BK28: n/a | BL28: 1 | BM28: 0.5 | BN28: 0 | BO28: 1 | BP28: 1 | BQ28: n/a | BR28: n/a | BS28: n/a | BT28: n/a | BU28: n/a | BW28: 0.69230769 | BX28: 1 | BY28: 0.5 | BZ28: 0.73076923
A29: 0.08045977 | B29: n/a | C29: 0.079545455 | D29: n/a | E29: n/a | F29: 0.085365854 | G29: n/a | H29: n/a | I29: n/a | J29: n/a | K29: n/a | L29: 0.079545455 | M29: 0.075268817 | N29: n/a | O29: 0.079545455 | P29: n/a | Q29: 0.078651685 | R29: 0.075268817 | S29: 0.079545455 | T29: 0.078651685 | U29: 0.073684211 | V29: 0.073684211 | W29: 0.074468085 | X29: 0.075268817 | Y29: 0.074468085 | Z29: n/a | AA29: n/a | AB29: n/a | AC29: 0.07 | AE29: El vendedor/a ofreció y explicó los beneficios del servicio de instalación garantizada. | AF29: 1 | AG29: n/a | AH29: n/a | AI29: n/a | AJ29: n/a | AK29: n/a | AL29: 1 | AM29: 0 | AN29: n/a | AO29: 1 | AP29: n/a | AQ29: 0 | AR29: n/a | AS29: 1 | AT29: 0 | AU29: 1 | AV29: 1 | AW29: n/a | AX29: n/a | AY29: 1 | AZ29: 1 | BA29: 1 | BB29: n/a | BC29: n/a | BD29: n/a | BE29: 1 | BF29: n/a | BG29: 1 | BH29: 0 | BI29: 1 | BJ29: n/a | BK29: n/a | BL29: 1 | BM29: 1 | BN29: 0 | BO29: n/a | BP29: n/a | BQ29: n/a | BR29: n/a | BS29: n/a | BT29: n/a | BU29: n/a | BW29: 0.66666667 | BX29: 0.85714286 | BY29: 0.66666667 | BZ29: 0.73015873
A30: 0.08045977 | B30: 0.0875 | C30: 0.079545455 | D30: 0.088607595 | E30: 0.093333333 | F30: 0.085365854 | G30: 0.086419753 | H30: 0.081395349 | I30: 0.086419753 | J30: 0.094594595 | K30: 0.081395349 | L30: 0.079545455 | M30: 0.075268817 | N30: 0.081395349 | O30: 0.079545455 | P30: 0.085365854 | Q30: 0.078651685 | R30: 0.075268817 | S30: 0.079545455 | T30: 0.078651685 | U30: 0.073684211 | V30: 0.073684211 | W30: 0.074468085 | X30: 0.075268817 | Y30: 0.074468085 | Z30: 0.085365854 | AA30: 0.079545455 | AB30: 0.075268817 | AC30: 0.07 | AE30: El vendedor/a explicó los beneficios de la política de cambios y devoluciones. | AF30: 0.5 | AG30: 0.5 | AH30: n/a | AI30: 0.5 | AJ30: n/a | AK30: n/a | AL30: 1 | AM30: 0.5 | AN30: n/a | AO30: 1 | AP30: n/a | AQ30: 0 | AR30: 0.5 | AS30: 1 | AT30: 0.5 | AU30: 1 | AV30: 1 | AW30: n/a | AX30: 1 | AY30: 0 | AZ30: 0 | BA30: 0.5 | BB30: n/a | BC30: n/a | BD30: n/a | BE30: 0 | BF30: n/a | BG30: 1 | BH30: 0.5 | BI30: 0.5 | BJ30: n/a | BK30: n/a | BL30: 0 | BM30: 0.5 | BN30: 0.5 | BO30: 0 | BP30: 1 | BQ30: n/a | BR30: n/a | BS30: n/a | BT30: n/a | BU30: n/a | BW30: 0.69230769 | BX30: 0.35714286 | BY30: 0.33333333 | BZ30: 0.46092796
A31: n/a | B31: n/a | C31: 0.068181818 | D31: 0.075949367 | E31: n/a | F31: n/a | G31: 0.074074074 | H31: 0.069767442 | I31: 0.074074074 | J31: 0.081081081 | K31: 0.069767442 | L31: 0.068181818 | M31: 0.064516129 | N31: 0.069767442 | O31: n/a | P31: 0.073170732 | Q31: n/a | R31: 0.064516129 | S31: 0.068181818 | T31: 0.06741573 | U31: 0.063157895 | V31: 0.063157895 | W31: n/a | X31: 0.064516129 | Y31: 0.063829787 | Z31: n/a | AA31: 0.068181818 | AB31: 0.064516129 | AC31: 0.06 | AE31: El vendedor/a preguntó, si necesitaba algo más, o tuvo la capacidad/ habilidad de ofrecer productos ADICIONALES diferentes al que solicitó | AF31: 1 | AG31: 0.5 | AH31: n/a | AI31: 0 | AJ31: n/a | AK31: n/a | AL31: 0.5 | AM31: 0.5 | AN31: n/a | AO31: 1 | AP31: n/a | AQ31: 0 | AR31: 1 | AS31: 1 | AT31: 0.5 | AU31: 1 | AV31: 0.5 | AW31: n/a | AX31: 0.5 | AY31: 0 | AZ31: 0 | BA31: 1 | BB31: n/a | BC31: n/a | BD31: n/a | BE31: n/a | BF31: n/a | BG31: 0 | BH31: 1 | BI31: 1 | BJ31: n/a | BK31: n/a | BL31: 0.5 | BM31: 0.5 | BN31: 1 | BO31: 1 | BP31: 1 | BQ31: n/a | BR31: n/a | BS31: n/a | BT31: n/a | BU31: n/a | BW31: 0.61538462 | BX31: 0.5 | BY31: 0.66666667 | BZ31: 0.59401709
A32: 0.08045977 | B32: 0.0875 | C32: 0.079545455 | D32: 0.088607595 | E32: 0.093333333 | F32: 0.085365854 | G32: 0.086419753 | H32: 0.081395349 | I32: 0.086419753 | J32: 0.094594595 | K32: 0.081395349 | L32: 0.079545455 | M32: 0.075268817 | N32: 0.081395349 | O32: 0.079545455 | P32: 0.085365854 | Q32: 0.078651685 | R32: n/a | S32: n/a | T32: 0.078651685 | U32: 0.073684211 | V32: 0.073684211 | W32: 0.074468085 | X32: 0.075268817 | Y32: 0.074468085 | Z32: 0.085365854 | AA32: 0.079545455 | AB32: 0.075268817 | AC32: 0.07 | AE32: El vendedor/a consultó el método de pago y ofreció MINICUOTAS | AF32: 1 | AG32: 0.5 | AH32: n/a | AI32: 0.5 | AJ32: n/a | AK32: n/a | AL32: 1 | AM32: 0.5 | AN32: n/a | AO32: 1 | AP32: n/a | AQ32: 0 | AR32: 1 | AS32: 1 | AT32: 0.5 | AU32: 1 | AV32: 1 | AW32: n/a | AX32: 1 | AY32: 0 | AZ32: 0 | BA32: 0.5 | BB32: n/a | BC32: n/a | BD32: n/a | BE32: 0.5 | BF32: n/a | BG32: 0.5 | BH32: 0.5 | BI32: 0.5 | BJ32: n/a | BK32: n/a | BL32: 0.5 | BM32: 0.5 | BN32: 1 | BO32: 0.5 | BP32: 0.5 | BQ32: n/a | BR32: n/a | BS32: n/a | BT32: n/a | BU32: n/a | BW32: 0.76923077 | BX32: 0.35714286 | BY32: 0.66666667 | BZ32: 0.5976801
A33: 0.057471264 | B33: 0.0625 | C33: 0.056818182 | D33: 0.063291139 | E33: 0.066666667 | F33: 0.06097561 | G33: 0.061728395 | H33: 0.058139535 | I33: 0.061728395 | J33: 0.067567568 | K33: 0.058139535 | L33: 0.056818182 | M33: 0.053763441 | N33: 0.058139535 | O33: 0.056818182 | P33: 0.06097561 | Q33: 0.056179775 | R33: 0.053763441 | S33: 0.056818182 | T33: 0.056179775 | U33: 0.052631579 | V33: n/a | W33: 0.053191489 | X33: 0.053763441 | Y33: 0.053191489 | Z33: 0.06097561 | AA33: 0.056818182 | AB33: 0.053763441 | AC33: 0.05 | AE33: El vendedor/a demostró actitud de servicio, amabilidad y cortesía en el trato | AF33: 1 | AG33: 1 | AH33: n/a | AI33: 1 | AJ33: n/a | AK33: n/a | AL33: 1 | AM33: 0.5 | AN33: n/a | AO33: 1 | AP33: n/a | AQ33: 1 | AR33: 1 | AS33: 1 | AT33: 1 | AU33: 1 | AV33: 1 | AW33: n/a | AX33: 1 | AY33: 1 | AZ33: 1 | BA33: 1 | BB33: n/a | BC33: n/a | BD33: n/a | BE33: 1 | BF33: n/a | BG33: 1 | BH33: 1 | BI33: 1 | BJ33: n/a | BK33: n/a | BL33: 0.5 | BM33: 1 | BN33: 1 | BO33: 1 | BP33: 1 | BQ33: n/a | BR33: n/a | BS33: n/a | BT33: n/a | BU33: n/a | BW33: 0.96153846 | BX33: 1 | BY33: 0.83333333 | BZ33: 0.93162393
A34: 0.057471264 | B34: 0.0625 | C34: n/a | D34: 0.063291139 | E34: n/a | F34: n/a | G34: n/a | H34: 0.058139535 | I34: n/a | J34: n/a | K34: 0.058139535 | L34: n/a | M34: 0.053763441 | N34: 0.058139535 | O34: 0.056818182 | P34: n/a | Q34: n/a | R34: 0.053763441 | S34: n/a | T34: n/a | U34: n/a | V34: 0.052631579 | W34: 0.053191489 | X34: 0.053763441 | Y34: 0.053191489 | Z34: n/a | AA34: n/a | AB34: 0.053763441 | AC34: 0.05 | AE34: En caso de interrupción durante la visita, el vendedor le pidió disculpas por la interrupción. | AF34: 1 | AG34: n/a | AH34: n/a | AI34: n/a | AJ34: n/a | AK34: n/a | AL34: 0 | AM34: 1 | AN34: n/a | AO34: 1 | AP34: n/a | AQ34: 0 | AR34: n/a | AS34: 1 | AT34: 1 | AU34: n/a | AV34: 0.5 | AW34: n/a | AX34: 1 | AY34: 0 | AZ34: 0.5 | BA34: n/a | BB34: n/a | BC34: n/a | BD34: n/a | BE34: 1 | BF34: n/a | BG34: n/a | BH34: 1 | BI34: 1 | BJ34: n/a | BK34: n/a | BL34: 1 | BM34: n/a | BN34: n/a | BO34: 1 | BP34: n/a | BQ34: n/a | BR34: n/a | BS34: n/a | BT34: n/a | BU34: n/a | BW34: 0.72222222 | BX34: 0.7 | BY34: 1 | BZ34: 0.80740741
AC35: n/a | AE35: DISMAC CLUB - El vendedor/a explicó de qué trata el Dismaclub | AF35: n/a | AG35: n/a | AH35: n/a | AI35: n/a | AJ35: n/a | AK35: n/a | AL35: n/a | AM35: n/a | AN35: n/a | AO35: n/a | AP35: n/a | AQ35: n/a | AR35: n/a | AS35: n/a | AT35: n/a | AU35: n/a | AV35: n/a | AW35: n/a | AX35: n/a | AY35: n/a | AZ35: n/a | BA35: n/a | BB35: n/a | BC35: n/a | BD35: n/a | BE35: n/a | BF35: n/a | BG35: n/a | BH35: n/a | BI35: n/a | BJ35: n/a | BK35: n/a | BL35: n/a | BM35: n/a | BN35: n/a | BO35: n/a | BP35: n/a | BQ35: n/a | BR35: n/a | BS35: n/a | BT35: n/a | BU35: n/a | BW35: n/a | BX35: n/a | BY35: n/a | BZ35: n/a
A36: 1 | B36: 1 | C36: 1 | D36: 1 | E36: 1 | F36: 1 | G36: 1 | H36: 1 | I36: 1 | J36: 1 | K36: 1 | L36: 1 | M36: 1 | N36: 1 | O36: 1 | P36: 1 | Q36: 1 | R36: 1 | S36: 1 | T36: 1 | U36: 1 | V36: 1 | W36: 1 | X36: 1 | Y36: 1 | Z36: 1 | AA36: 1 | AB36: 1 | AC36: 0.15 | AE36: INFORMACIÓN SOBRE LA INSTALACIÓN | AF36: 1 | AG36: n/a | AH36: n/a | AI36: n/a | AJ36: n/a | AK36: n/a | AL36: n/a | AM36: n/a | AN36: n/a | AO36: n/a | AP36: n/a | AQ36: n/a | AR36: n/a | AS36: n/a | AT36: n/a | AU36: 1 | AV36: n/a | AW36: n/a | AX36: n/a | AY36: 1 | AZ36: n/a | BA36: 1 | BB36: n/a | BC36: n/a | BD36: n/a | BE36: n/a | BF36: n/a | BG36: n/a | BH36: n/a | BI36: n/a | BJ36: n/a | BK36: n/a | BL36: n/a | BM36: 1 | BN36: n/a | BO36: n/a | BP36: n/a | BQ36: n/a | BR36: n/a | BS36: n/a | BT36: n/a | BU36: n/a | BW36: 1 | BX36: 1 | BY36: 1 | BZ36: 1
AC37: 0.3333 | AE37: El vendedor/a coordinó y programó la entrega a domicilio del producto | AF37: 1 | AG37: n/a | AH37: n/a | AI37: n/a | AJ37: n/a | AK37: n/a | AL37: n/a | AM37: n/a | AN37: n/a | AO37: n/a | AP37: n/a | AQ37: n/a | AR37: n/a | AS37: n/a | AT37: n/a | AU37: 1 | AV37: n/a | AW37: n/a | AX37: n/a | AY37: 1 | AZ37: n/a | BA37: 1 | BB37: n/a | BC37: n/a | BD37: n/a | BE37: n/a | BF37: n/a | BG37: n/a | BH37: n/a | BI37: n/a | BJ37: n/a | BK37: n/a | BL37: n/a | BM37: 1 | BN37: n/a | BO37: n/a | BP37: n/a | BQ37: n/a | BR37: n/a | BS37: n/a | BT37: n/a | BU37: n/a | BW37: 1 | BX37: 1 | BY37: 1 | BZ37: 1
AC38: 0.3333 | AE38: El vendedor/a coordinó y programó la instalación del producto | AF38: 1 | AG38: n/a | AH38: n/a | AI38: n/a | AJ38: n/a | AK38: n/a | AL38: n/a | AM38: n/a | AN38: n/a | AO38: n/a | AP38: n/a | AQ38: n/a | AR38: n/a | AS38: n/a | AT38: n/a | AU38: 1 | AV38: n/a | AW38: n/a | AX38: n/a | AY38: n/a | AZ38: n/a | BA38: 1 | BB38: n/a | BC38: n/a | BD38: n/a | BE38: n/a | BF38: n/a | BG38: n/a | BH38: n/a | BI38: n/a | BJ38: n/a | BK38: n/a | BL38: n/a | BM38: n/a | BN38: n/a | BO38: n/a | BP38: n/a | BQ38: n/a | BR38: n/a | BS38: n/a | BT38: n/a | BU38: n/a | BW38: 1 | BX38: 1 | BY38: n/a | BZ38: 1
AC39: 0.3333 | AE39: El vendedor/a informó y explicó los requisitos previos de instalación del producto | AF39: 1 | AG39: n/a | AH39: n/a | AI39: n/a | AJ39: n/a | AK39: n/a | AL39: n/a | AM39: n/a | AN39: n/a | AO39: n/a | AP39: n/a | AQ39: n/a | AR39: n/a | AS39: n/a | AT39: n/a | AU39: 1 | AV39: n/a | AW39: n/a | AX39: n/a | AY39: n/a | AZ39: n/a | BA39: 1 | BB39: n/a | BC39: n/a | BD39: n/a | BE39: n/a | BF39: n/a | BG39: n/a | BH39: n/a | BI39: n/a | BJ39: n/a | BK39: n/a | BL39: n/a | BM39: 1 | BN39: n/a | BO39: n/a | BP39: n/a | BQ39: n/a | BR39: n/a | BS39: n/a | BT39: n/a | BU39: n/a | BW39: 1 | BX39: 1 | BY39: 1 | BZ39: 1
AC40: 0.1 | AE40: DESPEDIDA | AF40: 0.83333333 | AG40: 0.66666667 | AH40: n/a | AI40: 0.66666667 | AJ40: n/a | AK40: n/a | AL40: 1 | AM40: 0.83333333 | AN40: n/a | AO40: 0.83333333 | AP40: n/a | AQ40: 0.66666667 | AR40: 0.83333333 | AS40: 0.83333333 | AT40: 0.66666667 | AU40: 0.83333333 | AV40: 1 | AW40: n/a | AX40: 1 | AY40: 0.33333333 | AZ40: 0.83333333 | BA40: 0.83333333 | BB40: n/a | BC40: n/a | BD40: n/a | BE40: 0.83333333 | BF40: n/a | BG40: 0.83333333 | BH40: 0.66666667 | BI40: 1 | BJ40: n/a | BK40: n/a | BL40: 0.83333333 | BM40: 0.66666667 | BN40: 0.83333333 | BO40: 1 | BP40: 0.83333333 | BQ40: n/a | BR40: n/a | BS40: n/a | BT40: n/a | BU40: n/a | BW40: 0.82051282 | BX40: 0.76190476 | BY40: 0.77777778 | BZ40: 0.78673179
AC41: 0.3333 | AE41: El vendedor/a le solicitó sus datos personales y en caso de no estar registrado en su sistema, lo registró | AF41: 0.5 | AG41: 0.5 | AH41: n/a | AI41: 0.5 | AJ41: n/a | AK41: n/a | AL41: 1 | AM41: 0.5 | AN41: n/a | AO41: 0.5 | AP41: n/a | AQ41: 0.5 | AR41: 0.5 | AS41: 0.5 | AT41: 0.5 | AU41: 0.5 | AV41: 1 | AW41: n/a | AX41: 1 | AY41: 0.5 | AZ41: 0.5 | BA41: 0.5 | BB41: n/a | BC41: n/a | BD41: n/a | BE41: 0.5 | BF41: n/a | BG41: 0.5 | BH41: 0.5 | BI41: 1 | BJ41: n/a | BK41: n/a | BL41: 1 | BM41: 0.5 | BN41: 0.5 | BO41: 1 | BP41: 0.5 | BQ41: n/a | BR41: n/a | BS41: n/a | BT41: n/a | BU41: n/a | BW41: 0.61538462 | BX41: 0.57142857 | BY41: 0.66666667 | BZ41: 0.61782662
AC42: 0.3333 | AE42: El vendedor/a lo dirigió a caja para efectuar el pago. | AF42: 1 | AG42: 1 | AH42: n/a | AI42: 1 | AJ42: n/a | AK42: n/a | AL42: 1 | AM42: 1 | AN42: n/a | AO42: 1 | AP42: n/a | AQ42: 1 | AR42: 1 | AS42: 1 | AT42: 1 | AU42: 1 | AV42: 1 | AW42: n/a | AX42: 1 | AY42: 0 | AZ42: 1 | BA42: 1 | BB42: n/a | BC42: n/a | BD42: n/a | BE42: 1 | BF42: n/a | BG42: 1 | BH42: 1 | BI42: 1 | BJ42: n/a | BK42: n/a | BL42: 1 | BM42: 1 | BN42: 1 | BO42: 1 | BP42: 1 | BQ42: n/a | BR42: n/a | BS42: n/a | BT42: n/a | BU42: n/a | BW42: 1 | BX42: 0.85714286 | BY42: 1 | BZ42: 0.95238095
AC43: 0.3333 | AE43: El vendedor/a se despidió amablemente y lo invito a visitar nuevamente la tienda | AF43: 1 | AG43: 0.5 | AH43: n/a | AI43: 0.5 | AJ43: n/a | AK43: n/a | AL43: 1 | AM43: 1 | AN43: n/a | AO43: 1 | AP43: n/a | AQ43: 0.5 | AR43: 1 | AS43: 1 | AT43: 0.5 | AU43: 1 | AV43: 1 | AW43: n/a | AX43: 1 | AY43: 0.5 | AZ43: 1 | BA43: 1 | BB43: n/a | BC43: n/a | BD43: n/a | BE43: 1 | BF43: n/a | BG43: 1 | BH43: 0.5 | BI43: 1 | BJ43: n/a | BK43: n/a | BL43: 0.5 | BM43: 0.5 | BN43: 1 | BO43: 1 | BP43: 1 | BQ43: n/a | BR43: n/a | BS43: n/a | BT43: n/a | BU43: n/a | BW43: 0.84615385 | BX43: 0.85714286 | BY43: 0.66666667 | BZ43: 0.78998779
AC44: 0.1 | AE44: PRESENTACIÓN PERSONAL DEL VENDEDOR/A | AF44: 1 | AG44: 1 | AH44: n/a | AI44: 1 | AJ44: n/a | AK44: n/a | AL44: 1 | AM44: 1 | AN44: n/a | AO44: 1 | AP44: n/a | AQ44: 1 | AR44: 1 | AS44: 1 | AT44: 1 | AU44: 1 | AV44: 1 | AW44: n/a | AX44: 1 | AY44: 1 | AZ44: 1 | BA44: 1 | BB44: n/a | BC44: n/a | BD44: n/a | BE44: 0.75 | BF44: n/a | BG44: 0.75 | BH44: 1 | BI44: 1 | BJ44: n/a | BK44: n/a | BL44: 1 | BM44: 1 | BN44: 1 | BO44: 1 | BP44: 0.75 | BQ44: 0 | BR44: 0 | BS44: 0 | BT44: 0 | BU44: 0 | BW44: 1 | BX44: 0.92857143 | BY44: 1 | BZ44: 0.97619048
AC45: 0.5 | AE45: El vendedor/a se encontraba con el uniforme de la empresa. | AF45: 1 | AG45: 1 | AH45: n/a | AI45: 1 | AJ45: n/a | AK45: n/a | AL45: 1 | AM45: 1 | AN45: n/a | AO45: 1 | AP45: n/a | AQ45: 1 | AR45: 1 | AS45: 1 | AT45: 1 | AU45: 1 | AV45: 1 | AW45: n/a | AX45: 1 | AY45: 1 | AZ45: 1 | BA45: 1 | BB45: n/a | BC45: n/a | BD45: n/a | BE45: 1 | BF45: n/a | BG45: 1 | BH45: 1 | BI45: 1 | BJ45: n/a | BK45: n/a | BL45: 1 | BM45: 1 | BN45: 1 | BO45: 1 | BP45: 0.5 | BQ45: n/a | BR45: n/a | BS45: n/a | BT45: n/a | BU45: n/a | BW45: 1 | BX45: 1 | BY45: 1 | BZ45: 1
...

Sheet Santa Cruz
B3: Reporte Diciembre 2025 - Visitas encubiertas DISMAC
B4: Santa Cruz - Comentarios Relevantes
C5: SANTA CRUZ
B7: DIMENSIONES EVALUADAS | C7: Cristobal de Mendoza #1055 | E7: Doble Vía entre 5to y 6to anillo | G7: Isabel 1 | I7: Montero | K7: Pampa de la Isla | M7: Show Room (P.I.) | O7: Villa 1ero de Mayo | Q7: 4to anillo e Isuto | S7: Plan 3000 | U7: Omar Chávez | W7: Av. Cristo Redentor | Y7: Av. Santos Dumont | AA7: Isabel 2
C8: Consulta | D8: Compra | E8: Consulta | F8: Compra | G8: Consulta | H8: Compra | I8: Consulta | J8: Compra | K8: Consulta | L8: Compra | M8: Consulta | N8: Compra | O8: Consulta | P8: Compra | Q8: Consulta | R8: Compra | S8: Consulta | T8: Compra | U8: Consulta | V8: Compra | W8: Consulta | X8: Compra | Y8: Consulta | Z8: Compra | AA8: Consulta | AB8: Compra
B9: FECHA DE LA VISITA | C9: 09-FEB-2026 | D9: 13-FEB-2026 | E9: 09-FEB-2026 | F9: 13-FEB-2026 | G9: 09-FEB-2026 | H9: 14-FEB-2026 | I9: 13-FEB-2026 | J9: 10-FEB-2026 | K9: 10-FEB-2026 | L9: 14-FEB-2026 | M9: 13-FEB-2026 | N9: 11-FEB-2026 | O9: 13-FEB-2026 | P9: 10-FEB-2026 | Q9: 13-FEB-2026 | R9: 11-FEB-2026 | S9: 13-FEB-2026 | T9: 10-FEB-2026 | U9: 10-FEB-2026 | V9: 11-FEB-2026 | W9: 11-FEB-2026 | X9: 13-FEB-2026 | Y9: 14-FEB-2026 | Z9: 12-FEB-2026 | AA9: 14-FEB-2026 | AB9: 10-FEB-2026
B10: TURNO | C10: Tarde | D10: Tarde | E10: Tarde | F10: Tarde | G10: Tarde | H10: Tarde | I10: Tarde | J10: Tarde | K10: Tarde | L10: Tarde | M10: Tarde | N10: Tarde | O10: Tarde | P10: Tarde | Q10: Tarde | R10: Mañana | S10: Tarde | T10: Medio día | U10: Tarde | V10: Tarde | W10: Tarde | X10: Tarde | Y10: Tarde | Z10: Tarde | AA10: Tarde | AB10: Tarde
B11: PRODUCTO | C11: Lavadora | D11: Cocina de 4 hornallas | E11: Aire acondicionado | F11: Plancha en seco | G11: Heladera | H11: Horno eléctrico Briara 550w | I11: Lavadora | J11: Secadora de cabello | K11: Lavadora y frezer | L11: Plancha de cabello Mallory Red Diamond | M11: Lavadoras | N11: Plancha en seco | O11: Lavadora | P11: Plancha a vapor Arno | Q11: Frezeer | R11: Plancha de cabello | S11: Aire acondicionado y hidrolavadora | T11: Plancha de cabello | U11: Lavadora y aire acondicionado | V11: Licuadora Arno 550W | W11: Lavadora | X11: Cocina Clásica Kerning | Y11: Aire acondicionado | Z11: Tostadora Philips | AA11: Televisor | AB11: Plancha a vapor arno essential 1100W de potencia
B13: ATENCIÓN DEL VENDEDOR
B14: PRIMER CONTACTO
B15: El vendedor/a se percató de la presencia del cliente y se aproximó para atenderlo | M15: No aplica, los vendedores estaba ocupados, había uno atendiendo a una familia y habían otros metiendo y sacando cosas del depósito | O15: No aplica, el vendedor se encontraba con otro cliente | Q15: No aplica, los vendedores se encontraban con otros clientes por lo cual esperé 5 minutos | T15: No aplica, esperé 8 minutos para ser atendida, ya que el vendedor se encontraba con otra cliente | U15: No aplica, esperé 6 minutos y había clientes en ese horario, todos estaban ocupados | X15: No aplica, los vendedores se encontraban ocupados, tuve que esperar que se desocupen para que me atiendan | Z15: No aplica, el vendedor me saludó, pero estaba ocupado haciendo una venta, esperé 5 minutos y fui y busqué un vendedor que pueda atenderme | AA15: No aplica, esperé 9 minutos, todos los vendedores se encontraban ocupado con otros clientes
B16: El vendedor/a lo saludó amablemente o pregunto en modo de bienvenida | G16: No aplica, yo saludé primero a la cual me devuelve el saludo | O16: Yo me acerqué y lo saludé no devolvió el saludo | T16: No aplica, yo me aproximé al vendedor y lo saludé primero, la cual me devuelve el saludo | U16: Yo me acerqué, saludé y pregunté por el producto, pero el no devolvió el saludo | Z16: No aplica, tuve que buscar un vendedor para que me atienda porque estaban ocupados trabajando, saludé primero y me devolvieron el saludo
B17: El vendedor/a pregunta al cliente lo que busca o sus preferencias. | E17: No aplica, yo fui directamente a preguntarle sobre el producto que estaba buscando | H17: No aplica, el vendedor estaba pendiente de mi porque me saludó y estaba cerca de mi esperando que le pregunté y ahí le consulte sobre el producto | J17: No aplica, yo le pregunté directamente sobre el producto ya que el vendedor solo me entregó un folleto de promociones y se pretendía ir | U17: No aplica, yo pregunté directamente sobre un producto | X17: No aplica, yo fui y lo busqué al vendedor porque estaban ocupados y le pregunté directamente sobre los productos que buscaba | Z17: No aplica, tuve que preguntarle yo donde estaba las tostadoras y el me indicó donde estaban, pero llegó se fue a la tv del ecomerce a ver otros productos y luego de un minuto el mismo me habló sobre el producto
B18: El vendedor/a dirige al cliente a donde debe, según su necesidad | C18: No aplica, ya me encontraba en la zona del producto que estaba buscando | H18: No aplica, ya estábamos en la zona de los productos que buscaba | J18: No aplica, ya me encontraba en la zona del producto | N18: No aplica, ya me encontraba en la zona | Q18: No aplica, ya me encontraba en la zona del producto | Z18: No aplica, ya estaba en la sección del producto | AA18: No aplica, ya me encontraba en la zona del producto
B19: GESTION DE VENTA
B20: El vendedor/a mostró el producto solicitado de forma rápida y sin hacer esperar mucho tiempo al cliente.
B21: El vendedor/a en caso de no disponer del producto en tienda, utilizó la página ecommerce de DISMAC para ofrecer otras opciones al cliente. | C21: No aplica, el producto estaba disponible en la tienda | D21: No aplica, el producto estaba disponible en tienda | E21: No aplica, el producto comsultado estaba disponible en la tienda | G21: No aplica, el producto estaba disponible en la tienda | H21: No aplica, los productos estaban disponibles en tienda | I21: No aplica, el producto estaba disponible en tienda | J21: No aplica, el producto estaba en la tienda, pero menciona que hay mas modelos en la página, sin embargo no me mostró la página | K21: No aplica, el producto se encontraba en la tienda | L21: No aplica, el producto estaba disponible en tienda | N21: No aplica, los productos se encontraban disponible en la tienda | P21: No aplica, no utilizó eso porque los productos estaban en tienda | R21: No aplica, el producto estaba disponible en la tienda | T21: No aplica, el producto se encontraba disponible | U21: No aplica, el producto estaba disponible en la tienda | W21: No aplica, el producto se encontraba en la tienda | X21: No aplica, los productos estaban en tienda disponible | Z21: No aplica, el producto estaba disponible en tienda | AA21: No aplica, el producto se encontraba en la tienda | AB21: No aplica, el producto estaba disponible en la tienda
B22: El vendedor/a demostró tener conocimiento del producto y proporcionó toda la información (garantía) y especificaciones del mismo.
B23: El vendedor/a mostró diferentes opciones de productos e hizo recomendaciones de acuerdo a sus necesidades. | J23: No me hizo otras recomendaciones al parecer su conocimiento era muy básico | K23: No mostró las diferentes opciones que tenían, tampoco hizo recomendaciones a lo que yo necesitaba y ni me preguntó, tenía que preguntarle para que el me hablara un poco del producto que estaba consultando
B24: El vendedor/a le comunicó los precios más bajos garantizados de Dismac. | E24: No me habló sobre que Dismac tenía los precios más bajos, siendo que le comenté que lo ví más barato el aire acondicionado en otro lado | G24: En ningún momento mencionó que Dismac tiene los precios más bajos del mercado | K24: No mencionó que tienen los precios más bajos, ni el descuento del 20%, con las justa me decía el precio de los productos que consulté | O24: No mencionó sobre los precios bajos garantizados | P24: No me habló de que cuentan con los precios más bajos garantizados | U24: No lo mencionó en ningún momento sobre los precios bajos garantizados
B25: El vendedor/a le comunicó sobre las promociones especiales, productos en combo, descuentos o lanzamientos. | E25: No me mencionó si había promociones especiales o productos en combos disponibles en tienda | K25: No mencionó ninguna promoción, descuentos o lanzamientos y tampoco combos | P25: No me habló de promociónes vigentes en la tienda | U25: En ningún momento mencionó alguna promoción o combos
B26: El vendedor/a explicó de qué trata la garantía extendida y sus beneficios | C26: No mencionó sobre la garantía extendida | E26: No mencionó sobre la garantía extendida | G26: No mencionó sobre la garantía extendida | K26: No me explicó sobre la garantía extendida ni sus beneficios | O26: No da ninguna información acerca de la garantía extendida | P26: No me habló de ningún tipo de garantía extendida de los productos | Q26: No mencionó ninguna de las garantías la extendida ni de la que cuenta el producto | U26: No proporcionó ninguna información sobre la garantía extendida | Z26: No me habló de las garantías extendidas que tenía la tienda
B27: El vendedor/a se esmeró en brindar argumentos para incentivar la compra del producto. | K27: El vendedor no se esmeró en dar buenos argumentos para poder incentivar la compra en todo mi recorrido lo tenía a el siguiendome, pero no me daba información a menos de que yo le preguntara algo sobre el producto | R27: Solo me dice las marcas y se aleja me dice que le consulte si tengo alguna duda | T27: El vendedor no se esmeró en darme detalles del producto que estaba buscando, tuve que preguntar para que el vendedor me diera más detalle del producto, no tenía mucho conocimiento del producto comprado | U27: Su explicación básica en cuanto a precios y tamaños, no me incentivaba a comprar solo se limitaba a responder lo que le consultaba
B28: El vendedor/a cerró la venta
B29: El vendedor/a ofreció y explicó los beneficios del servicio de entrega gratuita, tiempo de entrega, áreas de cobertura. | E29: No me habló si había entregas gratuitas o si llevaban el producto a domicilio | F29: No aplica, era compra pequeña | H29: No aplica, era compra pequeña | J29: No aplica, era compra pequeña, aunque si indicó el transporte | K29: No mencionó que tenían entrega gratuita | L29: No aplica, era compra pequeña | N29: No aplica, era compra pequeña, aunque si indicó el transporte | O29: No mencionó en ningún momento sobre la entrega gratuita | P29: No aplica, hicimos una compra pequeña de una plancha | R29: No aplica, era compra pequeña, aunque si indicó el transporte | T29: No aplica, era compra pequeña, aunque si indicó el transporte | U29: En ningún momento dijo que realizaban entrega a domicilio mayormente estaba con el celular ocupado | V29: No aplica, era compra pequeña | Z29: No aplica, era compra pequeña | AB29: No aplica, es un producto pequeño
B30: El vendedor/a ofreció y explicó los beneficios del servicio de instalación garantizada. | E30: No aplica, yo mencioné sobre la instalación ya el vendedor recién me explicó que tenía un costo aparte | F30: No aplica, se compró un producto pequeño | G30: No aplica, el producto no necesita instalación | H30: No aplica, estaba realizando la compra de un producto pequeño | J30: No aplica, era compra pequeña | K30: No mencionó que contaban con instalaciones garantizadas | L30: No aplica, se compró un producto pequeño | N30: No aplica, era compra pequeña | O30: No da esa información en ningún momento sobre la instalación garantizada | P30: No aplica, se compró un producto pequeño | Q30: el producto no requiere instalacion | R30: No aplica, era compra pequeña | T30: No aplica, era compra pequeña | U30: No me mencionó sobre este beneficio de la instalación | V30: No aplica, era compra pequeña | Z30: No aplica, era compra pequeña | AA30: No aplica, el producto no requiere instalación | AB30: No aplica, era compra pequeña
B31: El vendedor/a explicó los beneficios de la política de cambios y devoluciones. | C31: No explicó las políticas de cambios y devoluciones | E31: No me habló sobre devoluciones ni los cambios de los productos de Dismac | G31: En ningún momento mencionó la política de cambios y devoluciones | K31: No mencionó las políticas de cambios y devoluciones | O31: No da esa información de las políticas de cambio ni devoluciones | P31: No me habló de las políticas de devolución vigente en la tienda | Q31: No mencionó los beneficios de las politicas de cambios y devoluciones | U31: No mencionó nada sobre las políticas de cambio ni devoluciones
B32: El vendedor/a preguntó, si necesitaba algo más, o tuvo la capacidad/ habilidad de ofrecer productos ADICIONALES diferentes al que solicitó | C32: No aplica, solo consulté por un solo tipo de producto | E32: No indagó para preguntarme si buscaba algo más, porque después de que me explicó sobre los aires acondicionados me quedé viendo los aires para ver si el me decía algo, pero el agarró su celular y se puso a ver videos | G32: No preguntó en ningún momento si necesitaba algo más | H32: No me habló sobre otros productos adicionales que podía llevar en la tienda solo se dedicó a responder mis preguntas | J32: No preguntó si necesitaba algo más, ni ofreció | K32: No me ofreció otros productos diferente al que estaba buscando | O32: No aplica, solo consulté un producto | P32: solo me respondió las preguntas que yo le hacia, no me ofreció otros productos diferentes al que le consulté | U32: Solo mostró específicamente los productos por los cuales yo pregunté, no ofreció otras opciones | Z32: Solo se dedicaba a responder mis preguntas que le hacía, no me ofreció nada adiccional | AA32: No preguntaba si necesitaba algo mas ni ofreció otros productos
B33: El vendedor/a consultó el método de pago y ofreció MINICUOTAS | E33: No me mencionó de las mini cuotas de Dismac | G33: No explica ni menciona las mini cuotas | K33: No me consultó ni mencionó las mini cuotas | O33: No dio esa información de las mini cuotas | P33: No me ofrecieron mini cuotas ni créditos para comprar productos | U33: No preguntó ni mencionó las mini cuotas
B34: El vendedor/a demostró actitud de servicio, amabilidad y cortesía en el trato | K34: El vendedor se encontra serio y solo respondia los que yo le consultaba
B35: En caso de interrupción durante la visita, el vendedor le pidió disculpas por la interrupción. | D35: No aplica, no hubo interrupción | E35: No aplica, no hubo interrupción | F35: No aplica, no hubo interrupción | G35: No aplica, no hubo interrupción | H35: No aplica, no hubo interrupción | I35: No aplica, no hubo interrupción | J35: Si habían otros clientes que se acercaba y le consultaban por algunos productos, pero el no pedía disculpa por la interrupción | K35: No aplica, no hubo interrupción | M35: No aplica, no hubo interrupción | O35: No aplica, no hubo interrupción | P35: Hubo un vendedor que me atendío inicialmente, pero luego se fue sin decirme nada luego le volví a preguntar por lo que buscaba y solo me indicó dónde estaban los productos y se fue a hacer otras cosas al área de caja y luego no lo volví a ver más, tuve que efectuar mi compra con otra vendedora | Q35: No aplica, no hubo interrupción | R35: No aplica, no hubo interrupción | W35: No aplica, no hubo interrupción | X35: No aplica, no hubo interrupción | Z35: Hubo interrupciónes por la llamada de su celular, pero no me pidió disculpas solo se ausentó de mi lado y volvía solo y ya luego se volvió a ir y yo tuve que ir a buscarlo
B36: INFORMACIÓN SOBRE LA INSTALACIÓN
B37: El vendedor/a coordinó y programó la entrega a domicilio del producto
B38: El vendedor/a coordinó y programó la instalación del producto
B39: El vendedor/a informó y explicó los requisitos previos de instalación del producto
B40: DESPEDIDA
B41: El vendedor/a le solicitó sus datos personales y en caso de no estar registrado en su sistema, lo registró | C41: No solicitó mis datos ya que no realicé ninguna compra | E41: No me solicitó datos personales para ningún registro | G41: En ningún momento pide los datos personales ni nada | K41: No solicitó mis datos personales | M41: No me pidió datos personales porque estaba haciendo una consulta, pero si me habló de que podía registrarme en la página de Dismac para mini cuotas y ver más productos y pedidos desde la página | O41: No solicitó datos solo explicó lo que se le preguntó | Q41: No solicitó mis datos personales para el registro | S41: No me pidió mis datos personales, estaba realizando una consulta, pero si me dijo que podría registrarme en la tienda para solicitar créditos | U41: En ningún momento solicitó datos personales ni nada | W41: No solicitó los datos personales
B42: El vendedor/a lo dirigió a caja para efectuar el pago.
B43: El vendedor/a se despidió amablemente y lo invito a visitar nuevamente la tienda | E43: No sé despidió de mi yo le dije muchas gracias y el dijo de nada solo eso y no me invitó a volver a la tienda ni se despidió | G43: No se despidió y tampoco me invitó a volver a la tienda | P43: No se despidió de mi, ni me invitó a visitar la tienda otra vez, solo me entregó el producto y no hizo nada más | U43: Yo le dije gracias y el me dijo de nada solo eso
B44: PRESENTACIÓN PERSONAL DEL VENDEDOR/A
...

Sheet La Paz
B2: Reporte Diciembre 2025 - Visitas encubiertas Dismac
B3: La Paz - Comentarios Relevantes
C5: LA PAZ
B7: DIMENSIONES EVALUADAS | C7: Calacoto Av. Ballivian 1305 | E7: E. Salmon 1053 | G7: El Alto 4 | I7: Socabaya | K7: Multicine Río Seco | M7: El Alto Satélite | O7: El Alto Cruce Villa Adela
C8: Consulta | D8: Compra | E8: Consulta | F8: Compra | G8: Consulta | H8: Compra | I8: Consulta | J8: Compra | K8: Consulta | L8: Compra | M8: Consulta | N8: Compra | O8: Consulta | P8: Compra
B9: FECHA DE LA VISITA | C9: 08-FEB-2026 | D9: 09-FEB-2026 | E9: 06-FEB-2026 | F9: 14-FEB-2026 | G9: 14-FEB-2026 | H9: 11-FEB-2026 | I9: 06-FEB-2026 | J9: 09-FEB-2026 | K9: 07-FEB-2026 | L9: 11-FEB-2026 | M9: 07-FEB-2026 | N9: 10-FEB-2026 | O9: 12-FEB-2026 | P9: 14-FEB-2026
B10: TURNO | C10: Tarde | D10: Tarde | E10: Tarde | F10: Tarde | G10: Tarde | H10: Tarde | I10: Tarde | J10: Tarde | K10: Mañana | L10: Tarde | M10: Tarde | N10: Tarde | O10: Tarde | P10: Medio día
