Workbook

Sheet Plan de cuentas
A1: CODIGO | B1: CUENTA | C1: CLASIFICACION FLUJO | F1: 0 | G1: no corresponde
A2: 1 | B2: ACTIVO | F2: 1 | G2: OPERACIONES
A3: 101 | B3: ACTIVO DISPONIBLE | F3: 2 | G3: INVERSIONES
A4: 10101 | B4: CAJAS | F4: 3 | G4: FINANCIAMIENTO
A5: 10101001 | B5: CAJA MONEDA NACIONAL | C5: 4 | F5: 4 | G5: DISPONIBLE
A6: 10102 | B6: CAJA CHICAS
A7: 10102001 | B7: CAJA CHICA M/N | C7: 4
A8: 10103 | B8: BANCOS M/N
A9: 10103001 | B9: BANCO BISA 7468910017 | C9: 4
A10: 10103002 | B10: BANCO UNION 10000033281069 | C10: 4
A11: 10103003 | B11: BANCO 3 | C11: 4
A12: 10103004 | B12: BANCO 4 | C12: 4
A13: 10104 | B13: BANCOS M/N
A14: 10104001 | B14: BANCO GANADERO M/N | C14: 4
A15: 10104002 | B15: BANCO UNION M/N | C15: 4
A16: 102 | B16: ACTIVO EXIGIBLE
A17: 10201 | B17: CUENTAS POR COBRAR CLIENTES
A18: 10201001 | B18: CUENTAS POR COBRAR | C18: 1
A19: 10203 | B19: OTRAS CUENTAS POR COBRAR
A20: 10203001 | B20: ANTICIPO DE PROVEEDORES LOCALES | C20: 1
A21: 10203005 | B21: CUENTAS POR COBRAR SUBROGACION | C21: 1
A22: 10204 | B22: FONDOS A RENDIR
A23: 10204001 | B23: FONDOS 1 | C23: 1
A24: 10204002 | B24: FONDOS 2 | C24: 1
A25: 10204003 | B25: FONDOS 3 | C25: 1
A26: 10204004 | B26: FONDOS 4 | C26: 1
A27: 10205 | B27: PRESTAMOS A TERCEROS
A28: 10205001 | B28: PRESTAMOS AL PERSONAL | C28: 1
A29: 10206 | B29: CUENTAS TRIBUTARIAS
A30: 10206001 | B30: CREDITO FISCAL | C30: 1
A31: 10206002 | B31: I.T.PAGADO POR ANTICIPADO | C31: 1
A32: 10207 | B32: (-)PREV. PARA CUENTA INCOBRABLES M/N
A33: 10207001 | B33: (-)PREV.CUENTAS INCOBRABLES M/E | C33: 1
A34: 103 | B34: ACTIVO REALIZABLE
A35: 10301 | B35: INVENTARIOS DE MERCADERIAS
A36: 10301001 | B36: INVENTARIO DE MERCADERIAS | C36: 1
A37: 104 | B37: ACTIVO DIFERIDO
A38: 1 | B38: SEGUROS PAGADOS POR ADELANTADO
A39: 10401 | B39: GASTOS DE ORGANIZACION
A40: 105 | B40: ACTIVO FIJO
...

Sheet Blce. Apertura
A1: Empresa Princo Ltda.
A2: BALANCE DE APERTURA
A3: Practicado al 01 de Julio de 2023
A4: (Expresado en bolivianos)
A6: ACTIVO
B7: ACTIVO CORRIENTE
B8: Caja M/N | D8: 6300
B9: Banco Union M/N | D9: 4200
B10: Inventario de Mercaderia | D10: 6400
B12: ACTIVO NO CORRIENTE
B13: Vehiculos | D13: 7000
B14: Equipos de Computación | D14: 3000
B16: TOTAL ACTIVO | D16: =SUM(D8+D9+D10+D13+D14) -> 26900
A18: PASIVO
B19: PASIVO CORRIENTE
B20: Documentos por Pagar | D20: 4000
B21: Cuentas por Pagar | D21: 2000
B23: PASIVO NO CORRIENTE
A25: PATRIMONIO
B26: Capital Social | D26: 20900
B28: TOTAL PASIVO Y PATRIMONIO | D28: 26900

Sheet Libro Diario 1
A1: LIBRO DIARIO (COMPROBANTES)
A3: FECHA | B3: DETALLE | C3: DEBE | D3: HABER
A4: 45108 | B4: ------------ CT-01 ---------- | F4: 6300 | G4: 9400
B5: CAJA M/N | C5: 6300 | F5: 3760 | G5: 7500
B6: BANCO UNIÓN M/N | C6: 4200 | G6: 11347.7
B7: INVENTARIO DE MERCADERIAS | C7: 6400 | G7: 500
B8: VEHICULOS | C8: 7000
B9: EQUIPOS DE COMPUTACION | C9: 3000
B10: DOCUMENTOS POR PAGAR | D10: 4000
B11: CUENTAS POR PAGAR | D11: 2000
B12: CAPITAL SOCIAL | D12: 20900
B13: Glosa: Por inicio del asiento de balance inicial
A14: 45109 | B14: ------------ CI-01 ----------
B15: CAJA M/N | C15: 3760
B16: DOCUMENTOS POR COBRAR | C16: 5640
B17: I.T. | C17: 282
B18: VENTAS | D18: 8178
B19: DEBITO FISCAL | D19: 1222
B20: I.T. POR PAGAR | D20: 282 | G20: 6300
B21: Glosa:Por venta de Merc. Según fact. # | E21: 6300
A22: 45114 | B22: ------------ CE-01 ----------
B23: INVENTARIO DE MERCADERIAS | C23: 5655
B24: CREDITO FISCAL | C24: 845
B25: BANCO UNIÓN M/N | D25: 3500
B26: CUENTAS POR PAGAR | D26: 3000
B27: Glosa: Por compra de Merc. Según fact. #
A28: 45117 | B28: ------------ CT-02 ----------
B29: BANCO UNIÓN M/N | C29: 9400
B30: CAJA M/N | D30: 9400
B31: Glosa: Por deposito al banco de Merc. Vendida
A32: 45119 | B32: ------------ CT-03 ----------
B33: VEHICULOS | C33: 15000
B34: CAJA M/N | D34: 7500
B35: BANCO UNION M/N | D35: 7500
B36: Glosa:Por compra de un vehiculo para la empresa
A37: 45122 | B37: ------------ CE-02 ----------
B38: SUELDOS Y SALARIOS | C38: 13000
B39: CAJA M/N | D39: 11347.7
B40: APORTE LABORAL GESTORA POR PAGAR | D40: 1652.3
B41: Glosa: Por pago de sueldos 07/23 según planilla
...

Sheet Mayores
A3: CAJA M/N | D3: =+'Libro Diario 1'!B6 -> BANCO UNIÓN M/N | G3: INV. DE MERCADERIAS | J3: VEHICULOS | M3: EQUIPOS DE COMP.
A4: 6300 | B4: 9400 | D4: 4200 | E4: 3500 | G4: 6400 | J4: 7000 | M4: 3000
A5: 3760 | B5: 7500 | D5: 9400 | E5: 7500 | G5: 5655 | J5: 15000 | M5: 3000
A6: 10000 | B6: 11347.7 | D6: 2900 | E6: 0 | G6: 3480 | J6: =+J4+J5 -> 22000
A7: 2900 | B7: 500 | D7: =SUM(D4:D6) -> 16500 | E7: =SUM(E4:E6) -> 11000 | G7: =+G4+G5+G6 -> 15535
B8: 2300 | E8: =+D7-E7 -> 5500
B9: 3840
A10: =SUM(A4:A7) -> 22960 | B10: =SUM(B4:B9) -> 34887.7
B11: =+A10-B10 -> -11927.7
A14: DOCUMENTOS POR PAGAR | D14: CUENTAS POR PAGAR | G14: CAPITAL SOCIAL | J14: IMP. A LAS TRANSACCIONES | M14: VENTAS
B15: 4000 | D15: 3840 | E15: 2000 | H15: 20900 | J15: 282 | N15: 8178
B16: 4000 | E16: 3000 | H16: 20900 | J16: 300 | N16: 8700
E17: 3840 | J17: 174 | N17: 5046
D18: =+D15 -> 3840 | E18: =+E15+E16+E17 -> 8840 | J18: =+J15+J17+J16 -> 756 | N18: =+N15+N17+N16 -> 21924
E19: =E18-D18 -> 5000
A23: DEBITO FISCAL | D23: I.T. POR PAGAR | G23: CREDITO FISCAL | J23: SUELDOS Y SALARIOS | M23: APORTE LAB. GEST. POR PAGAR
A24: 1664 | B24: 1222 | E24: 282 | G24: 845 | H24: 3296.8 | J24: 13000 | N24: 1652.3
B25: 1300 | E25: 300 | G25: 299 | J25: 13000 | N25: 1652.3
B26: 754 | E26: 174 | G26: 520
B27: 20.8 | E27: =+E24+E25+E26 -> 756 | G27: =+G24+G25+G26 -> 1664 | H27: =+H24 -> 3296.8
A28: 1664 | B28: =SUM(B24+B25+B26+B27) -> 3296.8 | H28: =H27-G27 -> 1632.8
A29: =B28-A28 -> 1632.8
A30: APORTES PATRO. GESTORA | D30: CAJA DE SALUD | G30: AGUINALDOS | J30: INDEMNIZACION | M30: PRIMAS
A31: 872.3 | D31: 1300 | G31: 1083.33 | J31: 1083.33 | M31: 1083.33
A32: 872.3 | D32: 1300 | G32: 1083.33 | J32: 1083.33 | M32: 1083.33
A35: DOCUMEN. POR COBRAR | D35: APOR.PAT.GEST.POR PAGAR | G35: CAJA SALUD. POR PAGAR | J35: AGUINALDO POR PAGAR | M35: PREV. PARA INDEM.
A36: 5640 | E36: 872.3 | H36: 1300 | K36: 1083.33 | N36: 1083.33
A37: 5640 | E37: 872.3 | H37: 1300 | K37: 1083.33 | N37: 1083.33
A40: PRIMAS POR PAGAR | D40: SAGUAPAC LTDA | G40: DEVO. SOBRE VENTAS | J40: DESCUENTO EN COMPRAS
B41: 1083.33 | D41: 500 | H41: 2001 | K41: 139.2
B42: 1083.33 | D42: 500 | H42: 2001 | K42: 139.2

Sheet BCSS
A1: EMPRESA: LOS PENOCOS S.A.
A2: BALANCE DE COMPROBACION DE SUMAS Y SALDOS
A3: DEL 01 AL 30 DE NOVIEMBRE DE 2023
A4: EXPRESADO EN BOLIVIANOS
A6: NRO | B6: CUENTAS | C6: TIPO | D6: SUMAS | F6: SALDOS
D7: DEBE | E7: HABER | F7: DEUDOR | G7: ACREEDOR
A8: 1 | B8: CAJA MN | C8: A
A9: 2 | B9: BANCO BISA M/N | C9: A
A10: 3 | B10: MUEBLES Y ENSERES | C10: A
A11: 4 | B11: EQUIPOS DE COMPUTACION | C11: A
A12: 5 | B12: CAPITAL SOCIAL | C12: PAT
A13: 6 | B13: GASTOS LEGALES | C13: E
A14: 7 | B14: CREDITO FISCAL | C14: A
A15: 8 | B15: SEGUROS PAGADOS POR ADELANTADO | C15: A
A16: 9 | B16: I.T. | C16: E
A17: 10 | B17: VENTAS | C17: I
A18: 11 | B18: DEBITO FISCAL | C18: P
A19: 12 | B19: I.T. POR PAGAR | C19: P
... A27: 20 | B27: INDEMNIZACION | C27: E
A28: 21 | B28: PRIMAS | C28: E | F28: =+D28
A29: 22 | B29: APORTE PATRONAL GESTORA POR PAGAR | C29: P
A30: 23 | B30: CAJA DE SALUD POR PAGAR | C30: P
A31: 24 | B31: AGUINALDO POR PAGAR | C31: P
A32: 25 | B32: PREVISION PARA INDEMIZACION | C32: P
A33: 26 | B33: PRIMAS POR PAGAR | C33: P
A34: 27 | B34: DESCUENTO EN COMPRAS | C34: I
A35: 28 | B35: INVENTARIO DE MERCADERIAS | C35: A
B36: SUMAS IGUALES

Sheet HOJA DE TRABAJO
A1: EMPRESA: LOS PRINCOS LTDA
A2: HOJA DE TRABAJO PARA LA PREPARACIÓN DE LOS ESTADOS FINANCIEROS
A3: DEL 01 AL 1 DE JULIO DE 2023
A4: EXPRESADO EN BOLIVIANOS
A6: NRO | B6: CUENTAS | C6: TIPO | D6: SUMAS | F6: SALDOS | H6: ESTADO DE RESULTADOS | J6: BALANCE GENERAL
D7: DEBE | E7: HABER | F7: DEUDOR | G7: ACREEDOR | H7: EGRE/COSTO | I7: INGRESOS | J7: ACTIVOS | K7: PAS/PAT
A8: 1 | B8: =+[1]Mayores!A3 -> CAJA M/N | C8: A | D8: =+[1]Mayores!A10 -> 22960 | E8: =+[1]Mayores!B10 -> 34887.7 | F8: =IF((D8>E8),(D8-E8),0) -> 0 | G8: =IF(E8>D8,E8-D8,0) -> 11927.7 | J8: =+F8 -> 0 | K8: 11927.7
A9: 2 | B9: =+[1]Mayores!D3 -> BANCO UNIÓN M/N | C9: A | D9: 16500 | E9: 11000 | F9: =IF((D9>E9),(D9-E9),0) -> 5500 | G9: =IF(E9>D9,E9-D9,0) -> 0 | J9: =+F9 -> 5500 | K9: 0
A10: 3 | B10: =+[1]Mayores!G3 -> INV. DE MERCADERIAS | C10: A | D10: =+[1]Mayores!G7 -> 15535 | F10: =IF((D10>E10),(D10-E10),0) -> 15535 | G10: =IF(E10>D10,E10-D10,0) -> 0 | J10: =+F10 -> 15535
A11: 4 | B11: =+[1]Mayores!J3 -> VEHICULOS | C11: A | D11: =+[1]Mayores!J6 -> 22000 | F11: =IF((D11>E11),(D11-E11),0) -> 22000 | G11: =IF(E11>D11,E11-D11,0) -> 0 | J11: =+F11 -> 22000
A12: 5 | B12: =+[1]Mayores!M3 -> EQUIPOS DE COMP. | C12: A | D12: =+[1]Mayores!M5 -> 3000 | F12: =IF((D12>E12),(D12-E12),0) -> 3000 | G12: =IF(E12>D12,E12-D12,0) -> 0 | J12: 3000
A13: 6 | B13: =+[1]Mayores!A14 -> DOCUMENTOS POR PAGAR | C13: PG | E13: =+[1]Mayores!B16 -> 4000 | F13: =IF((D13>E13),(D13-E13),0) -> 0 | G13: =IF(E13>D13,E13-D13,0) -> 4000 | H13: 0 | I13: 0 | J13: 0 | K13: 4000
A14: 7 | B14: =+[1]Mayores!D14 -> CUENTAS POR PAGAR | C14: P | D14: =+[1]Mayores!D18 -> 3840 | E14: =+[1]Mayores!E18 -> 8840 | F14: =IF((D14>E14),(D14-E14),0) -> 0 | G14: =IF(E14>D14,E14-D14,0) -> 5000 | K14: 5000
A15: 8 | B15: =+[1]Mayores!G14 -> CAPITAL SOCIAL | C15: PAT | E15: =+[1]Mayores!H16 -> 20900 | F15: =IF((D15>E15),(D15-E15),0) -> 0 | G15: =IF(E15>D15,E15-D15,0) -> 20900 | K15: 20900
A16: 9 | B16: =+[1]Mayores!J14 -> DOCUMEN. POR COBRAR | C16: A | D16: =+[1]Mayores!J16 -> 5640 | F16: =IF((D16>E16),(D16-E16),0) -> 5640 | G16: =IF(E16>D16,E16-D16,0) -> 0 | J16: 5640
A17: 10 | B17: =[1]Mayores!M14 -> IMP. A LAS TRANSACCIONES | C17: E | D17: =+[1]Mayores!M18 -> 756 | F17: =IF((D17>E17),(D17-E17),0) -> 756 | G17: =IF(E17>D17,E17-D17,0) -> 0 | H17: 756 | I17: 0 | J17: 0 | K17: 0
A18: 11 | B18: =+[1]Mayores!A23 -> VENTAS | C18: I | E18: =+[1]Mayores!B27 -> 21924 | F18: =IF((D18>E18),(D18-E18),0) -> 0 | G18: =IF(E18>D18,E18-D18,0) -> 21924 | I18: =+G18 -> 21924
A19: 12 | B19: =+[1]Mayores!D23 -> DEBITO FISCAL | C19: P | E19: =+[1]Mayores!E28 -> 3296.8 | F19: =IF((D19>E19),(D19-E19),0) -> 0 | G19: =IF(E19>D19,E19-D19,0) -> 3296.8 | K19: =+G19 -> 3296.8
A20: 13 | B20: =+[1]Mayores!G23 -> I.T. POR PAGAR | C20: P | E20: =+[1]Mayores!H27 -> 756 | F20: =IF((D20>E20),(D20-E20),0) -> 0 | G20: =IF(E20>D20,E20-D20,0) -> 756 | K20: 756
A21: 14 | B21: =+[1]Mayores!J23 -> CREDITO FISCAL | C21: A | D21: =+[1]Mayores!J27 -> 1664 | F21: =IF((D21>E21),(D21-E21),0) -> 1664 | G21: =IF(E21>D21,E21-D21,0) -> 0 | J21: 1664 | K21: 0
A22: 15 | B22: =+[1]Mayores!M23 -> SUELDOS Y SALARIOS | C22: E | D22: =+[1]Mayores!M25 -> 13000 | F22: =IF((D22>E22),(D22-E22),0) -> 13000 | G22: =IF(E22>D22,E22-D22,0) -> 0 | H22: =+F22 -> 13000
A23: 16 | B23: =+[1]Mayores!A30 -> APORTE LAB. GEST. POR PAGAR | C23: P | E23: =+[1]Mayores!B32 -> 1652.3 | F23: =IF((D23>E23),(D23-E23),0) -> 0 | G23: =IF(E23>D23,E23-D23,0) -> 1652.3 | K23: =+G23 -> 1652.3
A24: 17 | B24: =+[1]Mayores!D30 -> APORTES PATRO. GESTORA | C24: E | D24: =+[1]Mayores!D32 -> 872.3 | F24: =IF((D24>E24),(D24-E24),0) -> 872.3 | G24: =IF(E24>D24,E24-D24,0) -> 0 | H24: =+F24 -> 872.3
A25: 18 | B25: =+[1]Mayores!G30 -> CAJA DE SALUD | C25: E | D25: =+[1]Mayores!G32 -> 1300 | F25: =IF((D25>E25),(D25-E25),0) -> 1300 | G25: =IF(E25>D25,E25-D25,0) -> 0 | H25: =+F25 -> 1300
A26: 19 | B26: =+[1]Mayores!J30 -> AGUINALDOS | C26: E | D26: =+[1]Mayores!J32 -> 1083.33 | F26: =IF((D26>E26),(D26-E26),0) -> 1083.33 | G26: =IF(E26>D26,E26-D26,0) -> 0 | H26: =+F26 -> 1083.33
A27: 20 | B27: =+[1]Mayores!M30 -> INDEMNIZACION | C27: E | D27: =+[1]Mayores!M32 -> 1083.33 | F27: =IF((D27>E27),(D27-E27),0) -> 1083.33 | G27: =IF(E27>D27,E27-D27,0) -> 0 | H27: =+F27 -> 1083.33
A28: 21 | B28: =+[1]Mayores!A37 -> PRIMAS | C28: E | D28: =+[1]Mayores!A39 -> 1083.33 | F28: =IF((D28>E28),(D28-E28),0) -> 1083.33 | G28: =IF(E28>D28,E28-D28,0) -> 0 | H28: =+F28 -> 1083.33
A29: 22 | B29: =+[1]Mayores!D37 -> APOR.PAT.GEST.POR PAGAR | C29: P | E29: =+[1]Mayores!E38 -> 872.3 | F29: =IF((D29>E29),(D29-E29),0) -> 0 | G29: =IF(E29>D29,E29-D29,0) -> 872.3 | K29: =+G29 -> 872.3
A30: 23 | B30: =+[1]Mayores!G37 -> CAJA SALUD. POR PAGAR | C30: P | D30: =+[1]Mayores!G42 -> 0 | E30: =+[1]Mayores!H42 -> 1300 | F30: =IF((D30>E30),(D30-E30),0) -> 0 | G30: =IF(E30>D30,E30-D30,0) -> 1300 | K30: =+G30 -> 1300
A31: 24 | B31: AGUINALDO POR PAGAR | C31: P | E31: =+[1]Mayores!K38 -> 1083.33 | F31: =IF((D31>E31),(D31-E31),0) -> 0 | G31: =IF(E31>D31,E31-D31,0) -> 1083.33 | K31: =+G31 -> 1083.33
A32: 25 | B32: PREVISION PARA INDEMNIZACION | C32: P | E32: =+[1]Mayores!N38 -> 1083.33 | F32: =IF((D32>E32),(D32-E32),0) -> 0 | G32: =IF(E32>D32,E32-D32,0) -> 1083.33 | K32: =+G32 -> 1083.33
A33: 26 | B33: PRIMAS POR PAGAR | C33: P | E33: =+[1]Mayores!B46 -> 1083.33 | F33: =IF((D33>E33),(D33-E33),0) -> 0 | G33: =IF(E33>D33,E33-D33,0) -> 1083.33 | K33: =+G33 -> 1083.33
A34: 27 | B34: SAGUAPAC | C34: E | D34: =+[1]Mayores!D46 -> 500 | F34: =IF((D34>E34),(D34-E34),0) -> 500 | G34: =IF(E34>D34,E34-D34,0) -> 0 | H34: 500 | I34: 0
A35: 28 | B35: DEVOLUCIONES SOBRE VENTAS | C35: E | D35: =+[1]Mayores!G46 -> 2001 | F35: =IF((D35>E35),(D35-E35),0) -> 2001 | G35: =IF(E35>D35,E35-D35,0) -> 0 | H35: 2001
A36: 29 | B36: DESCUENTOS EN COMPRAS | C36: I | E36: =+[1]Mayores!K46 -> 139.2 | F36: =IF((D36>E36),(D36-E36),0) -> 0 | G36: =IF(E36>D36,E36-D36,0) -> 139.2 | I36: 139.2
B37: SUMAS IGUALES | D37: =SUM(D8:D36) -> 112818.29 | E37: =SUM(E8:E36) -> 112818.29 | F37: =SUM(F4:F36) -> 75018.29 | G37: =SUM(G4:G36) -> 75018.29 | H37: =SUM(H8:H36) -> 21679.29 | I37: =SUM(I8:I36) -> 22063.2 | J37: =SUM(J8:J36) -> 53339 | K37: =SUM(K8:K36) -> 52955.09
B38: RESULTADO DEL PERIODO | I38: =H37-I37 -> -383.91 | J38: =K37-J37 -> -383.91
B39: SUMAS IGUALES | H39: =SUM(H37:H38) -> 21679.29 | I39: =SUM(I37:I38) -> 21679.29 | J39: =SUM(J37:J38) -> 52955.09 | K39: =SUM(K37:K38) -> 52955.09
E41: =D37-E37 -> 0 | G41: =F37-G37 -> 0 | I41: =J38+I38 -> -767.82
F43: =E41-G41 -> 0

Sheet FACTURA
B4: BAP SRL
B5: FACTURA
B7: Cliente: LOS PENOCOS S.A.
B9: ITEM | C9: DETALLE | D9: P/U | E9: TOTAL
B10: 1 | C10: VARIOS | D10: 12000 | E10: =+D10 -> 12000
F12: CF | G12: INVENTARIO
F13: 0.13 | G13: 0.87
C14: TOTAL | E14: =+E10 -> 12000 | F14: =+E14*F13 -> 1560 | G14: =+E14-F14 -> 10440
C15: DESCUENTO | D15: 0.05 | E15: =+E14*0.05 -> 600
C16: TOTAL A PAGAR | E16: =E14-E15 -> 11400
C21: INVENTARIO DE MERCADERIAS | D21: =+E23-D22 -> 9918
C22: CREDITO FISCAL | D22: =+E23*0.13 -> 1482
C23: CAJA M/N | E23: 11400

Sheet PLLA SUELDOS
A9: NOMBRE O RAZÓN SOCIAL
A10: Nº EMPLEADOR CAJA DE SALUD
A11: NIT
A12: DIRECCIÓN
A13: TELEFÓNO
A14: PLANILLA DE SUELDOS Y SALARIOS
A15: PERSONAL PERMANENTE
A16: (Expresado en Bolivianos)
A18: CORRESPONDIENTE AL MES DE NOVIEMBRE DE 2023
A20: Nº | B20: CARNET DE IDENTIDAD | C20: APELLIDOS Y NOMBRE | F20: NACIONALIDAD | G20: FECHA DE NACIMIENTO | H20: SEXO (F/M) | I20: OCUPACIÓN QUE DESEMPEÑA | J20: FECHA DE INGRESO | K20: DÍAS PAGADOS MES | L20: HABER BASICO | M20: BONO DE ANTIGÜEDAD | N20: HRS. EXTRAS | P20: BONOS | S20: TOTAL GANADO | T20: DESCUENTOS | X20: TOTAL DCTOS. | Y20: LÍQUIDO PAGABLE | Z20: FIRMA DEL EMPLEADO
T21: GESTORA | U21: AFP | V21: RC-IVA
O22: MONTO | P22: BONO DE | Q22: DOMINICA- | R22: OTROS | W22: OTROS
N23: No. | O23: PAGADO | P23: PRODUCC. | Q23: LES | R23: BONOS | S23: (G) | T23: 0.1271 | U23: Fondo | V23: 0.13 | W23: DCTOS. | X23: (K) | Y23: (L)
L24: (A) | M24: (B) | O24: (C) | P24: (D) | Q24: (E) | R24: (F) | T24: (H) | U24: Solidario | V24: (I) | W24: (J) | X24: H+I+J | Y24: G-K
A26: 1 | C26: TRABAJADORES | K26: 30 | L26: 25000 | M26: 0 | S26: =+L26 -> 25000 | T26: =S26*T23 -> 3177.5 | Y26: =S26-T26 -> 21822.5
A33: TOTALES | L33: =SUM(L26:L32) -> 25000 | M33: =SUM(M26:M32) -> 0 | N33: 0 | O33: 0 | P33: =SUM(P26:P32) -> 0 | Q33: 0 | R33: 0 | S33: =SUM(S26:S32) -> 25000 | T33: =SUM(T26:T32) -> 3177.5 | U33: =SUM(U26:U32) -> 0 | V33: 0 | W33: =SUM(W26:W32) -> 0 | X33: =SUM(X26:X32) -> 0 | Y33: =SUM(Y26:Y32) -> 21822.5
G39: EDUARDO VARGAS ROMAN | N39: 3200134 S.C
G40: NOMBRE DEL EMPLEADOR O REPRESENTANTE LEGAL | N40: Nº DE DOCUMENTO DE IDENTIDAD | S40: FIRMA | X40: FECHA: 30 DE JUNIO DE 2023

Sheet AP. Y BENEFICIOS
A9: NOMBRE O RAZÓN SOCIAL
A10: Nº EMPLEADOR CAJA DE SALUD
A11: NIT
A12: DIRECCIÓN
A13: TELEFÓNO
A14: PLANILLA DE APORTES PATRONALES Y BENEFICIOS SOCIALES
A15: PERSONAL PERMANENTE
A16: (Expresado en Bolivianos)
A18: CORRESPONDIENTE AL MES DE NOVIEMBRE DE 2023
A20: Nº | B20: CARNET DE IDENTIDAD | C20: APELLIDOS Y NOMBRE | F20: NACIONALIDAD | G20: FECHA DE NACIMIENTO | H20: SEXO (F/M) | I20: OCUPACIÓN QUE DESEMPEÑA | J20: FECHA DE INGRESO | K20: DÍAS PAGADOS MES | L20: HABER BASICO | M20: BONO DE ANTIGÜEDAD | N20: HRS. EXTRAS | P20: BONOS | S20: TOTAL GANADO | T20: GESTORA | U20: TOTAL GANADO | V20: TOTAL GANADO | W20: TOTAL GANADO | X20: TOTAL DCTOS. | Y20: CAJA DE SALUD | Z20: AGUINALDO | AA20: INDEMNIZACION | AB20: PRIMAS
O22: MONTO | P22: BONO DE | Q22: DOMINICA- | R22: OTROS
N23: No. | O23: PAGADO | P23: PRODUCC. | Q23: LES | R23: BONOS | T23: 0.0671 | U23: (G) | V23: (G) | W23: (G) | X23: (K) | Y23: 0.1 | Z23: =1/12 -> 0.083333333 | AA23: =1/12 -> 0.083333333 | AB23: =1/12 -> 0.083333333
A25: 1 | C25: TRABAJADORES | K25: 31 | L25: 16000 | M25: 0 | S25: 25000 | T25: =S25*T23 -> 1677.5 | Y25: =S25*Y23 -> 2500 | Z25: =S25/12 -> 2083.3333 | AA25: =+Z25 -> 2083.3333 | AB25: =+AA25 -> 2083.3333
A32: TOTALES | L32: =SUM(L25:L31) -> 16000 | M32: =SUM(M25:M31) -> 0 | N32: 0 | O32: 0 | P32: =SUM(P25:P31) -> 0 | Q32: 0 | R32: 0 | S32: =SUM(S25:S31) -> 25000 | T32: =SUM(T25:T31) -> 1677.5 | U32: =SUM(U25:U31) -> 0 | V32: =SUM(V25:V31) -> 0 | W32: =SUM(W25:W31) -> 0 | X32: =SUM(X25:X31) -> 0 | Y32: =SUM(Y25:Y31) -> 2500 | Z32: =SUM(Z25:Z31) -> 2083.3333 | ... AB32: =SUM(AB25:AB31) -> 2083.3333
G38: EDUARDO VARGAS ROMAN | N38: 3200134 S.C
G39: NOMBRE DEL EMPLEADOR O REPRESENTANTE LEGAL | N39: Nº DE DOCUMENTO DE IDENTIDAD | S39: FIRMA | X39: FECHA: 30 DE JUNIO DE 2023

Sheet ER
A1: =+'HOJA DE TRABAJO'!A1 -> EMPRESA: LOS PRINCOS LTDA
A3: ESTADO DE RESULTADOS
A4: Del 01 al 30 de noviembre de 2023
A5: (Expresado en bolivianos)
A7: VENTAS NETAS | D7: =SUM(C8:C10) -> #VALUE!
B8: Ventas | C8: 4176
A9: (-) | B9: Devoluciones s/ventas | C9: =-'HOJA DE TRABAJO'!H20 -> #VALUE!
A10: (-) | B10: Descuento s/ventas | C10: 0
A12: COSTO DE VENTAS | D12: 0
B13: Costo de ventas | C13: 0
B15: UTILIDAD BRUTA EN VENTAS | D15: =+D7-D12 -> #VALUE!
A17: GASTOS OPERATIVOS | D17: =SUM(C18:C25) -> 33611.29
B18: =+'HOJA DE TRABAJO'!B13 -> DOCUMENTOS POR PAGAR | C18: 3045
B19: =+'HOJA DE TRABAJO'!B16 -> DOCUMEN. POR COBRAR | C19: 144
B20: =+'HOJA DE TRABAJO'!B22 -> SUELDOS Y SALARIOS | C20: 25000
B21: =+'HOJA DE TRABAJO'!B24 -> APORTES PATRO. GESTORA | C21: =+'HOJA DE TRABAJO'!H24 -> 872.3
B22: =+'HOJA DE TRABAJO'!B25 -> CAJA DE SALUD | C22: =+'HOJA DE TRABAJO'!H25 -> 1300
B23: =+'HOJA DE TRABAJO'!B26 -> AGUINALDOS | C23: =+'HOJA DE TRABAJO'!H26 -> 1083.33
B24: =+'HOJA DE TRABAJO'!B27 -> INDEMNIZACION | C24: =+'HOJA DE TRABAJO'!H27 -> 1083.33
B25: =+'HOJA DE TRABAJO'!B28 -> PRIMAS | C25: =+'HOJA DE TRABAJO'!H28 -> 1083.33
B27: PÉRDIDA OPERATIVA | D27: =+D17-D15 -> #VALUE!
A29: (+) | B29: OTROS INGRESOS | D29: 522
B30: =+'HOJA DE TRABAJO'!B34 -> SAGUAPAC | C30: 522
B32: PÉRDIDA DEL EJERCICIO | D32: =+D27-D29 -> #VALUE!
B37: GERENTE GENERAL | C37: CONTADOR

Sheet BG
A1: =+'HOJA DE TRABAJO'!A1 -> EMPRESA: LOS PRINCOS LTDA
A3: BALANCE GENERAL
A4: Al 30 de noviembre de 2023
A5: (Expresado en bolivianos)
A7: ACTIVO
B8: ACTIVO CORRIENTE | D8: =SUM(C9:C13) -> 5500
B9: CAJA MN | C9: =+'HOJA DE TRABAJO'!J8 -> 0
B10: =+'HOJA DE TRABAJO'!B9 -> BANCO UNIÓN M/N | C10: =+'HOJA DE TRABAJO'!J9 -> 5500
B11: =+'HOJA DE TRABAJO'!B14 -> CUENTAS POR PAGAR | C11: =+'HOJA DE TRABAJO'!J14
B12: =+'HOJA DE TRABAJO'!B15 -> CAPITAL SOCIAL | C12: =+'HOJA DE TRABAJO'!J15
B13: =+'HOJA DE TRABAJO'!B35 -> DEVOLUCIONES SOBRE VENTAS | C13: =+'HOJA DE TRABAJO'!J35 -> 0
B15: ACTIVO NO CORRIENTE | D15: =SUM(C16:C17) -> 37535
B16: =+'HOJA DE TRABAJO'!B10 -> INV. DE MERCADERIAS | C16: =+'HOJA DE TRABAJO'!J10 -> 15535
B17: =+'HOJA DE TRABAJO'!B11 -> VEHICULOS | C17: =+'HOJA DE TRABAJO'!J11 -> 22000
B19: TOTAL ACTIVO | D19: =+D8+D15 -> 43035
A21: PASIVO
B22: PASIVO CORRIENTE | D22: =SUM(C23:C28) -> 6135.26
B23: =+'HOJA DE TRABAJO'!B19 -> DEBITO FISCAL | C23: 144
B24: =+'HOJA DE TRABAJO'!B23 -> APORTE LAB. GEST. POR PAGAR | C24: =+'HOJA DE TRABAJO'!K23 -> 1652.3
B25: =+'HOJA DE TRABAJO'!B29 -> APOR.PAT.GEST.POR PAGAR | C25: =+'HOJA DE TRABAJO'!K29 -> 872.3
B26: =+'HOJA DE TRABAJO'!B30 -> CAJA SALUD. POR PAGAR | C26: =+'HOJA DE TRABAJO'!K30 -> 1300
B27: =+'HOJA DE TRABAJO'!B31 -> AGUINALDO POR PAGAR | C27: =+'HOJA DE TRABAJO'!K31 -> 1083.33
B28: =+'HOJA DE TRABAJO'!B33 -> PRIMAS POR PAGAR | C28: =+'HOJA DE TRABAJO'!K33 -> 1083.33
B30: PASIVO NO CORRIENTE | D30: =+C31 -> 1083.33
B31: =+'HOJA DE TRABAJO'!B32 -> PREVISION PARA INDEMNIZACION | C31: =+'HOJA DE TRABAJO'!K32 -> 1083.33
A33: PATRIMONIO
B34: CAPITAL | D34: =+C36+C35 -> #VALUE!
B35: =+'HOJA DE TRABAJO'!B12 -> EQUIPOS DE COMP. | C35: 497000
B36: PÉRDIDA DEL EJERCICIO | C36: =-ER!D32 -> #VALUE!
B39: TOTAL PASIVO Y PATRIMONIO | D39: =+D22+D30+D34 -> #VALUE!
B44: GERENTE GENERAL | D44: CONTADOR
