Workbook

Sheet plan
B1: CÓDIGO | C1: DESCRIPCIÓN
B2: 1-0-00-00-000 | C2: ACTIVO
B3: 1-1-00-00-000 | C3: ACTIVO CORRIENTE
B4: 1-1-01-00-000 | C4: DISPONIBLE
B5: 1-1-01-01-000 | C5: DISPONIBLE EN MN
B6: 1-1-01-01-001 | C6: CAJA M/N
B7: 1-1-01-01-002 | C7: BANCO BNB MN
B8: 1-1-01-01-003 | C8: CAJA CHICA ADM
B9: 1-1-01-01-004 | C9: BANCO BISA M/N
B10: 1-1-01-01-005 | C10: CAJA CHICA COM
B11: 1-1-01-02-000 | C11: DISPONIBLE EN M/E
B12: 1-1-01-02-001 | C12: CAJA M/E
... B115: 3-1-01-01-000 | C115: CAPITAL CONTABLE
A116: # | B116: 3-1-01-01-001 | C116: CAPITAL SOCIAL
B117: 3-1-01-02-000 | C117: AJUSTES
A118: # | B118: 3-1-01-02-001 | C118: AJUSTE DE CAPITAL
A119: @ | B119: 3-1-01-02-002 | C119: AJUSTE DE RESERVAS PATRIMONIALES
A120: @ | B120: 3-1-01-02-003 | C120: AJUSTE GLOBAL AL PATRIMONIO
A121: @ | B121: 3-1-01-02-004 | C121: APORTES POR CAPITALIZAR
B122: 3-1-01-03-000 | C122: RESULTADOS
A123: $ | B123: 3-1-01-03-001 | C123: RESULTADO DE LA GESTION
A124: $ | B124: 3-1-01-03-002 | C124: RESULTADOS ACUMULADOS
B125: 3-1-01-04-000 | C125: APORTES POR CAPITALIZAR
B126: 4-0-00-00-000 | C126: INGRESOS
B127: 4-1-00-00-000 | C127: INGRESOS OPERATIVOS
B128: 4-1-01-00-000 | C128: INGRESOS POR VENTAS
B129: 4-1-01-01-000 | C129: VENTAS
B130: 4-1-01-01-001 | C130: VENTAS
B131: 4-2-00-00-000 | C131: INGRESOS NO OPERATIVOS
B132: 4-2-01-00-000 | C132: INGRESOS FINANCIEROS
B133: 4-2-01-01-000 | C133: INTERESES
B134: 4-2-01-01-001 | C134: INTERES BANCARIO GANADO
B135: 4-2-01-02-000 | C135: OTROS INGRESOS
B136: 4-2-01-02-001 | C136: AJUSTE POR INFLACION Y TENENCIA DE BIENES
... B270: 6-3-01-01-001 | C270: GASTOS DE REPRESENTACION

Sheet Blce. Apertura (2)
A1: Distribuidora "DISMACORP"
A2: BALANCE DE APERTURA
A3: Practicado al 01 de Enero de 2023
A4: (Expresado en bolivianos)
A6: ACTIVO
B7: ACTIVO CORRIENTE | D7: =SUM(D8:D11) -> 494000
B8: Banco Ganadero M/N | D8: 255000
B9: Caja M/N | D9: 100000
B10: Inventario de Mercaderia | D10: 84000
B11: Alquileres pagados por anticipado | D11: 55000
B13: ACTIVO NO CORRIENTE | D13: =D14+D15 -> 57000
B14: Muebles y enseres | D14: 12000
B15: Equipos de computación | D15: 45000
B17: TOTAL ACTIVO | D17: =D7+D13 -> 551000
H18: |
A19: PASIVO
B20: PASIVO CORRIENTE | D20: =SUM(D21:D21) -> 35000
B21: Documentos por Pagar | D21: 35000
B23: PASIVO NO CORRIENTE | D23: =D24 -> 350000
B24: PRESTAMO BANCARIO | D24: 350000
A25: PATRIMONIO
B26: Capital Social | D26: =SUM(D17-(D20+D23)) -> 166000
B28: TOTAL PASIVO Y PATRIMONIO | D28: =SUM(D20+D26+D23) -> 551000

Sheet Libro Diario 1
A1: LIBRO DIARIO (COMPROBANTES)
A3: FECHA | B3: DETALLE | C3: DEBE | D3: HABER
A4: 44927 | B4: ----------CT-01--------
B5: BANCO GANADERO M/N | C5: 255000
B6: CAJA M/N | C6: 100000
B7: INVENTARIO DE MERCADERIAS | C7: 84000
B8: ALQUILERES PAGADOS POR ANTICIPADO | C8: 55000
B9: MUEBLES Y ENSERES | C9: 12000
B10: EQUIPOS DE COMPUTACION | C10: 45000
B11: DOCUMENTOS POR PAGAR | D11: 35000
B12: DEUDAS POR PAGAR | D12: 350000
B13: CAPITAL SOCIAL | D13: 166000
B14: Glosa: Por inicio de actividades
A15: 44928 | B15: -----------CE-01----------
B16: GASTOS LEGALES, NOTARIALES Y JUDICIALES | C16: =D18*87/100 -> 3045
B17: CREDITO FISCAL | C17: =D18*13/100 -> 455
B18: CAJA M/N | D18: 3500
B19: Glosa: Pagos por gastosnlegales según factura #3510
A20: 44928 | B20: ------------CT-02------------
B21: INVENTARIO DE MERCADERIAS | C21: =65000-C22 -> 56550
B22: CREDITO FISCAL | C22: 8450
B23: BANCO GANADERO M/N | D23: 32500
B24: DOCUMENTOS POR PAGAR | D24: 32500
B25: Glosa: Por compra de mercaderia promayor s/g #3552
A26: 44930 | B26: -----------CT-03----------
B27: INVENTARIO DE MERCADERIAS | C27: =200000-C28 -> 174000
B28: CREDITO FISCAL | C28: 26000
B29: BANCO GANADERO M/N | D29: 90000
B30: DOCUMENTOS POR PAGAR | D30: 110000
B31: Glosa: Por compra de mercaderia a imp.todotec s/g#1254
A32: 44930 | B32: ---------CI-01---------
B33: CAJA M/N | C33: =55000*0.6 -> 33000
B34: DOCUMENTOS POR COBRAR | C34: =55000*0.4 -> 22000
B35: IMPUESTO A LAS TRANSACCIONES | C35: =55000*0.03 -> 1650
B36: VENTAS | D36: =55000*0.87 -> 47850
B37: DEBITO FISCAL | D37: =55000*0.13 -> 7150
B38: IT POR PAGAR | D38: =55000*0.03 -> 1650
B39: Glosa: Por venta de merc. Emp.DFASTORE S.A. s/f #001
A40: 44931 | B40: ---------CE-02---------
B41: MATERIAL DE ESCRITORIO | C41: =950*0.87 -> 826.5
...

Sheet Lista de Libros
A1: =IF(OR(ISNUMBER(FIND("-CT-",'Libro Diario 1'!#REF!)),ISNUMBER(FIND("-CE-",'Libro Diario 1'!#REF!)), ISNUMBER(FIND("-CI-",'Libro Diario 1'!#REF!)), ISNUMBER(FIND("Glosa", 'Libro Diario 1'!#REF!))), "", 'Libro Diario 1'!#REF!) -> #REF! | B1: =IF(OR(ISNUMBER(FIND("-CT-",'Libro Diario 1'!#REF!)),ISNUMBER(FIND("-CE-",'Libro Diario 1'!#REF!)), ISNUMBER(FIND("-CI-",'Libro Diario 1'!#REF!)), ISNUMBER(FIND("Glosa", 'Libro Diario 1'!#REF!))), "", 'Libro Diario 1'!#REF!) -> #REF! | C1: =IF(OR(ISNUMBER(FIND("-CT-",'Libro Diario 1'!#REF!)),ISNUMBER(FIND("-CE-",'Libro Diario 1'!#REF!)), ISNUMBER(FIND("-CI-",'Libro Diario 1'!#REF!)), ISNUMBER(FIND("Glosa", 'Libro Diario 1'!#REF!))), "", 'Libro Diario 1'!#REF!) -> #REF!
A2: =IF(OR(ISNUMBER(FIND("-CT-",'Libro Diario 1'!#REF!)),ISNUMBER(FIND("-CE-",'Libro Diario 1'!#REF!)), ISNUMBER(FIND("-CI-",'Libro Diario 1'!#REF!)), ISNUMBER(FIND("Glosa", 'Libro Diario 1'!#REF!))), "", 'Libro Diario 1'!#REF!) -> #REF! | B2: =IF(OR(ISNUMBER(FIND("-CT-",'Libro Diario 1'!#REF!)),ISNUMBER(FIND("-CE-",'Libro Diario 1'!#REF!)), ISNUMBER(FIND("-CI-",'Libro Diario 1'!#REF!)), ISNUMBER(FIND("Glosa", 'Libro Diario 1'!#REF!))), "", 'Libro Diario 1'!#REF!) -> #REF! | C2: =IF(OR(ISNUMBER(FIND("-CT-",'Libro Diario 1'!#REF!)),ISNUMBER(FIND("-CE-",'Libro Diario 1'!#REF!)), ISNUMBER(FIND("-CI-",'Libro Diario 1'!#REF!)), ISNUMBER(FIND("Glosa", 'Libro Diario 1'!#REF!))), "", 'Libro Diario 1'!#REF!) -> #REF! | E2: BANCO GANADERO M/N | F2: =SUMIF(A1:A54,E2,B1:B54) -> 0 | G2: =SUMIF(A1:A54,E2,C1:C54) -> 0
A3: =IF(OR(ISNUMBER(FIND("-CT-",'Libro Diario 1'!#REF!)),ISNUMBER(FIND("-CE-",'Libro Diario 1'!#REF!)), ISNUMBER(FIND("-CI-",'Libro Diario 1'!#REF!)), ISNUMBER(FIND("Glosa", 'Libro Diario 1'!#REF!))), "", 'Libro Diario 1'!#REF!) -> #REF! | B3: =IF(OR(ISNUMBER(FIND("-CT-",'Libro Diario 1'!#REF!)),ISNUMBER(FIND("-CE-",'Libro Diario 1'!#REF!)), ISNUMBER(FIND("-CI-",'Libro Diario 1'!#REF!)), ISNUMBER(FIND("Glosa", 'Libro Diario 1'!#REF!))), "", 'Libro Diario 1'!#REF!) -> #REF! | C3: =IF(OR(ISNUMBER(FIND("-CT-",'Libro Diario 1'!#REF!)),ISNUMBER(FIND("-CE-",'Libro Diario 1'!#REF!)), ISNUMBER(FIND("-CI-",'Libro Diario 1'!#REF!)), ISNUMBER(FIND("Glosa", 'Libro Diario 1'!#REF!))), "", 'Libro Diario 1'!#REF!) -> #REF! | E3: INVENTARIO DE MERCADERIAS | F3: =SUMIF(A2:A55,E3,B2:B55) -> 0 | G3: =SUMIF(A2:A55,E3,C2:C55) -> 0
A4: =IF(OR(ISNUMBER(FIND("-CT-",'Libro Diario 1'!#REF!)),ISNUMBER(FIND("-CE-",'Libro Diario 1'!#REF!)), ISNUMBER(FIND("-CI-",'Libro Diario 1'!#REF!)), ISNUMBER(FIND("Glosa", 'Libro Diario 1'!#REF!))), "", 'Libro Diario 1'!#REF!) -> #REF! | B4: =IF(OR(ISNUMBER(FIND("-CT-",'Libro Diario 1'!#REF!)),ISNUMBER(FIND("-CE-",'Libro Diario 1'!#REF!)), ISNUMBER(FIND("-CI-",'Libro Diario 1'!#REF!)), ISNUMBER(FIND("Glosa", 'Libro Diario 1'!#REF!))), "", 'Libro Diario 1'!#REF!) -> #REF! | C4: =IF(OR(ISNUMBER(FIND("-CT-",'Libro Diario 1'!#REF!)),ISNUMBER(FIND("-CE-",'Libro Diario 1'!#REF!)), ISNUMBER(FIND("-CI-",'Libro Diario 1'!#REF!)), ISNUMBER(FIND("Glosa", 'Libro Diario 1'!#REF!))), "", 'Libro Diario 1'!#REF!) -> #REF! | E4: MUEBLES Y ENSERES | F4: =SUMIF(A3:A56,E4,B3:B56) -> 0 | G4: =SUMIF(A3:A56,E4,C3:C56) -> 0
A5: =IF(OR(ISNUMBER(FIND("-CT-",'Libro Diario 1'!#REF!)),ISNUMBER(FIND("-CE-",'Libro Diario 1'!#REF!)), ISNUMBER(FIND("-CI-",'Libro Diario 1'!#REF!)), ISNUMBER(FIND("Glosa", 'Libro Diario 1'!#REF!))), "", 'Libro Diario 1'!#REF!) -> #REF! | B5: =IF(OR(ISNUMBER(FIND("-CT-",'Libro Diario 1'!#REF!)),ISNUMBER(FIND("-CE-",'Libro Diario 1'!#REF!)), ISNUMBER(FIND("-CI-",'Libro Diario 1'!#REF!)), ISNUMBER(FIND("Glosa", 'Libro Diario 1'!#REF!))), "", 'Libro Diario 1'!#REF!) -> #REF! | C5: =IF(OR(ISNUMBER(FIND("-CT-",'Libro Diario 1'!#REF!)),ISNUMBER(FIND("-CE-",'Libro Diario 1'!#REF!)), ISNUMBER(FIND("-CI-",'Libro Diario 1'!#REF!)), ISNUMBER(FIND("Glosa", 'Libro Diario 1'!#REF!))), "", 'Libro Diario 1'!#REF!) -> #REF! | E5: CUENTAS POR COBRAR | F5: =SUMIF(A4:A57,E5,B4:B57) -> 0 | G5: =SUMIF(A4:A57,E5,C4:C57) -> 0
A6: =IF(OR(ISNUMBER(FIND("-CT-",'Libro Diario 1'!#REF!)),ISNUMBER(FIND("-CE-",'Libro Diario 1'!#REF!)), ISNUMBER(FIND("-CI-",'Libro Diario 1'!#REF!)), ISNUMBER(FIND("Glosa", 'Libro Diario 1'!#REF!))), "", 'Libro Diario 1'!#REF!) -> #REF! | B6: =IF(OR(ISNUMBER(FIND("-CT-",'Libro Diario 1'!#REF!)),ISNUMBER(FIND("-CE-",'Libro Diario 1'!#REF!)), ISNUMBER(FIND("-CI-",'Libro Diario 1'!#REF!)), ISNUMBER(FIND("Glosa", 'Libro Diario 1'!#REF!))), "", 'Libro Diario 1'!#REF!) -> #REF! | C6: =IF(OR(ISNUMBER(FIND("-CT-",'Libro Diario 1'!#REF!)),ISNUMBER(FIND("-CE-",'Libro Diario 1'!#REF!)), ISNUMBER(FIND("-CI-",'Libro Diario 1'!#REF!)), ISNUMBER(FIND("Glosa", 'Libro Diario 1'!#REF!))), "", 'Libro Diario 1'!#REF!) -> #REF! | E6: ALQUILERES PAGADOS POR ANTICIPADO | F6: =SUMIF(A5:A58,E6,B5:B58) -> 0 | G6: =SUMIF(A5:A58,E6,C5:C58) -> 0
A7: =IF(OR(ISNUMBER(FIND("-CT-",'Libro Diario 1'!#REF!)),ISNUMBER(FIND("-CE-",'Libro Diario 1'!#REF!)), ISNUMBER(FIND("-CI-",'Libro Diario 1'!#REF!)), ISNUMBER(FIND("Glosa", 'Libro Diario 1'!#REF!))), "", 'Libro Diario 1'!#REF!) -> #REF! | B7: =IF(OR(ISNUMBER(FIND("-CT-",'Libro Diario 1'!#REF!)),ISNUMBER(FIND("-CE-",'Libro Diario 1'!#REF!)), ISNUMBER(FIND("-CI-",'Libro Diario 1'!#REF!)), ISNUMBER(FIND("Glosa", 'Libro Diario 1'!#REF!))), "", 'Libro Diario 1'!#REF!) -> #REF! | C7: =IF(OR(ISNUMBER(FIND("-CT-",'Libro Diario 1'!#REF!)),ISNUMBER(FIND("-CE-",'Libro Diario 1'!#REF!)), ISNUMBER(FIND("-CI-",'Libro Diario 1'!#REF!)), ISNUMBER(FIND("Glosa", 'Libro Diario 1'!#REF!))), "", 'Libro Diario 1'!#REF!) -> #REF! | E7: DOCUMENTOS POR PAGAR | F7: =SUMIF(A6:A59,E7,B6:B59) -> 0 | G7: =SUMIF(A6:A59,E7,C6:C59) -> 0
A8: =IF(OR(ISNUMBER(FIND("-CT-",'Libro Diario 1'!#REF!)),ISNUMBER(FIND("-CE-",'Libro Diario 1'!#REF!)), ISNUMBER(FIND("-CI-",'Libro Diario 1'!#REF!)), ISNUMBER(FIND("Glosa", 'Libro Diario 1'!#REF!))), "", 'Libro Diario 1'!#REF!) -> #REF! | B8: =IF(OR(ISNUMBER(FIND("-CT-",'Libro Diario 1'!#REF!)),ISNUMBER(FIND("-CE-",'Libro Diario 1'!#REF!)), ISNUMBER(FIND("-CI-",'Libro Diario 1'!#REF!)), ISNUMBER(FIND("Glosa", 'Libro Diario 1'!#REF!))), "", 'Libro Diario 1'!#REF!) -> #REF! | C8: =IF(OR(ISNUMBER(FIND("-CT-",'Libro Diario 1'!#REF!)),ISNUMBER(FIND("-CE-",'Libro Diario 1'!#REF!)), ISNUMBER(FIND("-CI-",'Libro Diario 1'!#REF!)), ISNUMBER(FIND("Glosa", 'Libro Diario 1'!#REF!))), "", 'Libro Diario 1'!#REF!) -> #REF! | E8: DEUDAS POR PAGAR | F8: =SUMIF(A7:A60,E8,B7:B60) -> 0 | G8: =SUMIF(A7:A60,E8,C7:C60) -> 0
A9: =IF(OR(ISNUMBER(FIND("-CT-",'Libro Diario 1'!#REF!)),ISNUMBER(FIND("-CE-",'Libro Diario 1'!#REF!)), ISNUMBER(FIND("-CI-",'Libro Diario 1'!#REF!)), ISNUMBER(FIND("Glosa", 'Libro Diario 1'!#REF!))), "", 'Libro Diario 1'!#REF!) -> #REF! | B9: =IF(OR(ISNUMBER(FIND("-CT-",'Libro Diario 1'!#REF!)),ISNUMBER(FIND("-CE-",'Libro Diario 1'!#REF!)), ISNUMBER(FIND("-CI-",'Libro Diario 1'!#REF!)), ISNUMBER(FIND("Glosa", 'Libro Diario 1'!#REF!))), "", 'Libro Diario 1'!#REF!) -> #REF! | C9: =IF(OR(ISNUMBER(FIND("-CT-",'Libro Diario 1'!#REF!)),ISNUMBER(FIND("-CE-",'Libro Diario 1'!#REF!)), ISNUMBER(FIND("-CI-",'Libro Diario 1'!#REF!)), ISNUMBER(FIND("Glosa", 'Libro Diario 1'!#REF!))), "", 'Libro Diario 1'!#REF!) -> #REF! | E9: CAPITAL SOCIAL | F9: =SUMIF(A8:A61,E9,B8:B61) -> 0 | G9: =SUMIF(A8:A61,E9,C8:C61) -> 0
A10: =IF(OR(ISNUMBER(FIND("-CT-",'Libro Diario 1'!#REF!)),ISNUMBER(FIND("-CE-",'Libro Diario 1'!#REF!)), ISNUMBER(FIND("-CI-",'Libro Diario 1'!#REF!)), ISNUMBER(FIND("Glosa", 'Libro Diario 1'!#REF!))), "", 'Libro Diario 1'!#REF!) -> #REF! | B10: =IF(OR(ISNUMBER(FIND("-CT-",'Libro Diario 1'!#REF!)),ISNUMBER(FIND("-CE-",'Libro Diario 1'!#REF!)), ISNUMBER(FIND("-CI-",'Libro Diario 1'!#REF!)), ISNUMBER(FIND("Glosa", 'Libro Diario 1'!#REF!))), "", 'Libro Diario 1'!#REF!) -> #REF! | C10: =IF(OR(ISNUMBER(FIND("-CT-",'Libro Diario 1'!#REF!)),ISNUMBER(FIND("-CE-",'Libro Diario 1'!#REF!)), ISNUMBER(FIND("-CI-",'Libro Diario 1'!#REF!)), ISNUMBER(FIND("Glosa", 'Libro Diario 1'!#REF!))), "", 'Libro Diario 1'!#REF!) -> #REF! | E10: CAJA M/N | F10: =SUMIF(A9:A62,E10,B9:B62) -> 0 | G10: =SUMIF(A9:A62,E10,C9:C62) -> 0
A11: =IF(OR(ISNUMBER(FIND("-CT-",'Libro Diario 1'!#REF!)),ISNUMBER(FIND("-CE-",'Libro Diario 1'!#REF!)), ISNUMBER(FIND("-CI-",'Libro Diario 1'!#REF!)), ISNUMBER(FIND("Glosa", 'Libro Diario 1'!#REF!))), "", 'Libro Diario 1'!#REF!) -> #REF! | B11: =IF(OR(ISNUMBER(FIND("-CT-",'Libro Diario 1'!#REF!)),ISNUMBER(FIND("-CE-",'Libro Diario 1'!#REF!)), ISNUMBER(FIND("-CI-",'Libro Diario 1'!#REF!)), ISNUMBER(FIND("Glosa", 'Libro Diario 1'!#REF!))), "", 'Libro Diario 1'!#REF!) -> #REF! | C11: =IF(OR(ISNUMBER(FIND("-CT-",'Libro Diario 1'!#REF!)),ISNUMBER(FIND("-CE-",'Libro Diario 1'!#REF!)), ISNUMBER(FIND("-CI-",'Libro Diario 1'!#REF!)), ISNUMBER(FIND("Glosa", 'Libro Diario 1'!#REF!))), "", 'Libro Diario 1'!#REF!) -> #REF! | E11: IMPUESTO A LAS TRANSACCIONES | F11: =SUMIF(A10:A63,E11,B10:B63) -> 0 | G11: =SUMIF(A10:A63,E11,C10:C63) -> 0
A12: =IF(OR(ISNUMBER(FIND("-CT-",'Libro Diario 1'!#REF!)),ISNUMBER(FIND("-CE-",'Libro Diario 1'!#REF!)), ISNUMBER(FIND("-CI-",'Libro Diario 1'!#REF!)), ISNUMBER(FIND("Glosa", 'Libro Diario 1'!#REF!))), "", 'Libro Diario 1'!#REF!) -> #REF! | B12: =IF(OR(ISNUMBER(FIND("-CT-",'Libro Diario 1'!#REF!)),ISNUMBER(FIND("-CE-",'Libro Diario 1'!#REF!)), ISNUMBER(FIND("-CI-",'Libro Diario 1'!#REF!)), ISNUMBER(FIND("Glosa", 'Libro Diario 1'!#REF!))), "", 'Libro Diario 1'!#REF!) -> #REF! | C12: =IF(OR(ISNUMBER(FIND("-CT-",'Libro Diario 1'!#REF!)),ISNUMBER(FIND("-CE-",'Libro Diario 1'!#REF!)), ISNUMBER(FIND("-CI-",'Libro Diario 1'!#REF!)), ISNUMBER(FIND("Glosa", 'Libro Diario 1'!#REF!))), "", 'Libro Diario 1'!#REF!) -> #REF! | E12: VENTAS | F12: =SUMIF(A11:A64,E12,B11:B64) -> 0 | G12: =SUMIF(A11:A64,E12,C11:C64) -> 0
A13: =IF(OR(ISNUMBER(FIND("-CT-",'Libro Diario 1'!#REF!)),ISNUMBER(FIND("-CE-",'Libro Diario 1'!#REF!)), ISNUMBER(FIND("-CI-",'Libro Diario 1'!#REF!)), ISNUMBER(FIND("Glosa", 'Libro Diario 1'!#REF!))), "", 'Libro Diario 1'!#REF!) -> #REF! | B13: =IF(OR(ISNUMBER(FIND("-CT-",'Libro Diario 1'!#REF!)),ISNUMBER(FIND("-CE-",'Libro Diario 1'!#REF!)), ISNUMBER(FIND("-CI-",'Libro Diario 1'!#REF!)), ISNUMBER(FIND("Glosa", 'Libro Diario 1'!#REF!))), "", 'Libro Diario 1'!#REF!) -> #REF! | C13: =IF(OR(ISNUMBER(FIND("-CT-",'Libro Diario 1'!#REF!)),ISNUMBER(FIND("-CE-",'Libro Diario 1'!#REF!)), ISNUMBER(FIND("-CI-",'Libro Diario 1'!#REF!)), ISNUMBER(FIND("Glosa", 'Libro Diario 1'!#REF!))), "", 'Libro Diario 1'!#REF!) -> #REF! | E13: DEBITO FISCAL | F13: =SUMIF(A12:A65,E13,B12:B65) -> 0 | G13: =SUMIF(A12:A65,E13,C12:C65) -> 0
... A18: =IF(OR(ISNUMBER(FIND("-CT-",'Libro Diario 1'!#REF!)),ISNUMBER(FIND("-CE-",'Libro Diario 1'!#REF!)), ISNUMBER(FIND("-CI-",'Libro Diario 1'!#REF!)), ISNUMBER(FIND("Glosa", 'Libro Diario 1'!#REF!))), "", 'Libro Diario 1'!#REF!) -> #REF! | B18: =IF(OR(ISNUMBER(FIND("-CT-",'Libro Diario 1'!#REF!)),ISNUMBER(FIND("-CE-",'Libro Diario 1'!#REF!)), ISNUMBER(FIND("-CI-",'Libro Diario 1'!#REF!)), ISNUMBER(FIND("Glosa", 'Libro Diario 1'!#REF!))), "", 'Libro Diario 1'!#REF!) -> #REF! | C18: =IF(OR(ISNUMBER(FIND("-CT-",'Libro Diario 1'!#REF!)),ISNUMBER(FIND("-CE-",'Libro Diario 1'!#REF!)), ISNUMBER(FIND("-CI-",'Libro Diario 1'!#REF!)), ISNUMBER(FIND("Glosa", 'Libro Diario 1'!#REF!))), "", 'Libro Diario 1'!#REF!) -> #REF! | E18: ALQUILER DE OFICINA | F18: =SUMIF(A17:A70,E18,B17:B70) -> 0 | G18: =SUMIF(A17:A70,E18,C17:C70) -> 0
A19: =IF(OR(ISNUMBER(FIND("-CT-",'Libro Diario 1'!#REF!)),ISNUMBER(FIND("-CE-",'Libro Diario 1'!#REF!)), ISNUMBER(FIND("-CI-",'Libro Diario 1'!#REF!)), ISNUMBER(FIND("Glosa", 'Libro Diario 1'!#REF!))), "", 'Libro Diario 1'!#REF!) -> #REF! | B19: =IF(OR(ISNUMBER(FIND("-CT-",'Libro Diario 1'!#REF!)),ISNUMBER(FIND("-CE-",'Libro Diario 1'!#REF!)), ISNUMBER(FIND("-CI-",'Libro Diario 1'!#REF!)), ISNUMBER(FIND("Glosa", 'Libro Diario 1'!#REF!))), "", 'Libro Diario 1'!#REF!) -> #REF! | C19: =IF(OR(ISNUMBER(FIND("-CT-",'Libro Diario 1'!#REF!)),ISNUMBER(FIND("-CE-",'Libro Diario 1'!#REF!)), ISNUMBER(FIND("-CI-",'Libro Diario 1'!#REF!)), ISNUMBER(FIND("Glosa", 'Libro Diario 1'!#REF!))), "", 'Libro Diario 1'!#REF!) -> #REF!
A20: =IF(OR(ISNUMBER(FIND("-CT-",'Libro Diario 1'!#REF!)),ISNUMBER(FIND("-CE-",'Libro Diario 1'!#REF!)), ISNUMBER(FIND("-CI-",'Libro Diario 1'!#REF!)), ISNUMBER(FIND("Glosa", 'Libro Diario 1'!#REF!))), "", 'Libro Diario 1'!#REF!) -> #REF! | B20: =IF(OR(ISNUMBER(FIND("-CT-",'Libro Diario 1'!#REF!)),ISNUMBER(FIND("-CE-",'Libro Diario 1'!#REF!)), ISNUMBER(FIND("-CI-",'Libro Diario 1'!#REF!)), ISNUMBER(FIND("Glosa", 'Libro Diario 1'!#REF!))), "", 'Libro Diario 1'!#REF!) -> #REF! | C20: =IF(OR(ISNUMBER(FIND("-CT-",'Libro Diario 1'!#REF!)),ISNUMBER(FIND("-CE-",'Libro Diario 1'!#REF!)), ISNUMBER(FIND("-CI-",'Libro Diario 1'!#REF!)), ISNUMBER(FIND("Glosa", 'Libro Diario 1'!#REF!))), "", 'Libro Diario 1'!#REF!) -> #REF!
A21: =IF(OR(ISNUMBER(FIND("-CT-",'Libro Diario 1'!#REF!)),ISNUMBER(FIND("-CE-",'Libro Diario 1'!#REF!)), ISNUMBER(FIND("-CI-",'Libro Diario 1'!#REF!)), ISNUMBER(FIND("Glosa", 'Libro Diario 1'!#REF!))), "", 'Libro Diario 1'!#REF!) -> #REF! | B21: =IF(OR(ISNUMBER(FIND("-CT-",'Libro Diario 1'!#REF!)),ISNUMBER(FIND("-CE-",'Libro Diario 1'!#REF!)), ISNUMBER(FIND("-CI-",'Libro Diario 1'!#REF!)), ISNUMBER(FIND("Glosa", 'Libro Diario 1'!#REF!))), "", 'Libro Diario 1'!#REF!) -> #REF! | C21: =IF(OR(ISNUMBER(FIND("-CT-",'Libro Diario 1'!#REF!)),ISNUMBER(FIND("-CE-",'Libro Diario 1'!#REF!)), ISNUMBER(FIND("-CI-",'Libro Diario 1'!#REF!)), ISNUMBER(FIND("Glosa", 'Libro Diario 1'!#REF!))), "", 'Libro Diario 1'!#REF!) -> #REF!
A22: =IF(OR(ISNUMBER(FIND("-CT-",'Libro Diario 1'!#REF!)),ISNUMBER(FIND("-CE-",'Libro Diario 1'!#REF!)), ISNUMBER(FIND("-CI-",'Libro Diario 1'!#REF!)), ISNUMBER(FIND("Glosa", 'Libro Diario 1'!#REF!))), "", 'Libro Diario 1'!#REF!) -> #REF! | B22: =IF(OR(ISNUMBER(FIND("-CT-",'Libro Diario 1'!#REF!)),ISNUMBER(FIND("-CE-",'Libro Diario 1'!#REF!)), ISNUMBER(FIND("-CI-",'Libro Diario 1'!#REF!)), ISNUMBER(FIND("Glosa", 'Libro Diario 1'!#REF!))), "", 'Libro Diario 1'!#REF!) -> #REF! | C22: =IF(OR(ISNUMBER(FIND("-CT-",'Libro Diario 1'!#REF!)),ISNUMBER(FIND("-CE-",'Libro Diario 1'!#REF!)), ISNUMBER(FIND("-CI-",'Libro Diario 1'!#REF!)), ISNUMBER(FIND("Glosa", 'Libro Diario 1'!#REF!))), "", 'Libro Diario 1'!#REF!) -> #REF!
A23: =IF(OR(ISNUMBER(FIND("-CT-",'Libro Diario 1'!#REF!)),ISNUMBER(FIND("-CE-",'Libro Diario 1'!#REF!)), ISNUMBER(FIND("-CI-",'Libro Diario 1'!#REF!)), ISNUMBER(FIND("Glosa", 'Libro Diario 1'!#REF!))), "", 'Libro Diario 1'!#REF!) -> #REF! | B23: =IF(OR(ISNUMBER(FIND("-CT-",'Libro Diario 1'!#REF!)),ISNUMBER(FIND("-CE-",'Libro Diario 1'!#REF!)), ISNUMBER(FIND("-CI-",'Libro Diario 1'!#REF!)), ISNUMBER(FIND("Glosa", 'Libro Diario 1'!#REF!))), "", 'Libro Diario 1'!#REF!) -> #REF! | C23: =IF(OR(ISNUMBER(FIND("-CT-",'Libro Diario 1'!#REF!)),ISNUMBER(FIND("-CE-",'Libro Diario 1'!#REF!)), ISNUMBER(FIND("-CI-",'Libro Diario 1'!#REF!)), ISNUMBER(FIND("Glosa", 'Libro Diario 1'!#REF!))), "", 'Libro Diario 1'!#REF!) -> #REF!
A24: =IF(OR(ISNUMBER(FIND("-CT-",'Libro Diario 1'!#REF!)),ISNUMBER(FIND("-CE-",'Libro Diario 1'!#REF!)), ISNUMBER(FIND("-CI-",'Libro Diario 1'!#REF!)), ISNUMBER(FIND("Glosa", 'Libro Diario 1'!#REF!))), "", 'Libro Diario 1'!#REF!) -> #REF! | B24: =IF(OR(ISNUMBER(FIND("-CT-",'Libro Diario 1'!#REF!)),ISNUMBER(FIND("-CE-",'Libro Diario 1'!#REF!)), ISNUMBER(FIND("-CI-",'Libro Diario 1'!#REF!)), ISNUMBER(FIND("Glosa", 'Libro Diario 1'!#REF!))), "", 'Libro Diario 1'!#REF!) -> #REF! | C24: =IF(OR(ISNUMBER(FIND("-CT-",'Libro Diario 1'!#REF!)),ISNUMBER(FIND("-CE-",'Libro Diario 1'!#REF!)), ISNUMBER(FIND("-CI-",'Libro Diario 1'!#REF!)), ISNUMBER(FIND("Glosa", 'Libro Diario 1'!#REF!))), "", 'Libro Diario 1'!#REF!) -> #REF!
A25: =IF(OR(ISNUMBER(FIND("-CT-",'Libro Diario 1'!#REF!)),ISNUMBER(FIND("-CE-",'Libro Diario 1'!#REF!)), ISNUMBER(FIND("-CI-",'Libro Diario 1'!#REF!)), ISNUMBER(FIND("Glosa", 'Libro Diario 1'!#REF!))), "", 'Libro Diario 1'!#REF!) -> #REF! | B25: =IF(OR(ISNUMBER(FIND("-CT-",'Libro Diario 1'!#REF!)),ISNUMBER(FIND("-CE-",'Libro Diario 1'!#REF!)), ISNUMBER(FIND("-CI-",'Libro Diario 1'!#REF!)), ISNUMBER(FIND("Glosa", 'Libro Diario 1'!#REF!))), "", 'Libro Diario 1'!#REF!) -> #REF! | C25: =IF(OR(ISNUMBER(FIND("-CT-",'Libro Diario 1'!#REF!)),ISNUMBER(FIND("-CE-",'Libro Diario 1'!#REF!)), ISNUMBER(FIND("-CI-",'Libro Diario 1'!#REF!)), ISNUMBER(FIND("Glosa", 'Libro Diario 1'!#REF!))), "", 'Libro Diario 1'!#REF!) -> #REF!
A26: =IF(OR(ISNUMBER(FIND("-CT-",'Libro Diario 1'!#REF!)),ISNUMBER(FIND("-CE-",'Libro Diario 1'!#REF!)), ISNUMBER(FIND("-CI-",'Libro Diario 1'!#REF!)), ISNUMBER(FIND("Glosa", 'Libro Diario 1'!#REF!))), "", 'Libro Diario 1'!#REF!) -> #REF! | B26: =IF(OR(ISNUMBER(FIND("-CT-",'Libro Diario 1'!#REF!)),ISNUMBER(FIND("-CE-",'Libro Diario 1'!#REF!)), ISNUMBER(FIND("-CI-",'Libro Diario 1'!#REF!)), ISNUMBER(FIND("Glosa", 'Libro Diario 1'!#REF!))), "", 'Libro Diario 1'!#REF!) -> #REF! | C26: =IF(OR(ISNUMBER(FIND("-CT-",'Libro Diario 1'!#REF!)),ISNUMBER(FIND("-CE-",'Libro Diario 1'!#REF!)), ISNUMBER(FIND("-CI-",'Libro Diario 1'!#REF!)), ISNUMBER(FIND("Glosa", 'Libro Diario 1'!#REF!))), "", 'Libro Diario 1'!#REF!) -> #REF!
A27: =IF(OR(ISNUMBER(FIND("-CT-",'Libro Diario 1'!#REF!)),ISNUMBER(FIND("-CE-",'Libro Diario 1'!#REF!)), ISNUMBER(FIND("-CI-",'Libro Diario 1'!#REF!)), ISNUMBER(FIND("Glosa", 'Libro Diario 1'!#REF!))), "", 'Libro Diario 1'!#REF!) -> #REF! | B27: =IF(OR(ISNUMBER(FIND("-CT-",'Libro Diario 1'!#REF!)),ISNUMBER(FIND("-CE-",'Libro Diario 1'!#REF!)), ISNUMBER(FIND("-CI-",'Libro Diario 1'!#REF!)), ISNUMBER(FIND("Glosa", 'Libro Diario 1'!#REF!))), "", 'Libro Diario 1'!#REF!) -> #REF! | C27: =IF(OR(ISNUMBER(FIND("-CT-",'Libro Diario 1'!#REF!)),ISNUMBER(FIND("-CE-",'Libro Diario 1'!#REF!)), ISNUMBER(FIND("-CI-",'Libro Diario 1'!#REF!)), ISNUMBER(FIND("Glosa", 'Libro Diario 1'!#REF!))), "", 'Libro Diario 1'!#REF!) -> #REF!
A28: =IF(OR(ISNUMBER(FIND("-CT-",'Libro Diario 1'!#REF!)),ISNUMBER(FIND("-CE-",'Libro Diario 1'!#REF!)), ISNUMBER(FIND("-CI-",'Libro Diario 1'!#REF!)), ISNUMBER(FIND("Glosa", 'Libro Diario 1'!#REF!))), "", 'Libro Diario 1'!#REF!) -> #REF! | B28: =IF(OR(ISNUMBER(FIND("-CT-",'Libro Diario 1'!#REF!)),ISNUMBER(FIND("-CE-",'Libro Diario 1'!#REF!)), ISNUMBER(FIND("-CI-",'Libro Diario 1'!#REF!)), ISNUMBER(FIND("Glosa", 'Libro Diario 1'!#REF!))), "", 'Libro Diario 1'!#REF!) -> #REF! | C28: =IF(OR(ISNUMBER(FIND("-CT-",'Libro Diario 1'!#REF!)),ISNUMBER(FIND("-CE-",'Libro Diario 1'!#REF!)), ISNUMBER(FIND("-CI-",'Libro Diario 1'!#REF!)), ISNUMBER(FIND("Glosa", 'Libro Diario 1'!#REF!))), "", 'Libro Diario 1'!#REF!) -> #REF!
A29: =IF(OR(ISNUMBER(FIND("-CT-",'Libro Diario 1'!#REF!)),ISNUMBER(FIND("-CE-",'Libro Diario 1'!#REF!)), ISNUMBER(FIND("-CI-",'Libro Diario 1'!#REF!)), ISNUMBER(FIND("Glosa", 'Libro Diario 1'!#REF!))), "", 'Libro Diario 1'!#REF!) -> #REF! | B29: =IF(OR(ISNUMBER(FIND("-CT-",'Libro Diario 1'!#REF!)),ISNUMBER(FIND("-CE-",'Libro Diario 1'!#REF!)), ISNUMBER(FIND("-CI-",'Libro Diario 1'!#REF!)), ISNUMBER(FIND("Glosa", 'Libro Diario 1'!#REF!))), "", 'Libro Diario 1'!#REF!) -> #REF! | C29: =IF(OR(ISNUMBER(FIND("-CT-",'Libro Diario 1'!#REF!)),ISNUMBER(FIND("-CE-",'Libro Diario 1'!#REF!)), ISNUMBER(FIND("-CI-",'Libro Diario 1'!#REF!)), ISNUMBER(FIND("Glosa", 'Libro Diario 1'!#REF!))), "", 'Libro Diario 1'!#REF!) -> #REF!
A30: =IF(OR(ISNUMBER(FIND("-CT-",'Libro Diario 1'!#REF!)),ISNUMBER(FIND("-CE-",'Libro Diario 1'!#REF!)), ISNUMBER(FIND("-CI-",'Libro Diario 1'!#REF!)), ISNUMBER(FIND("Glosa", 'Libro Diario 1'!#REF!))), "", 'Libro Diario 1'!#REF!) -> #REF! | B30: =IF(OR(ISNUMBER(FIND("-CT-",'Libro Diario 1'!#REF!)),ISNUMBER(FIND("-CE-",'Libro Diario 1'!#REF!)), ISNUMBER(FIND("-CI-",'Libro Diario 1'!#REF!)), ISNUMBER(FIND("Glosa", 'Libro Diario 1'!#REF!))), "", 'Libro Diario 1'!#REF!) -> #REF! | C30: =IF(OR(ISNUMBER(FIND("-CT-",'Libro Diario 1'!#REF!)),ISNUMBER(FIND("-CE-",'Libro Diario 1'!#REF!)), ISNUMBER(FIND("-CI-",'Libro Diario 1'!#REF!)), ISNUMBER(FIND("Glosa", 'Libro Diario 1'!#REF!))), "", 'Libro Diario 1'!#REF!) -> #REF!
... A52: =IF(OR(ISNUMBER(FIND("-CT-",'Libro Diario 1'!#REF!)),ISNUMBER(FIND("-CE-",'Libro Diario 1'!#REF!)), ISNUMBER(FIND("-CI-",'Libro Diario 1'!#REF!)), ISNUMBER(FIND("Glosa", 'Libro Diario 1'!#REF!))), "", 'Libro Diario 1'!#REF!) -> #REF! | B52: =IF(OR(ISNUMBER(FIND("-CT-",'Libro Diario 1'!#REF!)),ISNUMBER(FIND("-CE-",'Libro Diario 1'!#REF!)), ISNUMBER(FIND("-CI-",'Libro Diario 1'!#REF!)), ISNUMBER(FIND("Glosa", 'Libro Diario 1'!#REF!))), "", 'Libro Diario 1'!#REF!) -> #REF! | C52: =IF(OR(ISNUMBER(FIND("-CT-",'Libro Diario 1'!#REF!)),ISNUMBER(FIND("-CE-",'Libro Diario 1'!#REF!)), ISNUMBER(FIND("-CI-",'Libro Diario 1'!#REF!)), ISNUMBER(FIND("Glosa", 'Libro Diario 1'!#REF!))), "", 'Libro Diario 1'!#REF!) -> #REF!
B53: =IF(OR(ISNUMBER(FIND("-CT-",'Libro Diario 1'!#REF!)),ISNUMBER(FIND("-CE-",'Libro Diario 1'!#REF!)), ISNUMBER(FIND("-CI-",'Libro Diario 1'!#REF!)), ISNUMBER(FIND("Glosa", 'Libro Diario 1'!#REF!))), "", 'Libro Diario 1'!#REF!) -> #REF! | C53: =IF(OR(ISNUMBER(FIND("-CT-",'Libro Diario 1'!#REF!)),ISNUMBER(FIND("-CE-",'Libro Diario 1'!#REF!)), ISNUMBER(FIND("-CI-",'Libro Diario 1'!#REF!)), ISNUMBER(FIND("Glosa", 'Libro Diario 1'!#REF!))), "", 'Libro Diario 1'!#REF!) -> #REF!
B54: =IF(OR(ISNUMBER(FIND("-CT-",'Libro Diario 1'!#REF!)),ISNUMBER(FIND("-CE-",'Libro Diario 1'!#REF!)), ISNUMBER(FIND("-CI-",'Libro Diario 1'!#REF!)), ISNUMBER(FIND("Glosa", 'Libro Diario 1'!#REF!))), "", 'Libro Diario 1'!#REF!) -> #REF! | C54: =IF(OR(ISNUMBER(FIND("-CT-",'Libro Diario 1'!#REF!)),ISNUMBER(FIND("-CE-",'Libro Diario 1'!#REF!)), ISNUMBER(FIND("-CI-",'Libro Diario 1'!#REF!)), ISNUMBER(FIND("Glosa", 'Libro Diario 1'!#REF!))), "", 'Libro Diario 1'!#REF!) -> #REF!

Sheet Mayores
A4: =+'Libro Diario 1'!B5 -> BANCO GANADERO M/N | D4: CAJA M/N | G4: =+'Libro Diario 1'!$B$7 -> INVENTARIO DE MERCADERIAS | J4: =+'Libro Diario 1'!$B$8 -> ALQUILERES PAGADOS POR ANTICIPADO | M4: =+'Libro Diario 1'!$B$9 -> MUEBLES Y ENSERES | U4: ='Lista de Libros'!S4 -> 0
A5: =+'Libro Diario 1'!C5 -> 255000 | B5: =+'Libro Diario 1'!D23 -> 32500 | D5: 100000 | E5: 3500 | G5: =+'Libro Diario 1'!$C$7 -> 84000 | J5: =+'Libro Diario 1'!$C$8 -> 55000 | M5: =+'Libro Diario 1'!$C$9 -> 12000
A6: =+'Libro Diario 1'!C52 -> 25830 | B6: =+'Libro Diario 1'!D29 -> 90000 | D6: =+'Libro Diario 1'!C33 -> 33000 | E6: =+'Libro Diario 1'!D43 -> 950 | G6: =+'Libro Diario 1'!$C$21 -> 56550 | M6: 2610
A7: =+'Libro Diario 1'!C83 -> 9100 | B7: =+'Libro Diario 1'!D48 -> 76000 | D7: =+'Libro Diario 1'!C60 -> 23400 | E7: =+'Libro Diario 1'!$D$49 -> 19000 | G7: =+'Libro Diario 1'!$C$27 -> 174000
A8: 400000 | B8: =+'Libro Diario 1'!D89 -> 5000 | D8: =+'Libro Diario 1'!C116 -> 73450 | E8: =+'Libro Diario 1'!$D$75 -> 3000 | G8: =+'Libro Diario 1'!$C$46 -> 82650
A9: =+'Libro Diario 1'!C132 -> 39550 | B9: =+'Libro Diario 1'!D93 -> 249256.6 | D9: =+'Libro Diario 1'!C124 -> 26268 | E9: =+'Libro Diario 1'!$D$80 -> 250000 | G9: =+'Libro Diario 1'!$C$68 -> 174000
A10: =+'Libro Diario 1'!C157 -> 140000 | B10: =+'Libro Diario 1'!D138 -> 10000 | D10: =+'Libro Diario 1'!C141 -> 51840 | E10: =+'Libro Diario 1'!$D$158 -> 140000 | G10: =+'Libro Diario 1'!$C$78 -> 217500
B11: =+'Libro Diario 1'!$D$167 -> 236315.85 | D11: =+'Libro Diario 1'!C149 -> 121000 | E11: =+'Libro Diario 1'!$D$163 -> 3256
B12: ='Libro Diario 1'!D185 -> 25198.42
A13: =SUM(A5:A12) -> 869480 | B13: =SUM(B5:B12) -> 724270.87 | D13: =SUM(D5:D12) -> 428958 | E13: =SUM(E5:E12) -> 419706 | G13: =SUM(G5:G12) -> 788700 | H13: =SUM(H5:H12) -> 0 | J13: =SUM(J5:J12) -> 55000 | K13: =SUM(K5:K12) -> 0 | M13: =SUM(M5:M12) -> 14610 | N13: =SUM(N5:N12) -> 0
A14: =A13-B13 -> 145209.13 | D14: =D13-E13 -> 9252 | G14: =+G13 -> 788700 | J14: =+J13 -> 55000 | M14: =+M13 -> 14610
A17: =+'Libro Diario 1'!$B$10 -> EQUIPOS DE COMPUTACION | D17: =+'Libro Diario 1'!$B$11 -> DOCUMENTOS POR PAGAR | G17: =+'Libro Diario 1'!$B$12 -> DEUDAS POR PAGAR | J17: =+'Libro Diario 1'!$B$13 -> CAPITAL SOCIAL | M17: =+'Libro Diario 1'!$B$16 -> GASTOS LEGALES, NOTARIALES Y JUDICIALES
A18: =+'Libro Diario 1'!$C$10 -> 45000 | E18: =+'Libro Diario 1'!$D$11 -> 35000 | H18: =+'Libro Diario 1'!$D$12 -> 350000 | K18: =+'Libro Diario 1'!$D$13 -> 166000 | M18: =+'Libro Diario 1'!$C$16 -> 3045
E19: ='Libro Diario 1'!D24 -> 32500
E20: ='Libro Diario 1'!D30 -> 110000
E21: ='Libro Diario 1'!D70 -> 200000
A27: =+A18 -> 45000 | E27: =SUM(E18:E21) -> 377500 | H27: =+H18 -> 350000 | K27: =+K18 -> 166000 | M27: =+M18 -> 3045
A28: =A27 -> 45000 | E28: =E27 -> 377500 | H28: =H27 -> 350000 | K28: =K27 -> 166000 | M28: =M27 -> 3045
A30: =+'Libro Diario 1'!$B$22 -> CREDITO FISCAL | G30: =+'Libro Diario 1'!$B$34 -> DOCUMENTOS POR COBRAR | J30: =+'Libro Diario 1'!$B$35 -> IMPUESTO A LAS TRANSACCIONES | M30: =+'Libro Diario 1'!$B$36 -> VENTAS
A31: =+'Libro Diario 1'!$C$17 -> 455 | G31: =+'Libro Diario 1'!$C$34 -> 22000 | H31: =+'Libro Diario 1'!$D$84 -> 9100 | J31: =+'Libro Diario 1'!$C$35 -> 1650 | N31: =+'Libro Diario 1'!$D$36 -> 47850
A32: =+'Libro Diario 1'!$C$22 -> 8450 | G32: =+'Libro Diario 1'!$C$53 -> 35670 | H32: =+'Libro Diario 1'!$D$133 -> 39550 | J32: =+'Libro Diario 1'!$C$54 -> 1845 | N32: =+'Libro Diario 1'!$D$55 -> 53505
A33: =+'Libro Diario 1'!$C$28 -> 26000 | G33: =+'Libro Diario 1'!$C$61 -> 9100 | J33: =+'Libro Diario 1'!$C$62 -> 975 | N33: =+'Libro Diario 1'!$D$63 -> 28275
A34: =+'Libro Diario 1'!$C$42 -> 123.5 | G34: =+'Libro Diario 1'!$C$117 -> 39550 | J34: =+'Libro Diario 1'!$C$110 -> 12000 | N34: =+'Libro Diario 1'!$D$111 -> 348000
A35: =+'Libro Diario 1'!$C$47 -> 12350 | G35: =+'Libro Diario 1'!$C$125 -> 105072 | J35: =+'Libro Diario 1'!$C$118 -> 3390 | N35: =+'Libro Diario 1'!$D$119 -> 98310
A36: =+'Libro Diario 1'!$C$69 -> 26000 | G36: =+'Libro Diario 1'!$C$142 -> 63360 | J36: =+'Libro Diario 1'!$C$126 -> 3940.2 | N36: =+'Libro Diario 1'!$D$127 -> 114265.8
A37: =+'Libro Diario 1'!$C$74 -> 390 | J37: =+'Libro Diario 1'!$C$143 -> 3456 | N37: =+'Libro Diario 1'!$D$144 -> 100224
A38: =+'Libro Diario 1'!$C$79 -> 32500 | J38: =+'Libro Diario 1'!$C$150 -> 3630 | N38: =+'Libro Diario 1'!$D$152 -> 105270
A39: =+'Libro Diario 1'!$C$88 -> 650 | J39: =SUM(I31:J38) -> 30886.2
A40: =+'Libro Diario 1'!$C$137 -> 1300 | J40: =+J39 -> 30886.2
A41: =+'Libro Diario 1'!$C$162 -> 423.28
A42: =SUM(A31:A41) -> 108641.78 | B42: 108641.78 | G42: =SUM(G31:G41) -> 274752 | H42: =SUM(H31:H41) -> 48650 | N42: =SUM(N31:N38) -> 895699.8
A43: =A42 -> 108641.78 | B43: 108641.78 | G43: =G42-H42 -> 226102 | N43: =N42 -> 895699.8
A45: =+'Libro Diario 1'!$B$37 -> DEBITO FISCAL | D45: =+'Libro Diario 1'!$B$38 -> IT POR PAGAR | G45: =+'Libro Diario 1'!$B$41 -> MATERIAL DE ESCRITORIO | J45: =+'Libro Diario 1'!$B$87 -> SEGURIDAD Y VIGILANCIA
B46: =+'Libro Diario 1'!$D$37 -> 7150 | E46: =+'Libro Diario 1'!$D$38 -> 1650 | G46: =+'Libro Diario 1'!$C$41 -> 826.5 | J46: =+'Libro Diario 1'!$C$87 -> 4350
B47: =+'Libro Diario 1'!$D$56 -> 7995 | E47: =+'Libro Diario 1'!$D$57 -> 1845
B48: =+'Libro Diario 1'!$D$64 -> 4225 | E48: =+'Libro Diario 1'!$D$65 -> 975
B49: =+'Libro Diario 1'!$D$112 -> 52000 | E49: =+'Libro Diario 1'!$D$113 -> 12000
B50: =+'Libro Diario 1'!$D$120 -> 14690 | E50: =+'Libro Diario 1'!$D$121 -> 3390
B51: =+'Libro Diario 1'!$D$128 -> 17074.2 | E51: =+'Libro Diario 1'!$D$129 -> 3940.2
B52: =+'Libro Diario 1'!$D$145 -> 14976 | E52: =+'Libro Diario 1'!$D$146 -> 3456
...

Sheet HOJA DE TRABAJO
A1: DISTRIBUIDORA "DISMACORP"
A2: HOJA DE TRABAJO PARA LA PREPARACIÓN DE LOS ESTADOS FINANCIEROS
A3: DEL 01 AL 30 DE ABRIL DE 2023
A4: EXPRESADO EN BOLIVIANOS
A6: NRO | B6: CUENTAS | C6: TIPO | D6: SUMAS | F6: SALDOS | H6: ESTADO DE RESULTADOS | J6: BALANCE GENERAL
D7: DEBE | E7: HABER | F7: DEUDOR | G7: ACREEDOR | H7: EGRE/COSTO | I7: INGRESOS | J7: ACTIVOS | K7: PAS/PAT
A8: 1 | B8: BANCO GANADERO M/N | C8: A | D8: =+Mayores!$A$13 -> 869480 | E8: =+Mayores!$B$13 -> 724270.87 | F8: =IF(D8>E8,D8-E8,"") -> 145209.13 | G8: =IF(E8>D8,E8-D8,"") | H8: =IF(C8="E",F8,) -> 0 | I8: =IF(C8="I",G8,0) -> 0 | J8: =IF(C8="A",F8,0) -> 145209.13 | K8: =IF(OR(C8="P",C8="PAT"),G8,0) -> 0
A9: 2 | B9: CAJA M/N | C9: A | D9: =+Mayores!$D$13 -> 428958 | E9: =+Mayores!$E$13 -> 419706 | F9: =IF(D9>E9,D9-E9,"") -> 9252 | G9: =IF(E9>D9,E9-D9,"") | H9: =IF(C9="E",F9,) -> 0 | I9: =IF(C9="I",G9,0) -> 0 | J9: =IF(C9="A",F9,0) -> 9252 | K9: =IF(OR(C9="P",C9="PAT"),G9,0) -> 0
A10: 3 | B10: INVENTARIO DE MERCADERIA | C10: A | D10: =+Mayores!$G$14 -> 788700 | F10: =IF(D10>E10,D10-E10,"") -> 788700 | G10: =IF(E10>D10,E10-D10,"") | H10: =IF(C10="E",F10,) -> 0 | I10: =IF(C10="I",G10,0) -> 0 | J10: =IF(C10="A",F10,0) -> 788700 | K10: =IF(OR(C10="P",C10="PAT"),G10,0) -> 0
A11: 4 | B11: ALQUILERES PAGADO POR ADELANTADO | C11: A | D11: =+Mayores!$J$14 -> 55000 | F11: =IF(D11>E11,D11-E11,"") -> 55000 | G11: =IF(E11>D11,E11-D11,"") | H11: =IF(C11="E",F11,) -> 0 | I11: =IF(C11="I",G11,0) -> 0 | J11: =IF(C11="A",F11,0) -> 55000 | K11: =IF(OR(C11="P",C11="PAT"),G11,0) -> 0
A12: 5 | B12: MUEBLES Y ENSERES | C12: A | D12: =+Mayores!$M$14 -> 14610 | F12: =IF(D12>E12,D12-E12,"") -> 14610 | G12: =IF(E12>D12,E12-D12,"") | H12: =IF(C12="E",F12,) -> 0 | I12: =IF(C12="I",G12,0) -> 0 | J12: =IF(C12="A",F12,0) -> 14610 | K12: =IF(OR(C12="P",C12="PAT"),G12,0) -> 0
A13: 6 | B13: EQUIPOS DE COMPUTACION | C13: A | D13: =+Mayores!$A$28 -> 45000 | F13: =IF(D13>E13,D13-E13,"") -> 45000 | G13: =IF(E13>D13,E13-D13,"") | H13: =IF(C13="E",F13,) -> 0 | I13: =IF(C13="I",G13,0) -> 0 | J13: =IF(C13="A",F13,0) -> 45000 | K13: =IF(OR(C13="P",C13="PAT"),G13,0) -> 0
A14: 7 | B14: DOCUMENTOS POR PAGAR | C14: P | E14: =+Mayores!$E$28 -> 377500 | F14: =IF(D14>E14,D14-E14,"") | G14: =IF(E14>D14,E14-D14,"") -> 377500 | H14: =IF(C14="E",F14,) -> 0 | I14: =IF(C14="I",G14,0) -> 0 | J14: =IF(C14="A",F14,0) -> 0 | K14: =IF(OR(C14="P",C14="PAT"),G14,0) -> 377500
A15: 8 | B15: DEUDAS POR PAGAR | C15: P | E15: =+Mayores!$H$28 -> 350000 | F15: =IF(D15>E15,D15-E15,"") | G15: =IF(E15>D15,E15-D15,"") -> 350000 | H15: =IF(C15="E",F15,) -> 0 | I15: =IF(C15="I",G15,0) -> 0 | J15: =IF(C15="A",F15,0) -> 0 | K15: =IF(OR(C15="P",C15="PAT"),G15,0) -> 350000
A16: 9 | B16: CAPITAL SOCIAL | C16: PAT | E16: =+Mayores!$K$28 -> 166000 | F16: =IF(D16>E16,D16-E16,"") | G16: =IF(E16>D16,E16-D16,"") -> 166000 | H16: =IF(C16="E",F16,) -> 0 | I16: =IF(C16="I",G16,0) -> 0 | J16: =IF(C16="A",F16,0) -> 0 | K16: =IF(OR(C16="P",C16="PAT"),G16,0) -> 166000
A17: 10 | B17: GASTOS LEGALES.NOTARIALES Y JUDICIALES | C17: E | D17: =+Mayores!$M$28 -> 3045 | F17: =IF(D17>E17,D17-E17,"") -> 3045 | G17: =IF(E17>D17,E17-D17,"") | H17: =IF(C17="E",F17,) -> 3045 | I17: =IF(C17="I",G17,0) -> 0 | J17: =IF(C17="A",F17,0) -> 0 | K17: =IF(OR(C17="P",C17="PAT"),G17,0) -> 0
A18: 11 | B18: CREDITO FISCAL | C18: A | D18: =+Mayores!$A$43 -> 108641.78 | E18: =Mayores!B43 -> 108641.78 | F18: =IF(D18>E18,D18-E18,"") | G18: =IF(E18>D18,E18-D18,"") | H18: =IF(C18="E",F18,) -> 0 | I18: =IF(C18="I",G18,0) -> 0 | J18: =IF(C18="A",F18,0) | K18: =IF(OR(C18="P",C18="PAT"),G18,0) -> 0
A19: 13 | B19: DOCUMENTOS POR COBRAR | C19: A | D19: =+Mayores!$G$42 -> 274752 | E19: =+Mayores!$H$42 -> 48650 | F19: =IF(D19>E19,D19-E19,"") -> 226102 | G19: =IF(E19>D19,E19-D19,"") | H19: =IF(C19="E",F19,) -> 0 | I19: =IF(C19="I",G19,0) -> 0 | J19: =IF(C19="A",F19,0) -> 226102 | K19: =IF(OR(C19="P",C19="PAT"),G19,0) -> 0
A20: 14 | B20: IMPUESTO A LAS TRANSACCIONES | C20: E | D20: =+Mayores!$J$40 -> 30886.2 | F20: =IF(D20>E20,D20-E20,"") -> 30886.2 | G20: =IF(E20>D20,E20-D20,"") | H20: =IF(C20="E",F20,) -> 30886.2 | I20: =IF(C20="I",G20,0) -> 0 | J20: =IF(C20="A",F20,0) -> 0 | K20: =IF(OR(C20="P",C20="PAT"),G20,0) -> 0
A21: 15 | B21: VENTAS | C21: I | E21: =+Mayores!$N$43 -> 895699.8 | F21: =IF(D21>E21,D21-E21,"") | G21: =IF(E21>D21,E21-D21,"") -> 895699.8 | H21: =IF(C21="E",F21,) -> 0 | I21: =IF(C21="I",G21,0) -> 895699.8 | J21: =IF(C21="A",F21,0) -> 0 | K21: =IF(OR(C21="P",C21="PAT"),G21,0) -> 0
A22: 16 | B22: DEBITO FISCAL | C22: P | D22: =Mayores!A56 -> 133840.2 | E22: =+Mayores!$B$56 -> 133840.2 | F22: =IF(D22>E22,D22-E22,"") | G22: =IF(E22>D22,E22-D22,"") | H22: =IF(C22="E",F22,) -> 0 | I22: =IF(C22="I",G22,0) -> 0 | J22: =IF(C22="A",F22,0) -> 0 | K22: =IF(OR(C22="P",C22="PAT"),G22,0)
A23: 17 | B23: IT POR PAGAR | C23: P | E23: =+Mayores!$E$56 -> 30886.2 | F23: =IF(D23>E23,D23-E23,"") | G23: =IF(E23>D23,E23-D23,"") -> 30886.2 | H23: =IF(C23="E",F23,) -> 0 | I23: =IF(C23="I",G23,0) -> 0 | J23: =IF(C23="A",F23,0) -> 0 | K23: =IF(OR(C23="P",C23="PAT"),G23,0) -> 30886.2
A24: 18 | B24: MATERIAL DE ESCRITORIO | C24: A | D24: =+Mayores!$G$56 -> 826.5 | F24: =IF(D24>E24,D24-E24,"") -> 826.5 | G24: =IF(E24>D24,E24-D24,"") | H24: =IF(C24="E",F24,) -> 0 | I24: =IF(C24="I",G24,0) -> 0 | J24: =IF(C24="A",F24,0) -> 826.5 | K24: =IF(OR(C24="P",C24="PAT"),G24,0) -> 0
A25: 19 | B25: SEGURIDAD Y VIGILANCIA | C25: A | D25: =+Mayores!$J$56 -> 4350 | F25: =IF(D25>E25,D25-E25,"") -> 4350 | G25: =IF(E25>D25,E25-D25,"") | H25: =IF(C25="E",F25,) -> 0 | I25: =IF(C25="I",G25,0) -> 0 | J25: =IF(C25="A",F25,0) -> 4350 | K25: =IF(OR(C25="P",C25="PAT"),G25,0) -> 0
A26: 20 | B26: COMISIONES | C26: E | D26: =+Mayores!$A$69 -> 285550 | F26: =IF(D26>E26,D26-E26,"") -> 285550 | G26: =IF(E26>D26,E26-D26,"") | H26: =IF(C26="E",F26,) -> 285550 | I26: =IF(C26="I",G26,0) -> 0 | J26: =IF(C26="A",F26,0) -> 0 | K26: =IF(OR(C26="P",C26="PAT"),G26,0) -> 0
A27: 21 | B27: APORTE LABORAL GESTORA POR PAGAR | C27: P | E27: =+Mayores!$E$69 -> 70702.553 | F27: =IF(D27>E27,D27-E27,"") | G27: =IF(E27>D27,E27-D27,"") -> 70702.553 | H27: =IF(C27="E",F27,) -> 0 | I27: =IF(C27="I",G27,0) -> 0 | J27: =IF(C27="A",F27,0) -> 0 | K27: =IF(OR(C27="P",C27="PAT"),G27,0) -> 70702.553
A28: 22 | B28: APORTE PATRONALES GESTORA | C28: E | D28: =+Mayores!$G$69 -> 37326.053 | F28: =IF(D28>E28,D28-E28,"") -> 37326.053 | G28: =IF(E28>D28,E28-D28,"") | H28: =IF(C28="E",F28,) -> 37326.053 | I28: =IF(C28="I",G28,0) -> 0 | J28: =IF(C28="A",F28,0) -> 0 | K28: =IF(OR(C28="P",C28="PAT"),G28,0) -> 0
A29: 23 | B29: CAJA DE SALUD | C29: E | D29: =+Mayores!$J$69 -> 55627.5 | F29: =IF(D29>E29,D29-E29,"") -> 55627.5 | G29: =IF(E29>D29,E29-D29,"") | H29: =IF(C29="E",F29,) -> 55627.5 | I29: =IF(C29="I",G29,0) -> 0 | J29: =IF(C29="A",F29,0) -> 0 | K29: =IF(OR(C29="P",C29="PAT"),G29,0) -> 0
A30: 24 | B30: AGUINALDOS | C30: E | D30: =+Mayores!$M$69 -> 58015.247 | F30: =IF(D30>E30,D30-E30,"") -> 58015.247 | G30: =IF(E30>D30,E30-D30,"") | H30: =IF(C30="E",F30,) -> 58015.247 | I30: =IF(C30="I",G30,0) -> 0 | J30: =IF(C30="A",F30,0) -> 0 | K30: =IF(OR(C30="P",C30="PAT"),G30,0) -> 0
A31: 25 | B31: INDEMNIZACION | C31: E | D31: =+Mayores!$A$83 -> 58015.247 | F31: =IF(D31>E31,D31-E31,"") -> 58015.247 | G31: =IF(E31>D31,E31-D31,"") | H31: =IF(C31="E",F31,) -> 58015.247 | I31: =IF(C31="I",G31,0) -> 0 | J31: =IF(C31="A",F31,0) -> 0 | K31: =IF(OR(C31="P",C31="PAT"),G31,0) -> 0
A32: 26 | B32: PRIMAS | C32: E | D32: =+Mayores!$D$83 -> 58015.247 | F32: =IF(D32>E32,D32-E32,"") -> 58015.247 | G32: =IF(E32>D32,E32-D32,"") | H32: =IF(C32="E",F32,) -> 58015.247 | I32: =IF(C32="I",G32,0) -> 0 | J32: =IF(C32="A",F32,0) -> 0 | K32: =IF(OR(C32="P",C32="PAT"),G32,0) -> 0
A33: 27 | B33: APORTE PATRONALES GESTORA POR PAGAR | C33: P | D33: =Mayores!G12 -> 0 | E33: =+Mayores!$H$83 -> 37326.053 | F33: =IF(D33>E33,D33-E33,"") | G33: =IF(E33>D33,E33-D33,"") -> 37326.053 | H33: =IF(C33="E",F33,) -> 0 | I33: =IF(C33="I",G33,0) -> 0 | J33: =IF(C33="A",F33,0) -> 0 | K33: =IF(OR(C33="P",C33="PAT"),G33,0) -> 37326.053
A34: 28 | B34: CAJA DE SALUD POR PAGAR | C34: P | D34: =Mayores!J9 -> 0 | E34: =+Mayores!$K$83 -> 55627.5 | F34: =IF(D34>E34,D34-E34,"") | G34: =IF(E34>D34,E34-D34,"") -> 55627.5 | H34: =IF(C34="E",F34,) -> 0 | I34: =IF(C34="I",G34,0) -> 0 | J34: =IF(C34="A",F34,0) -> 0 | K34: =IF(OR(C34="P",C34="PAT"),G34,0) -> 55627.5
A35: 29 | B35: AGUINALDOS POR PAGAR | C35: P | D35: =Mayores!M9 -> 0 | E35: =+Mayores!$N$83 -> 58015.247 | F35: =IF(D35>E35,D35-E35,"") | G35: =IF(E35>D35,E35-D35,"") -> 58015.247 | H35: =IF(C35="E",F35,) -> 0 | I35: =IF(C35="I",G35,0) -> 0 | J35: =IF(C35="A",F35,0) -> 0 | K35: =IF(OR(C35="P",C35="PAT"),G35,0) -> 58015.247
A36: 30 | B36: PREVISION PARA INDEMNIZACION | C36: P | E36: =+Mayores!$B$97 -> 58015.247 | F36: =IF(D36>E36,D36-E36,"") | G36: =IF(E36>D36,E36-D36,"") -> 58015.247 | H36: =IF(C36="E",F36,) -> 0 | I36: =IF(C36="I",G36,0) -> 0 | J36: =IF(C36="A",F36,0) -> 0 | K36: =IF(OR(C36="P",C36="PAT"),G36,0) -> 58015.247
A37: 31 | B37: PRIMAS POR PAGAR | C37: P | D37: =Mayores!D21 -> 0 | E37: =+Mayores!$E$97 -> 58015.247 | F37: =IF(D37>E37,D37-E37,"") | G37: =IF(E37>D37,E37-D37,"") -> 58015.247 | H37: =IF(C37="E",F37,) -> 0 | I37: =IF(C37="I",G37,0) -> 0 | J37: =IF(C37="A",F37,0) -> 0 | K37: =IF(OR(C37="P",C37="PAT"),G37,0) -> 58015.247
A38: 32 | B38: PUBLICIDAD EN RADIO Y T.V. | C38: E | D38: =+Mayores!$G$97 -> 8700 | E38: =Mayores!H19 -> 0 | F38: =IF(D38>E38,D38-E38,"") -> 8700 | G38: =IF(E38>D38,E38-D38,"") | H38: =IF(C38="E",F38,) -> 8700 | I38: =IF(C38="I",G38,0) -> 0 | J38: =IF(C38="A",F38,0) -> 0 | K38: =IF(OR(C38="P",C38="PAT"),G38,0) -> 0
A39: 33 | B39: ENERGIA ELECTRICA | C39: E | D39: =+Mayores!$J$97 -> 2832.72 | E39: =Mayores!K25 -> 0 | F39: =IF(D39>E39,D39-E39,"") -> 2832.72 | G39: =IF(E39>D39,E39-D39,"") | H39: =IF(C39="E",F39,) -> 2832.72 | I39: =IF(C39="I",G39,0) -> 0 | J39: =IF(C39="A",F39,0) -> 0 | K39: =IF(OR(C39="P",C39="PAT"),G39,0) -> 0
A40: 34 | B40: SUELDOS Y SALARIOS | C40: E | D40: =+Mayores!$M$97 -> 270725 | F40: =IF(D40>E40,D40-E40,"") -> 270725 | G40: =IF(E40>D40,E40-D40,"") | H40: =IF(C40="E",F40,) -> 270725 | I40: =IF(C40="I",G40,0) -> 0 | J40: =IF(C40="A",F40,0) -> 0 | K40: =IF(OR(C40="P",C40="PAT"),G40,0) -> 0
D41: =SUM(D8:D40) -> 3592896.7 | E41: =SUM(E8:E40) -> 3592896.7 | F41: =SUM(F8:F40) -> 2157787.8 | G41: =SUM(G8:G40) -> 2157787.8 | H41: =SUM(H8:H40) -> 868738.21 | I41: =SUM(I8:I40) -> 895699.8 | J41: =SUM(J8:J40) -> 1289049.6 | K41: =SUM(K8:K40) -> 1262088
...

Sheet ER
A1: DISTRIBUIDORA "DISMACORP"
A3: ESTADO DE RESULTADOS
A4: Del 01 al 30 de abril de 2023
A5: (Expresado en bolivianos)
A7: VENTAS NETAS | D7: =SUM(C8:C10) -> 895699.8
B8: Ventas | C8: ='HOJA DE TRABAJO'!G21 -> 895699.8
A9: (-) | B9: Devoluciones s/ventas | C9: 0
A10: (-) | B10: Descuento s/ventas | C10: 0
A12: COSTO DE VENTAS | D12: 0
B13: Costo de ventas | C13: 0
B15: UTILIDAD BRUTA EN VENTAS | D15: =+D7-D12 -> 895699.8
A17: GASTOS OPERATIVOS | D17: =SUM(C18:C28) -> 868738.21
B18: I.T. | C18: ='HOJA DE TRABAJO'!F20 -> 30886.2
B19: ='HOJA DE TRABAJO'!B17 -> GASTOS LEGALES.NOTARIALES Y JUDICIALES | C19: ='HOJA DE TRABAJO'!F17 -> 3045
B20: ='HOJA DE TRABAJO'!B40 -> SUELDOS Y SALARIOS | C20: ='HOJA DE TRABAJO'!F40 -> 270725
B21: ='HOJA DE TRABAJO'!B26 -> COMISIONES | C21: ='HOJA DE TRABAJO'!F26 -> 285550
B22: ='HOJA DE TRABAJO'!B38 -> PUBLICIDAD EN RADIO Y T.V. | C22: ='HOJA DE TRABAJO'!F38 -> 8700
B23: ='HOJA DE TRABAJO'!B39 -> ENERGIA ELECTRICA | C23: ='HOJA DE TRABAJO'!F39 -> 2832.72
B24: {='HOJA DE TRABAJO'!B28:B32} -> APORTE PATRONALES GESTORA | C24: {='HOJA DE TRABAJO'!F28:F32} -> 37326.053
B25: CAJA DE SALUD | C25: 55627.5
B26: AGUINALDOS | C26: 58015.247
B27: INDEMNIZACION | C27: 58015.247
B28: PRIMAS | C28: 58015.247
B31: GANANCIA OPERATIVA | D31: =D15-D17 -> 26961.588
B34: GANANCIA DEL EJERCICIO | D34: =D31 -> 26961.588
B39: GERENTE GENERAL | C39: CONTADOR

Sheet BG
A1: DISTRIBUIDORA DISMACORP
A3: BALANCE GENERAL
A4: Al 30 de abril de 2023
A5: (Expresado en bolivianos)
A7: ACTIVO
B8: ACTIVO CORRIENTE | D8: =SUM(C9:C13) -> 1224263.1
B9: CAJA MN | C9: ='HOJA DE TRABAJO'!F9 -> 9252
B10: BANCO GANADERO M/N | C10: ='HOJA DE TRABAJO'!F8 -> 145209.13
B11: INVENTARIO DE MERCADERIAS | C11: ='HOJA DE TRABAJO'!F10 -> 788700
B12: DOCUMENTOS POR COBRAR | C12: ='HOJA DE TRABAJO'!F19 -> 226102
B13: ALQUILERES PAGADOS POR ANTICIPADO | C13: ='HOJA DE TRABAJO'!F11 -> 55000
B16: ACTIVO NO CORRIENTE | D16: =SUM(C17:C20) -> 64786.5
B17: MUEBLES Y ENSERES | C17: ='HOJA DE TRABAJO'!F12 -> 14610
B18: SEGURIDAD Y VIGILANCIA | C18: ='HOJA DE TRABAJO'!F25 -> 4350
B19: EQUIPOS DE COMPUTACION | C19: ='HOJA DE TRABAJO'!F13 -> 45000
B20: MATERIAL DE ESCRITORIO | C20: ='HOJA DE TRABAJO'!F24 -> 826.5
B22: TOTAL ACTIVO | D22: =+D8+D16 -> 1289049.6
A24: PASIVO
B25: PASIVO CORRIENTE | D25: =SUM(C26:C34) -> 1096088
B26: I.T. POR PAGAR | C26: ='HOJA DE TRABAJO'!G23 -> 30886.2
B27: DOCUMENTOS POR PAGAR | C27: ='HOJA DE TRABAJO'!G14 -> 377500
B28: DEUDAS POR PAGAR | C28: ='HOJA DE TRABAJO'!G15 -> 350000
B29: ='HOJA DE TRABAJO'!B27 -> APORTE LABORAL GESTORA POR PAGAR | C29: ='HOJA DE TRABAJO'!G27 -> 70702.553
B30: {='HOJA DE TRABAJO'!B33:B37} -> APORTE PATRONALES GESTORA POR PAGAR | C30: {='HOJA DE TRABAJO'!G33:G37} -> 37326.053
B31: CAJA DE SALUD POR PAGAR | C31: 55627.5
B32: AGUINALDOS POR PAGAR | C32: 58015.247
B33: PREVISION PARA INDEMNIZACION | C33: 58015.247
B34: PRIMAS POR PAGAR | C34: 58015.247
A36: PATRIMONIO
B37: CAPITAL | D37: =+C39+C38 -> 192961.59
B38: CAPITAL SOCIAL | C38: ='HOJA DE TRABAJO'!G16 -> 166000
B39: GANANCIA DEL EJERCICIO | C39: =ER!D34 -> 26961.588
B42: TOTAL PASIVO Y PATRIMONIO | D42: =D25+D37 -> 1289049.6
B47: GERENTE GENERAL | D47: CONTADOR

Sheet AP. Y BENEFICIOS
A9: NOMBRE O RAZÓN SOCIAL
A10: Nº EMPLEADOR CAJA DE SALUD
A11: NIT
A12: DIRECCIÓN
A13: TELEFÓNO
A14: PLANILLA DE APORTES PATRONALES Y BENEFICIOS SOCIALES
A15: PERSONAL PERMANENTE
A16: (Expresado en Bolivianos)
A18: CORRESPONDIENTE AL MES DE NOVIEMBRE DE 2023
A20: Nº | B20: CARNET DE IDENTIDAD | C20: APELLIDOS Y NOMBRE | F20: NACIONALIDAD | G20: FECHA DE NACIMIENTO | H20: SEXO (F/M) | I20: OCUPACIÓN QUE DESEMPEÑA | J20: FECHA DE INGRESO | K20: DÍAS PAGADOS MES | L20: HABER BASICO | M20: BONO DE ANTIGÜEDAD | N20: HRS. EXTRAS | P20: BONOS | S20: TOTAL GANADO | T20: GESTORA | U20: TOTAL GANADO | V20: TOTAL GANADO | W20: TOTAL GANADO | X20: TOTAL DCTOS. | Y20: CAJA DE SALUD | Z20: AGUINALDO | AA20: INDEMNIZACION | AB20: PRIMAS
O22: MONTO | P22: BONO DE | Q22: DOMINICA- | R22: OTROS
N23: No. | O23: PAGADO | P23: PRODUCC. | Q23: LES | R23: BONOS | T23: 0.0671 | U23: (G) | V23: (G) | W23: (G) | X23: (K) | Y23: 0.1 | Z23: =1/12 -> 0.083333333 | AA23: =1/12 -> 0.083333333 | AB23: =1/12 -> 0.083333333
A25: 1 | C25: TRABAJADORES | K25: 31 | L25: 16000 | M25: 0 | S25: 298725 | T25: =S25*T23 -> 20044.448 | Y25: =S25*Y23 -> 29872.5 | Z25: =S25/12 -> 24893.75 | AA25: =+Z25 -> 24893.75 | AB25: =+AA25 -> 24893.75
A32: TOTALES | L32: =SUM(L25:L31) -> 16000 | M32: =SUM(M25:M31) -> 0 | N32: 0 | O32: 0 | P32: =SUM(P25:P31) -> 0 | Q32: 0 | R32: 0 | S32: =SUM(S25:S31) -> 298725 | T32: =SUM(T25:T31) -> 20044.448 | U32: =SUM(U25:U31) -> 0 | V32: =SUM(V25:V31) -> 0 | W32: =SUM(W25:W31) -> 0 | X32: =SUM(X25:X31) -> 0 | Y32: =SUM(Y25:Y31) -> 29872.5 | Z32: =SUM(Z25:Z31) -> 24893.75 | ... AB32: =SUM(AB25:AB31) -> 24893.75
G38: EDUARDO VARGAS ROMAN | N38: 3200134 S.C
G39: NOMBRE DEL EMPLEADOR O REPRESENTANTE LEGAL | N39: Nº DE DOCUMENTO DE IDENTIDAD | S39: FIRMA | X39: FECHA: 30 DE JUNIO DE 2023
