Workbook

Sheet plan
B1: CÓDIGO | C1: DESCRIPCIÓN
B2: 1-0-00-00-000 | C2: ACTIVO
B3: 1-1-00-00-000 | C3: ACTIVO CORRIENTE
B4: 1-1-01-00-000 | C4: DISPONIBLE
B5: 1-1-01-01-000 | C5: DISPONIBLE EN MN
B6: 1-1-01-01-001 | C6: CAJA M/N
B7: 1-1-01-01-002 | C7: BANCO BNB MN
B8: 1-1-01-01-003 | C8: CAJA CHICA ADM
B9: 1-1-01-01-004 | C9: BANCO BISA M/N
B10: 1-1-01-01-005 | C10: CAJA CHICA COM
B11: 1-1-01-02-000 | C11: DISPONIBLE EN M/E
B12: 1-1-01-02-001 | C12: CAJA M/E
... B115: 3-1-01-01-000 | C115: CAPITAL CONTABLE
A116: # | B116: 3-1-01-01-001 | C116: CAPITAL SOCIAL
B117: 3-1-01-02-000 | C117: AJUSTES
A118: # | B118: 3-1-01-02-001 | C118: AJUSTE DE CAPITAL
A119: @ | B119: 3-1-01-02-002 | C119: AJUSTE DE RESERVAS PATRIMONIALES
A120: @ | B120: 3-1-01-02-003 | C120: AJUSTE GLOBAL AL PATRIMONIO
A121: @ | B121: 3-1-01-02-004 | C121: APORTES POR CAPITALIZAR
B122: 3-1-01-03-000 | C122: RESULTADOS
A123: $ | B123: 3-1-01-03-001 | C123: RESULTADO DE LA GESTION
A124: $ | B124: 3-1-01-03-002 | C124: RESULTADOS ACUMULADOS
B125: 3-1-01-04-000 | C125: APORTES POR CAPITALIZAR
B126: 4-0-00-00-000 | C126: INGRESOS
B127: 4-1-00-00-000 | C127: INGRESOS OPERATIVOS
B128: 4-1-01-00-000 | C128: INGRESOS POR VENTAS
B129: 4-1-01-01-000 | C129: VENTAS
B130: 4-1-01-01-001 | C130: VENTAS
B131: 4-2-00-00-000 | C131: INGRESOS NO OPERATIVOS
B132: 4-2-01-00-000 | C132: INGRESOS FINANCIEROS
B133: 4-2-01-01-000 | C133: INTERESES
B134: 4-2-01-01-001 | C134: INTERES BANCARIO GANADO
B135: 4-2-01-02-000 | C135: OTROS INGRESOS
B136: 4-2-01-02-001 | C136: AJUSTE POR INFLACION Y TENENCIA DE BIENES
... B270: 6-3-01-01-001 | C270: GASTOS DE REPRESENTACION

Sheet Blce. Apertura
A1: Comercial "LOS ROBLES"
A2: BALANCE DE APERTURA
A3: Practicado al 01 de Abril de 2023
A4: (Expresado en bolivianos)
A6: ACTIVO
B7: ACTIVO CORRIENTE | D7: =SUM(D8:D11) -> 48000
B8: Banco Ganadero M/N | D8: 26000
B9: Inventario de Mercaderia | D9: 8000
B10: Deudas por cobrar | D10: 2000
B11: Alquileres pagados por anticipado | D11: 12000
B13: ACTIVO NO CORRIENTE | D13: =D14 -> 6000
B14: Muebles y enseres | D14: 6000
B16: TOTAL ACTIVO | D16: =D7+D13 -> 54000
H17: |
A18: PASIVO
B19: PASIVO CORRIENTE | D19: =SUM(D20:D21) -> 10000
B20: Documentos por Pagar | D20: 6000
B21: Cuentas por Pagar | D21: 4000
B23: PASIVO NO CORRIENTE
A25: PATRIMONIO
B26: Capital Social | D26: =SUM(D16-D19) -> 44000
B28: TOTAL PASIVO Y PATRIMONIO | D28: =SUM(D19+D26) -> 54000

Sheet Libro Diario 1
A1: LIBRO DIARIO (COMPROBANTES)
A3: FECHA | B3: DETALLE | C3: DEBE | D3: HABER
A4: 45017 | B4: ----------CT-01--------
B5: BANCO GANADERO M/N | C5: 26000
B6: INVENTARIO DE MERCADERIAS | C6: 8000
B7: MUEBLES Y ENSERES | C7: 6000
B8: CUENTAS POR COBRAR | C8: 2000
B9: ALQUILERES PAGADOS POR ANTICIPADO | C9: 12000
B10: DOCUMENTOS POR PAGAR | D10: 6000
B11: DEUDAS POR PAGAR | D11: 4000
B12: CAPITAL SOCIAL | D12: ='Blce. Apertura'!D26 -> 44000
B13: Glosa: Por inicio de actividades
A14: 45018 | B14: -----------CI-01----------
B15: CAJA M/N | C15: 7000
B16: IMPUESTO A LAS TRANSACCIONES | C16: =7000*0.03 -> 210
B17: VENTAS | D17: =7000*0.87 -> 6090
B18: DEBITO FISCAL | D18: =7000*0.13 -> 910
B19: IT POR PAGAR | D19: =C16 -> 210
B20: Glosa: Por venta de mercaderia s/fact # 101
A21: 45020 | B21: ------------CT-02------------
B22: DEUDAS POR PAGAR | C22: 4000
B23: BANCO GANADERO M/N | D23: 4000
B24: Glosa: Por cancelacion de deuda con "Gato Blanco"
A25: 45022 | B25: -----------CE-01----------
B26: INVENTARIO DE MERCADERIAS | C26: =9000*0.87 -> 7830
B27: CREDITO FISCAL | C27: =9000*0.13 -> 1170
B28: DEUDAS POR PAGAR | D28: 9000
B29: Glosa: Por compra al credito de mercaderia s/fact # 490
A30: 45026 | B30: ---------CI-02---------
B31: CAJA M/N | C31: =10000*0.8 -> 8000
B32: DOCUMENTOS POR COBRAR | C32: =10000*0.2 -> 2000
B33: IMPUESTO A LAS TRANSACCIONES | C33: =10000*0.03 -> 300
B34: VENTAS | D34: =10000*0.87 -> 8700
B35: DEBITO FISCAL | D35: =10000*0.13 -> 1300
B36: IT POR PAGAR | D36: =C33 -> 300
B37: Glosa: Por venta de mercaderia s/fact # 4031
A38: 45031 | B38: ---------CE-02---------
B39: MANTENIMIENTO MOBILIARIO | C39: 70
B40: CREDITO FISCAL | C40: 30
B41: CAJA M/N | D41: 100
...

Sheet Lista de Libros
A1: =IF(OR(ISNUMBER(FIND("-CT-",'Libro Diario 1'!B4)),ISNUMBER(FIND("-CE-",'Libro Diario 1'!B4)), ISNUMBER(FIND("-CI-",'Libro Diario 1'!B4)), ISNUMBER(FIND("Glosa", 'Libro Diario 1'!B4))), "", 'Libro Diario 1'!B4) | B1: =IF(OR(ISNUMBER(FIND("-CT-",'Libro Diario 1'!C4)),ISNUMBER(FIND("-CE-",'Libro Diario 1'!C4)), ISNUMBER(FIND("-CI-",'Libro Diario 1'!C4)), ISNUMBER(FIND("Glosa", 'Libro Diario 1'!C4))), "", 'Libro Diario 1'!C4) -> 0 | C1: =IF(OR(ISNUMBER(FIND("-CT-",'Libro Diario 1'!D4)),ISNUMBER(FIND("-CE-",'Libro Diario 1'!D4)), ISNUMBER(FIND("-CI-",'Libro Diario 1'!D4)), ISNUMBER(FIND("Glosa", 'Libro Diario 1'!D4))), "", 'Libro Diario 1'!D4) -> 0
A2: =IF(OR(ISNUMBER(FIND("-CT-",'Libro Diario 1'!B5)),ISNUMBER(FIND("-CE-",'Libro Diario 1'!B5)), ISNUMBER(FIND("-CI-",'Libro Diario 1'!B5)), ISNUMBER(FIND("Glosa", 'Libro Diario 1'!B5))), "", 'Libro Diario 1'!B5) -> BANCO GANADERO M/N | B2: =IF(OR(ISNUMBER(FIND("-CT-",'Libro Diario 1'!C5)),ISNUMBER(FIND("-CE-",'Libro Diario 1'!C5)), ISNUMBER(FIND("-CI-",'Libro Diario 1'!C5)), ISNUMBER(FIND("Glosa", 'Libro Diario 1'!C5))), "", 'Libro Diario 1'!C5) -> 26000 | C2: =IF(OR(ISNUMBER(FIND("-CT-",'Libro Diario 1'!D5)),ISNUMBER(FIND("-CE-",'Libro Diario 1'!D5)), ISNUMBER(FIND("-CI-",'Libro Diario 1'!D5)), ISNUMBER(FIND("Glosa", 'Libro Diario 1'!D5))), "", 'Libro Diario 1'!D5) -> 0 | E2: BANCO GANADERO M/N | F2: =SUMIF(A1:A54,E2,B1:B54) -> 26000 | G2: =SUMIF(A1:A54,E2,C1:C54) -> 4800
A3: =IF(OR(ISNUMBER(FIND("-CT-",'Libro Diario 1'!B6)),ISNUMBER(FIND("-CE-",'Libro Diario 1'!B6)), ISNUMBER(FIND("-CI-",'Libro Diario 1'!B6)), ISNUMBER(FIND("Glosa", 'Libro Diario 1'!B6))), "", 'Libro Diario 1'!B6) -> INVENTARIO DE MERCADERIAS | B3: =IF(OR(ISNUMBER(FIND("-CT-",'Libro Diario 1'!C6)),ISNUMBER(FIND("-CE-",'Libro Diario 1'!C6)), ISNUMBER(FIND("-CI-",'Libro Diario 1'!C6)), ISNUMBER(FIND("Glosa", 'Libro Diario 1'!C6))), "", 'Libro Diario 1'!C6) -> 8000 | C3: =IF(OR(ISNUMBER(FIND("-CT-",'Libro Diario 1'!D6)),ISNUMBER(FIND("-CE-",'Libro Diario 1'!D6)), ISNUMBER(FIND("-CI-",'Libro Diario 1'!D6)), ISNUMBER(FIND("Glosa", 'Libro Diario 1'!D6))), "", 'Libro Diario 1'!D6) -> 0 | E3: INVENTARIO DE MERCADERIAS | F3: =SUMIF(A2:A55,E3,B2:B55) -> 15830 | G3: =SUMIF(A2:A55,E3,C2:C55) -> 0
A4: =IF(OR(ISNUMBER(FIND("-CT-",'Libro Diario 1'!B7)),ISNUMBER(FIND("-CE-",'Libro Diario 1'!B7)), ISNUMBER(FIND("-CI-",'Libro Diario 1'!B7)), ISNUMBER(FIND("Glosa", 'Libro Diario 1'!B7))), "", 'Libro Diario 1'!B7) -> MUEBLES Y ENSERES | B4: =IF(OR(ISNUMBER(FIND("-CT-",'Libro Diario 1'!C7)),ISNUMBER(FIND("-CE-",'Libro Diario 1'!C7)), ISNUMBER(FIND("-CI-",'Libro Diario 1'!C7)), ISNUMBER(FIND("Glosa", 'Libro Diario 1'!C7))), "", 'Libro Diario 1'!C7) -> 6000 | C4: =IF(OR(ISNUMBER(FIND("-CT-",'Libro Diario 1'!D7)),ISNUMBER(FIND("-CE-",'Libro Diario 1'!D7)), ISNUMBER(FIND("-CI-",'Libro Diario 1'!D7)), ISNUMBER(FIND("Glosa", 'Libro Diario 1'!D7))), "", 'Libro Diario 1'!D7) -> 0 | E4: MUEBLES Y ENSERES | F4: =SUMIF(A3:A56,E4,B3:B56) -> 7305 | G4: =SUMIF(A3:A56,E4,C3:C56) -> 0
A5: =IF(OR(ISNUMBER(FIND("-CT-",'Libro Diario 1'!B8)),ISNUMBER(FIND("-CE-",'Libro Diario 1'!B8)), ISNUMBER(FIND("-CI-",'Libro Diario 1'!B8)), ISNUMBER(FIND("Glosa", 'Libro Diario 1'!B8))), "", 'Libro Diario 1'!B8) -> CUENTAS POR COBRAR | B5: =IF(OR(ISNUMBER(FIND("-CT-",'Libro Diario 1'!C8)),ISNUMBER(FIND("-CE-",'Libro Diario 1'!C8)), ISNUMBER(FIND("-CI-",'Libro Diario 1'!C8)), ISNUMBER(FIND("Glosa", 'Libro Diario 1'!C8))), "", 'Libro Diario 1'!C8) -> 2000 | C5: =IF(OR(ISNUMBER(FIND("-CT-",'Libro Diario 1'!D8)),ISNUMBER(FIND("-CE-",'Libro Diario 1'!D8)), ISNUMBER(FIND("-CI-",'Libro Diario 1'!D8)), ISNUMBER(FIND("Glosa", 'Libro Diario 1'!D8))), "", 'Libro Diario 1'!D8) -> 0 | E5: CUENTAS POR COBRAR | F5: =SUMIF(A4:A57,E5,B4:B57) -> 2000 | G5: =SUMIF(A4:A57,E5,C4:C57) -> 0
A6: =IF(OR(ISNUMBER(FIND("-CT-",'Libro Diario 1'!B9)),ISNUMBER(FIND("-CE-",'Libro Diario 1'!B9)), ISNUMBER(FIND("-CI-",'Libro Diario 1'!B9)), ISNUMBER(FIND("Glosa", 'Libro Diario 1'!B9))), "", 'Libro Diario 1'!B9) -> ALQUILERES PAGADOS POR ANTICIPADO | B6: =IF(OR(ISNUMBER(FIND("-CT-",'Libro Diario 1'!C9)),ISNUMBER(FIND("-CE-",'Libro Diario 1'!C9)), ISNUMBER(FIND("-CI-",'Libro Diario 1'!C9)), ISNUMBER(FIND("Glosa", 'Libro Diario 1'!C9))), "", 'Libro Diario 1'!C9) -> 12000 | C6: =IF(OR(ISNUMBER(FIND("-CT-",'Libro Diario 1'!D9)),ISNUMBER(FIND("-CE-",'Libro Diario 1'!D9)), ISNUMBER(FIND("-CI-",'Libro Diario 1'!D9)), ISNUMBER(FIND("Glosa", 'Libro Diario 1'!D9))), "", 'Libro Diario 1'!D9) -> 0 | E6: ALQUILERES PAGADOS POR ANTICIPADO | F6: =SUMIF(A5:A58,E6,B5:B58) -> 12000 | G6: =SUMIF(A5:A58,E6,C5:C58) -> 0
A7: =IF(OR(ISNUMBER(FIND("-CT-",'Libro Diario 1'!B10)),ISNUMBER(FIND("-CE-",'Libro Diario 1'!B10)), ISNUMBER(FIND("-CI-",'Libro Diario 1'!B10)), ISNUMBER(FIND("Glosa", 'Libro Diario 1'!B10))), "", 'Libro Diario 1'!B10) -> DOCUMENTOS POR PAGAR | B7: =IF(OR(ISNUMBER(FIND("-CT-",'Libro Diario 1'!C10)),ISNUMBER(FIND("-CE-",'Libro Diario 1'!C10)), ISNUMBER(FIND("-CI-",'Libro Diario 1'!C10)), ISNUMBER(FIND("Glosa", 'Libro Diario 1'!C10))), "", 'Libro Diario 1'!C10) -> 0 | C7: =IF(OR(ISNUMBER(FIND("-CT-",'Libro Diario 1'!D10)),ISNUMBER(FIND("-CE-",'Libro Diario 1'!D10)), ISNUMBER(FIND("-CI-",'Libro Diario 1'!D10)), ISNUMBER(FIND("Glosa", 'Libro Diario 1'!D10))), "", 'Libro Diario 1'!D10) -> 6000 | E7: DOCUMENTOS POR PAGAR | F7: =SUMIF(A6:A59,E7,B6:B59) -> 0 | G7: =SUMIF(A6:A59,E7,C6:C59) -> 6000
A8: =IF(OR(ISNUMBER(FIND("-CT-",'Libro Diario 1'!B11)),ISNUMBER(FIND("-CE-",'Libro Diario 1'!B11)), ISNUMBER(FIND("-CI-",'Libro Diario 1'!B11)), ISNUMBER(FIND("Glosa", 'Libro Diario 1'!B11))), "", 'Libro Diario 1'!B11) -> DEUDAS POR PAGAR | B8: =IF(OR(ISNUMBER(FIND("-CT-",'Libro Diario 1'!C11)),ISNUMBER(FIND("-CE-",'Libro Diario 1'!C11)), ISNUMBER(FIND("-CI-",'Libro Diario 1'!C11)), ISNUMBER(FIND("Glosa", 'Libro Diario 1'!C11))), "", 'Libro Diario 1'!C11) -> 0 | C8: =IF(OR(ISNUMBER(FIND("-CT-",'Libro Diario 1'!D11)),ISNUMBER(FIND("-CE-",'Libro Diario 1'!D11)), ISNUMBER(FIND("-CI-",'Libro Diario 1'!D11)), ISNUMBER(FIND("Glosa", 'Libro Diario 1'!D11))), "", 'Libro Diario 1'!D11) -> 4000 | E8: DEUDAS POR PAGAR | F8: =SUMIF(A7:A60,E8,B7:B60) -> 4000 | G8: =SUMIF(A7:A60,E8,C7:C60) -> 13000
A9: =IF(OR(ISNUMBER(FIND("-CT-",'Libro Diario 1'!B12)),ISNUMBER(FIND("-CE-",'Libro Diario 1'!B12)), ISNUMBER(FIND("-CI-",'Libro Diario 1'!B12)), ISNUMBER(FIND("Glosa", 'Libro Diario 1'!B12))), "", 'Libro Diario 1'!B12) -> CAPITAL SOCIAL | B9: =IF(OR(ISNUMBER(FIND("-CT-",'Libro Diario 1'!C12)),ISNUMBER(FIND("-CE-",'Libro Diario 1'!C12)), ISNUMBER(FIND("-CI-",'Libro Diario 1'!C12)), ISNUMBER(FIND("Glosa", 'Libro Diario 1'!C12))), "", 'Libro Diario 1'!C12) -> 0 | C9: =IF(OR(ISNUMBER(FIND("-CT-",'Libro Diario 1'!D12)),ISNUMBER(FIND("-CE-",'Libro Diario 1'!D12)), ISNUMBER(FIND("-CI-",'Libro Diario 1'!D12)), ISNUMBER(FIND("Glosa", 'Libro Diario 1'!D12))), "", 'Libro Diario 1'!D12) -> 44000 | E9: CAPITAL SOCIAL | F9: =SUMIF(A8:A61,E9,B8:B61) -> 0 | G9: =SUMIF(A8:A61,E9,C8:C61) -> 44000
A10: =IF(OR(ISNUMBER(FIND("-CT-",'Libro Diario 1'!B13)),ISNUMBER(FIND("-CE-",'Libro Diario 1'!B13)), ISNUMBER(FIND("-CI-",'Libro Diario 1'!B13)), ISNUMBER(FIND("Glosa", 'Libro Diario 1'!B13))), "", 'Libro Diario 1'!B13) | B10: =IF(OR(ISNUMBER(FIND("-CT-",'Libro Diario 1'!C13)),ISNUMBER(FIND("-CE-",'Libro Diario 1'!C13)), ISNUMBER(FIND("-CI-",'Libro Diario 1'!C13)), ISNUMBER(FIND("Glosa", 'Libro Diario 1'!C13))), "", 'Libro Diario 1'!C13) -> 0 | C10: =IF(OR(ISNUMBER(FIND("-CT-",'Libro Diario 1'!D13)),ISNUMBER(FIND("-CE-",'Libro Diario 1'!D13)), ISNUMBER(FIND("-CI-",'Libro Diario 1'!D13)), ISNUMBER(FIND("Glosa", 'Libro Diario 1'!D13))), "", 'Libro Diario 1'!D13) -> 0 | E10: CAJA M/N | F10: =SUMIF(A9:A62,E10,B9:B62) -> 15800 | G10: =SUMIF(A9:A62,E10,C9:C62) -> 2800
A11: =IF(OR(ISNUMBER(FIND("-CT-",'Libro Diario 1'!B14)),ISNUMBER(FIND("-CE-",'Libro Diario 1'!B14)), ISNUMBER(FIND("-CI-",'Libro Diario 1'!B14)), ISNUMBER(FIND("Glosa", 'Libro Diario 1'!B14))), "", 'Libro Diario 1'!B14) | B11: =IF(OR(ISNUMBER(FIND("-CT-",'Libro Diario 1'!C14)),ISNUMBER(FIND("-CE-",'Libro Diario 1'!C14)), ISNUMBER(FIND("-CI-",'Libro Diario 1'!C14)), ISNUMBER(FIND("Glosa", 'Libro Diario 1'!C14))), "", 'Libro Diario 1'!C14) -> 0 | C11: =IF(OR(ISNUMBER(FIND("-CT-",'Libro Diario 1'!D14)),ISNUMBER(FIND("-CE-",'Libro Diario 1'!D14)), ISNUMBER(FIND("-CI-",'Libro Diario 1'!D14)), ISNUMBER(FIND("Glosa", 'Libro Diario 1'!D14))), "", 'Libro Diario 1'!D14) -> 0 | E11: IMPUESTO A LAS TRANSACCIONES | F11: =SUMIF(A10:A63,E11,B10:B63) -> 510 | G11: =SUMIF(A10:A63,E11,C10:C63) -> 0
A12: =IF(OR(ISNUMBER(FIND("-CT-",'Libro Diario 1'!B15)),ISNUMBER(FIND("-CE-",'Libro Diario 1'!B15)), ISNUMBER(FIND("-CI-",'Libro Diario 1'!B15)), ISNUMBER(FIND("Glosa", 'Libro Diario 1'!B15))), "", 'Libro Diario 1'!B15) -> CAJA M/N | B12: =IF(OR(ISNUMBER(FIND("-CT-",'Libro Diario 1'!C15)),ISNUMBER(FIND("-CE-",'Libro Diario 1'!C15)), ISNUMBER(FIND("-CI-",'Libro Diario 1'!C15)), ISNUMBER(FIND("Glosa", 'Libro Diario 1'!C15))), "", 'Libro Diario 1'!C15) -> 7000 | C12: =IF(OR(ISNUMBER(FIND("-CT-",'Libro Diario 1'!D15)),ISNUMBER(FIND("-CE-",'Libro Diario 1'!D15)), ISNUMBER(FIND("-CI-",'Libro Diario 1'!D15)), ISNUMBER(FIND("Glosa", 'Libro Diario 1'!D15))), "", 'Libro Diario 1'!D15) -> 0 | E12: VENTAS | F12: =SUMIF(A11:A64,E12,B11:B64) -> 0 | G12: =SUMIF(A11:A64,E12,C11:C64) -> 14790
A13: =IF(OR(ISNUMBER(FIND("-CT-",'Libro Diario 1'!B16)),ISNUMBER(FIND("-CE-",'Libro Diario 1'!B16)), ISNUMBER(FIND("-CI-",'Libro Diario 1'!B16)), ISNUMBER(FIND("Glosa", 'Libro Diario 1'!B16))), "", 'Libro Diario 1'!B16) -> IMPUESTO A LAS TRANSACCIONES | B13: =IF(OR(ISNUMBER(FIND("-CT-",'Libro Diario 1'!C16)),ISNUMBER(FIND("-CE-",'Libro Diario 1'!C16)), ISNUMBER(FIND("-CI-",'Libro Diario 1'!C16)), ISNUMBER(FIND("Glosa", 'Libro Diario 1'!C16))), "", 'Libro Diario 1'!C16) -> 210 | C13: =IF(OR(ISNUMBER(FIND("-CT-",'Libro Diario 1'!D16)),ISNUMBER(FIND("-CE-",'Libro Diario 1'!D16)), ISNUMBER(FIND("-CI-",'Libro Diario 1'!D16)), ISNUMBER(FIND("Glosa", 'Libro Diario 1'!D16))), "", 'Libro Diario 1'!D16) -> 0 | E13: DEBITO FISCAL | F13: =SUMIF(A12:A65,E13,B12:B65) -> 0 | G13: =SUMIF(A12:A65,E13,C12:C65) -> 2210
... A18: =IF(OR(ISNUMBER(FIND("-CT-",'Libro Diario 1'!B21)),ISNUMBER(FIND("-CE-",'Libro Diario 1'!B21)), ISNUMBER(FIND("-CI-",'Libro Diario 1'!B21)), ISNUMBER(FIND("Glosa", 'Libro Diario 1'!B21))), "", 'Libro Diario 1'!B21) | B18: =IF(OR(ISNUMBER(FIND("-CT-",'Libro Diario 1'!C21)),ISNUMBER(FIND("-CE-",'Libro Diario 1'!C21)), ISNUMBER(FIND("-CI-",'Libro Diario 1'!C21)), ISNUMBER(FIND("Glosa", 'Libro Diario 1'!C21))), "", 'Libro Diario 1'!C21) -> 0 | C18: =IF(OR(ISNUMBER(FIND("-CT-",'Libro Diario 1'!D21)),ISNUMBER(FIND("-CE-",'Libro Diario 1'!D21)), ISNUMBER(FIND("-CI-",'Libro Diario 1'!D21)), ISNUMBER(FIND("Glosa", 'Libro Diario 1'!D21))), "", 'Libro Diario 1'!D21) -> 0 | E18: ALQUILER DE OFICINA | F18: =SUMIF(A17:A70,E18,B17:B70) -> 1044 | G18: =SUMIF(A17:A70,E18,C17:C70) -> 0
A19: =IF(OR(ISNUMBER(FIND("-CT-",'Libro Diario 1'!B22)),ISNUMBER(FIND("-CE-",'Libro Diario 1'!B22)), ISNUMBER(FIND("-CI-",'Libro Diario 1'!B22)), ISNUMBER(FIND("Glosa", 'Libro Diario 1'!B22))), "", 'Libro Diario 1'!B22) -> DEUDAS POR PAGAR | B19: =IF(OR(ISNUMBER(FIND("-CT-",'Libro Diario 1'!C22)),ISNUMBER(FIND("-CE-",'Libro Diario 1'!C22)), ISNUMBER(FIND("-CI-",'Libro Diario 1'!C22)), ISNUMBER(FIND("Glosa", 'Libro Diario 1'!C22))), "", 'Libro Diario 1'!C22) -> 4000 | C19: =IF(OR(ISNUMBER(FIND("-CT-",'Libro Diario 1'!D22)),ISNUMBER(FIND("-CE-",'Libro Diario 1'!D22)), ISNUMBER(FIND("-CI-",'Libro Diario 1'!D22)), ISNUMBER(FIND("Glosa", 'Libro Diario 1'!D22))), "", 'Libro Diario 1'!D22) -> 0
A20: =IF(OR(ISNUMBER(FIND("-CT-",'Libro Diario 1'!B23)),ISNUMBER(FIND("-CE-",'Libro Diario 1'!B23)), ISNUMBER(FIND("-CI-",'Libro Diario 1'!B23)), ISNUMBER(FIND("Glosa", 'Libro Diario 1'!B23))), "", 'Libro Diario 1'!B23) -> BANCO GANADERO M/N | B20: =IF(OR(ISNUMBER(FIND("-CT-",'Libro Diario 1'!C23)),ISNUMBER(FIND("-CE-",'Libro Diario 1'!C23)), ISNUMBER(FIND("-CI-",'Libro Diario 1'!C23)), ISNUMBER(FIND("Glosa", 'Libro Diario 1'!C23))), "", 'Libro Diario 1'!C23) -> 0 | C20: =IF(OR(ISNUMBER(FIND("-CT-",'Libro Diario 1'!D23)),ISNUMBER(FIND("-CE-",'Libro Diario 1'!D23)), ISNUMBER(FIND("-CI-",'Libro Diario 1'!D23)), ISNUMBER(FIND("Glosa", 'Libro Diario 1'!D23))), "", 'Libro Diario 1'!D23) -> 4000
A21: =IF(OR(ISNUMBER(FIND("-CT-",'Libro Diario 1'!B24)),ISNUMBER(FIND("-CE-",'Libro Diario 1'!B24)), ISNUMBER(FIND("-CI-",'Libro Diario 1'!B24)), ISNUMBER(FIND("Glosa", 'Libro Diario 1'!B24))), "", 'Libro Diario 1'!B24) | B21: =IF(OR(ISNUMBER(FIND("-CT-",'Libro Diario 1'!C24)),ISNUMBER(FIND("-CE-",'Libro Diario 1'!C24)), ISNUMBER(FIND("-CI-",'Libro Diario 1'!C24)), ISNUMBER(FIND("Glosa", 'Libro Diario 1'!C24))), "", 'Libro Diario 1'!C24) -> 0 | C21: =IF(OR(ISNUMBER(FIND("-CT-",'Libro Diario 1'!D24)),ISNUMBER(FIND("-CE-",'Libro Diario 1'!D24)), ISNUMBER(FIND("-CI-",'Libro Diario 1'!D24)), ISNUMBER(FIND("Glosa", 'Libro Diario 1'!D24))), "", 'Libro Diario 1'!D24) -> 0
A22: =IF(OR(ISNUMBER(FIND("-CT-",'Libro Diario 1'!B25)),ISNUMBER(FIND("-CE-",'Libro Diario 1'!B25)), ISNUMBER(FIND("-CI-",'Libro Diario 1'!B25)), ISNUMBER(FIND("Glosa", 'Libro Diario 1'!B25))), "", 'Libro Diario 1'!B25) | B22: =IF(OR(ISNUMBER(FIND("-CT-",'Libro Diario 1'!C25)),ISNUMBER(FIND("-CE-",'Libro Diario 1'!C25)), ISNUMBER(FIND("-CI-",'Libro Diario 1'!C25)), ISNUMBER(FIND("Glosa", 'Libro Diario 1'!C25))), "", 'Libro Diario 1'!C25) -> 0 | C22: =IF(OR(ISNUMBER(FIND("-CT-",'Libro Diario 1'!D25)),ISNUMBER(FIND("-CE-",'Libro Diario 1'!D25)), ISNUMBER(FIND("-CI-",'Libro Diario 1'!D25)), ISNUMBER(FIND("Glosa", 'Libro Diario 1'!D25))), "", 'Libro Diario 1'!D25) -> 0
A23: =IF(OR(ISNUMBER(FIND("-CT-",'Libro Diario 1'!B26)),ISNUMBER(FIND("-CE-",'Libro Diario 1'!B26)), ISNUMBER(FIND("-CI-",'Libro Diario 1'!B26)), ISNUMBER(FIND("Glosa", 'Libro Diario 1'!B26))), "", 'Libro Diario 1'!B26) -> INVENTARIO DE MERCADERIAS | B23: =IF(OR(ISNUMBER(FIND("-CT-",'Libro Diario 1'!C26)),ISNUMBER(FIND("-CE-",'Libro Diario 1'!C26)), ISNUMBER(FIND("-CI-",'Libro Diario 1'!C26)), ISNUMBER(FIND("Glosa", 'Libro Diario 1'!C26))), "", 'Libro Diario 1'!C26) -> 7830 | C23: =IF(OR(ISNUMBER(FIND("-CT-",'Libro Diario 1'!D26)),ISNUMBER(FIND("-CE-",'Libro Diario 1'!D26)), ISNUMBER(FIND("-CI-",'Libro Diario 1'!D26)), ISNUMBER(FIND("Glosa", 'Libro Diario 1'!D26))), "", 'Libro Diario 1'!D26) -> 0
A24: =IF(OR(ISNUMBER(FIND("-CT-",'Libro Diario 1'!B27)),ISNUMBER(FIND("-CE-",'Libro Diario 1'!B27)), ISNUMBER(FIND("-CI-",'Libro Diario 1'!B27)), ISNUMBER(FIND("Glosa", 'Libro Diario 1'!B27))), "", 'Libro Diario 1'!B27) -> CREDITO FISCAL | B24: =IF(OR(ISNUMBER(FIND("-CT-",'Libro Diario 1'!C27)),ISNUMBER(FIND("-CE-",'Libro Diario 1'!C27)), ISNUMBER(FIND("-CI-",'Libro Diario 1'!C27)), ISNUMBER(FIND("Glosa", 'Libro Diario 1'!C27))), "", 'Libro Diario 1'!C27) -> 1170 | C24: =IF(OR(ISNUMBER(FIND("-CT-",'Libro Diario 1'!D27)),ISNUMBER(FIND("-CE-",'Libro Diario 1'!D27)), ISNUMBER(FIND("-CI-",'Libro Diario 1'!D27)), ISNUMBER(FIND("Glosa", 'Libro Diario 1'!D27))), "", 'Libro Diario 1'!D27) -> 0
A25: =IF(OR(ISNUMBER(FIND("-CT-",'Libro Diario 1'!B28)),ISNUMBER(FIND("-CE-",'Libro Diario 1'!B28)), ISNUMBER(FIND("-CI-",'Libro Diario 1'!B28)), ISNUMBER(FIND("Glosa", 'Libro Diario 1'!B28))), "", 'Libro Diario 1'!B28) -> DEUDAS POR PAGAR | B25: =IF(OR(ISNUMBER(FIND("-CT-",'Libro Diario 1'!C28)),ISNUMBER(FIND("-CE-",'Libro Diario 1'!C28)), ISNUMBER(FIND("-CI-",'Libro Diario 1'!C28)), ISNUMBER(FIND("Glosa", 'Libro Diario 1'!C28))), "", 'Libro Diario 1'!C28) -> 0 | C25: =IF(OR(ISNUMBER(FIND("-CT-",'Libro Diario 1'!D28)),ISNUMBER(FIND("-CE-",'Libro Diario 1'!D28)), ISNUMBER(FIND("-CI-",'Libro Diario 1'!D28)), ISNUMBER(FIND("Glosa", 'Libro Diario 1'!D28))), "", 'Libro Diario 1'!D28) -> 9000
A26: =IF(OR(ISNUMBER(FIND("-CT-",'Libro Diario 1'!B29)),ISNUMBER(FIND("-CE-",'Libro Diario 1'!B29)), ISNUMBER(FIND("-CI-",'Libro Diario 1'!B29)), ISNUMBER(FIND("Glosa", 'Libro Diario 1'!B29))), "", 'Libro Diario 1'!B29) | B26: =IF(OR(ISNUMBER(FIND("-CT-",'Libro Diario 1'!C29)),ISNUMBER(FIND("-CE-",'Libro Diario 1'!C29)), ISNUMBER(FIND("-CI-",'Libro Diario 1'!C29)), ISNUMBER(FIND("Glosa", 'Libro Diario 1'!C29))), "", 'Libro Diario 1'!C29) -> 0 | C26: =IF(OR(ISNUMBER(FIND("-CT-",'Libro Diario 1'!D29)),ISNUMBER(FIND("-CE-",'Libro Diario 1'!D29)), ISNUMBER(FIND("-CI-",'Libro Diario 1'!D29)), ISNUMBER(FIND("Glosa", 'Libro Diario 1'!D29))), "", 'Libro Diario 1'!D29) -> 0
A27: =IF(OR(ISNUMBER(FIND("-CT-",'Libro Diario 1'!B30)),ISNUMBER(FIND("-CE-",'Libro Diario 1'!B30)), ISNUMBER(FIND("-CI-",'Libro Diario 1'!B30)), ISNUMBER(FIND("Glosa", 'Libro Diario 1'!B30))), "", 'Libro Diario 1'!B30) | B27: =IF(OR(ISNUMBER(FIND("-CT-",'Libro Diario 1'!C30)),ISNUMBER(FIND("-CE-",'Libro Diario 1'!C30)), ISNUMBER(FIND("-CI-",'Libro Diario 1'!C30)), ISNUMBER(FIND("Glosa", 'Libro Diario 1'!C30))), "", 'Libro Diario 1'!C30) -> 0 | C27: =IF(OR(ISNUMBER(FIND("-CT-",'Libro Diario 1'!D30)),ISNUMBER(FIND("-CE-",'Libro Diario 1'!D30)), ISNUMBER(FIND("-CI-",'Libro Diario 1'!D30)), ISNUMBER(FIND("Glosa", 'Libro Diario 1'!D30))), "", 'Libro Diario 1'!D30) -> 0
A28: =IF(OR(ISNUMBER(FIND("-CT-",'Libro Diario 1'!B31)),ISNUMBER(FIND("-CE-",'Libro Diario 1'!B31)), ISNUMBER(FIND("-CI-",'Libro Diario 1'!B31)), ISNUMBER(FIND("Glosa", 'Libro Diario 1'!B31))), "", 'Libro Diario 1'!B31) -> CAJA M/N | B28: =IF(OR(ISNUMBER(FIND("-CT-",'Libro Diario 1'!C31)),ISNUMBER(FIND("-CE-",'Libro Diario 1'!C31)), ISNUMBER(FIND("-CI-",'Libro Diario 1'!C31)), ISNUMBER(FIND("Glosa", 'Libro Diario 1'!C31))), "", 'Libro Diario 1'!C31) -> 8000 | C28: =IF(OR(ISNUMBER(FIND("-CT-",'Libro Diario 1'!D31)),ISNUMBER(FIND("-CE-",'Libro Diario 1'!D31)), ISNUMBER(FIND("-CI-",'Libro Diario 1'!D31)), ISNUMBER(FIND("Glosa", 'Libro Diario 1'!D31))), "", 'Libro Diario 1'!D31) -> 0
A29: =IF(OR(ISNUMBER(FIND("-CT-",'Libro Diario 1'!B32)),ISNUMBER(FIND("-CE-",'Libro Diario 1'!B32)), ISNUMBER(FIND("-CI-",'Libro Diario 1'!B32)), ISNUMBER(FIND("Glosa", 'Libro Diario 1'!B32))), "", 'Libro Diario 1'!B32) -> DOCUMENTOS POR COBRAR | B29: =IF(OR(ISNUMBER(FIND("-CT-",'Libro Diario 1'!C32)),ISNUMBER(FIND("-CE-",'Libro Diario 1'!C32)), ISNUMBER(FIND("-CI-",'Libro Diario 1'!C32)), ISNUMBER(FIND("Glosa", 'Libro Diario 1'!C32))), "", 'Libro Diario 1'!C32) -> 2000 | C29: =IF(OR(ISNUMBER(FIND("-CT-",'Libro Diario 1'!D32)),ISNUMBER(FIND("-CE-",'Libro Diario 1'!D32)), ISNUMBER(FIND("-CI-",'Libro Diario 1'!D32)), ISNUMBER(FIND("Glosa", 'Libro Diario 1'!D32))), "", 'Libro Diario 1'!D32) -> 0
A30: =IF(OR(ISNUMBER(FIND("-CT-",'Libro Diario 1'!B33)),ISNUMBER(FIND("-CE-",'Libro Diario 1'!B33)), ISNUMBER(FIND("-CI-",'Libro Diario 1'!B33)), ISNUMBER(FIND("Glosa", 'Libro Diario 1'!B33))), "", 'Libro Diario 1'!B33) -> IMPUESTO A LAS TRANSACCIONES | B30: =IF(OR(ISNUMBER(FIND("-CT-",'Libro Diario 1'!C33)),ISNUMBER(FIND("-CE-",'Libro Diario 1'!C33)), ISNUMBER(FIND("-CI-",'Libro Diario 1'!C33)), ISNUMBER(FIND("Glosa", 'Libro Diario 1'!C33))), "", 'Libro Diario 1'!C33) -> 300 | C30: =IF(OR(ISNUMBER(FIND("-CT-",'Libro Diario 1'!D33)),ISNUMBER(FIND("-CE-",'Libro Diario 1'!D33)), ISNUMBER(FIND("-CI-",'Libro Diario 1'!D33)), ISNUMBER(FIND("Glosa", 'Libro Diario 1'!D33))), "", 'Libro Diario 1'!D33) -> 0
... A52: =IF(OR(ISNUMBER(FIND("-CT-",'Libro Diario 1'!B55)),ISNUMBER(FIND("-CE-",'Libro Diario 1'!B55)), ISNUMBER(FIND("-CI-",'Libro Diario 1'!B55)), ISNUMBER(FIND("Glosa", 'Libro Diario 1'!B55))), "", 'Libro Diario 1'!B55) -> CAJA M/N | B52: =IF(OR(ISNUMBER(FIND("-CT-",'Libro Diario 1'!C55)),ISNUMBER(FIND("-CE-",'Libro Diario 1'!C55)), ISNUMBER(FIND("-CI-",'Libro Diario 1'!C55)), ISNUMBER(FIND("Glosa", 'Libro Diario 1'!C55))), "", 'Libro Diario 1'!C55) -> 0 | C52: =IF(OR(ISNUMBER(FIND("-CT-",'Libro Diario 1'!D55)),ISNUMBER(FIND("-CE-",'Libro Diario 1'!D55)), ISNUMBER(FIND("-CI-",'Libro Diario 1'!D55)), ISNUMBER(FIND("Glosa", 'Libro Diario 1'!D55))), "", 'Libro Diario 1'!D55) -> 1200
B53: =IF(OR(ISNUMBER(FIND("-CT-",'Libro Diario 1'!C56)),ISNUMBER(FIND("-CE-",'Libro Diario 1'!C56)), ISNUMBER(FIND("-CI-",'Libro Diario 1'!C56)), ISNUMBER(FIND("Glosa", 'Libro Diario 1'!C56))), "", 'Libro Diario 1'!C56) -> 0 | C53: =IF(OR(ISNUMBER(FIND("-CT-",'Libro Diario 1'!D56)),ISNUMBER(FIND("-CE-",'Libro Diario 1'!D56)), ISNUMBER(FIND("-CI-",'Libro Diario 1'!D56)), ISNUMBER(FIND("Glosa", 'Libro Diario 1'!D56))), "", 'Libro Diario 1'!D56) -> 0
B54: =IF(OR(ISNUMBER(FIND("-CT-",'Libro Diario 1'!#REF!)),ISNUMBER(FIND("-CE-",'Libro Diario 1'!#REF!)), ISNUMBER(FIND("-CI-",'Libro Diario 1'!#REF!)), ISNUMBER(FIND("Glosa", 'Libro Diario 1'!#REF!))), "", 'Libro Diario 1'!#REF!) -> #REF! | C54: =IF(OR(ISNUMBER(FIND("-CT-",'Libro Diario 1'!#REF!)),ISNUMBER(FIND("-CE-",'Libro Diario 1'!#REF!)), ISNUMBER(FIND("-CI-",'Libro Diario 1'!#REF!)), ISNUMBER(FIND("Glosa", 'Libro Diario 1'!#REF!))), "", 'Libro Diario 1'!#REF!) -> #REF!

Sheet Mayores
A4: ='Lista de Libros'!E2 -> BANCO GANADERO M/N | D4: ='Lista de Libros'!E3 -> INVENTARIO DE MERCADERIAS | G4: ='Lista de Libros'!E4 -> MUEBLES Y ENSERES | J4: CUENTAS POR COBRAR | M4: ='Lista de Libros'!E6 -> ALQUILERES PAGADOS POR ANTICIPADO | U4: ='Lista de Libros'!S4 -> 0
A5: {=_xlfn._xlws.FILTER('Libro Diario 1'!C4:C59,'Libro Diario 1'!B4:B59=A4)} -> #NAME? | B5: {=_xlfn._xlws.FILTER('Libro Diario 1'!D4:D56,'Libro Diario 1'!B4:B56=Mayores!A4)} -> #NAME? | D5: {=_xlfn._xlws.FILTER('Libro Diario 1'!C4:C56,'Libro Diario 1'!B4:B56=Mayores!D4)} -> #NAME? | E5: {=_xlfn._xlws.FILTER('Libro Diario 1'!D4:D56,'Libro Diario 1'!B4:B56=Mayores!D4)} -> #NAME? | G5: {=_xlfn._xlws.FILTER('Libro Diario 1'!C4:C56,'Libro Diario 1'!B4:B56=G4)} -> #NAME? | H5: {=_xlfn._xlws.FILTER('Libro Diario 1'!D4:D56,'Libro Diario 1'!B4:B56=G4)} -> #NAME? | J5: {=_xlfn._xlws.FILTER('Libro Diario 1'!C4:C56,'Libro Diario 1'!B4:B56=J4)} -> #NAME? | K5: {=_xlfn._xlws.FILTER('Libro Diario 1'!D4:D56,'Libro Diario 1'!B4:B56=J4)} -> #NAME? | M5: {=_xlfn._xlws.FILTER('Libro Diario 1'!C4:C56,'Libro Diario 1'!B4:B56=M4)} -> #NAME? | N5: {=_xlfn._xlws.FILTER('Libro Diario 1'!D4:D56,'Libro Diario 1'!B4:B56=M4)} -> #NAME?
A6: #NAME? | B6: #NAME? | D6: #NAME? | E6: #NAME? | G6: #NAME? | H6: #NAME? | J6: =SUM(J5) -> #NAME? | K6: =SUM(K5) -> #NAME? | M6: =SUM(M5) -> #NAME? | N6: =SUM(N5) -> #NAME?
A7: #NAME? | B7: #NAME? | D7: =SUM(D5:D6) -> #NAME? | E7: =SUM(E5:E6) -> #NAME? | G7: =SUM(G5:G6) -> #NAME? | H7: =SUM(H5:H6) -> #NAME?
A8: =SUM(A5:A7) -> #NAME? | B8: =SUM(B5:B7) -> #NAME?
B9: =A8-B8 -> #NAME?
A11: ='Lista de Libros'!E7 -> DOCUMENTOS POR PAGAR | D11: ='Lista de Libros'!E8 -> DEUDAS POR PAGAR | G11: ='Lista de Libros'!E9 -> CAPITAL SOCIAL | J11: ='Lista de Libros'!E10 -> CAJA M/N | M11: ='Lista de Libros'!E11 -> IMPUESTO A LAS TRANSACCIONES
A12: {=_xlfn._xlws.FILTER('Libro Diario 1'!C4:C56,'Libro Diario 1'!B4:B56=A11)} -> #NAME? | B12: {=_xlfn._xlws.FILTER('Libro Diario 1'!D4:D56,'Libro Diario 1'!B4:B56=A11)} -> #NAME? | D12: {=_xlfn._xlws.FILTER('Libro Diario 1'!C4:C56,'Libro Diario 1'!B4:B56=D11)} -> #NAME? | E12: {=_xlfn._xlws.FILTER('Libro Diario 1'!D4:D56,'Libro Diario 1'!B4:B56=D11)} -> #NAME? | G12: {=_xlfn._xlws.FILTER('Libro Diario 1'!C4:C56,'Libro Diario 1'!B4:B56=G11)} -> #NAME? | H12: {=_xlfn._xlws.FILTER('Libro Diario 1'!D4:D56,'Libro Diario 1'!B4:B56=G11)} -> #NAME? | J12: {=_xlfn._xlws.FILTER('Libro Diario 1'!C4:C56,'Libro Diario 1'!B4:B56=J11)} -> #NAME? | K12: {=_xlfn._xlws.FILTER('Libro Diario 1'!D4:D60,'Libro Diario 1'!B4:B60=J11)} -> #NAME? | M12: {=_xlfn._xlws.FILTER('Libro Diario 1'!C4:C56,'Libro Diario 1'!B4:B56=M11)} -> #NAME? | N12: {=_xlfn._xlws.FILTER('Libro Diario 1'!D4:D56,'Libro Diario 1'!B4:B56=M11)} -> #NAME?
A13: =SUM(A12) -> #NAME? | B13: =SUM(B12) -> #NAME? | D13: #NAME? | E13: #NAME? | G13: =SUM(G12) -> #NAME? | H13: =SUM(H12) -> #NAME? | J13: #NAME? | K13: #NAME? | M13: #NAME? | N13: #NAME?
D14: #NAME? | E14: #NAME? | J14: #NAME? | K14: #NAME? | M14: =SUM(M12:M13) -> #NAME? | N14: =SUM(N12:N13) -> #NAME?
D15: =SUM(D12:D14) -> #NAME? | E15: =SUM(E12:E14) -> #NAME? | J15: #NAME? | K15: #NAME?
E16: =D15-E15 -> #NAME? | J16: #NAME? | K16: #NAME?
J17: #NAME? | K17: #NAME?
J19: =SUM(_xlfn.ANCHORARRAY(J12)) -> #NAME? | K19: =SUM(_xlfn.ANCHORARRAY(K12)) -> #NAME?
K20: =J19-K19 -> #NAME?
A21: ='Lista de Libros'!E12 -> VENTAS | D21: ='Lista de Libros'!E13 -> DEBITO FISCAL | G21: ='Lista de Libros'!E14 -> IT POR PAGAR | J21: ='Lista de Libros'!E15 -> CREDITO FISCAL | M21: ='Lista de Libros'!E16 -> DOCUMENTOS POR COBRAR
A22: {=_xlfn._xlws.FILTER('Libro Diario 1'!C4:C56,'Libro Diario 1'!B4:B56=A21)} -> #NAME? | B22: {=_xlfn._xlws.FILTER('Libro Diario 1'!D4:D56,'Libro Diario 1'!B4:B56=A21)} -> #NAME? | D22: {=_xlfn._xlws.FILTER('Libro Diario 1'!C4:C60,'Libro Diario 1'!B4:B60=D21)} -> #NAME? | E22: {=_xlfn._xlws.FILTER('Libro Diario 1'!D4:D60,'Libro Diario 1'!B4:B60=D21)} -> #NAME? | G22: {=_xlfn._xlws.FILTER('Libro Diario 1'!C4:C56,'Libro Diario 1'!B4:B56=G21)} -> #NAME? | H22: {=_xlfn._xlws.FILTER('Libro Diario 1'!D4:D56,'Libro Diario 1'!B4:B56=G21)} -> #NAME? | J22: {=_xlfn._xlws.FILTER('Libro Diario 1'!C4:C60,'Libro Diario 1'!B4:B60=J21)} -> #NAME? | K22: {=_xlfn._xlws.FILTER('Libro Diario 1'!D4:D60,'Libro Diario 1'!B4:B60=J21)} -> #NAME? | M22: {=_xlfn._xlws.FILTER('Libro Diario 1'!C4:C56,'Libro Diario 1'!B4:B56=M21)} -> #NAME? | N22: {=_xlfn._xlws.FILTER('Libro Diario 1'!D4:D56,'Libro Diario 1'!B4:B56=M21)} -> #NAME?
A23: #NAME? | B23: #NAME? | D23: #NAME? | E23: #NAME? | G23: #NAME? | H23: #NAME? | J23: #NAME? | K23: #NAME? | M23: =SUM(M22) -> #NAME? | N23: =SUM(N22) -> #NAME?
A24: =SUM(A22:A23) -> #NAME? | B24: =SUM(B22:B23) -> #NAME? | D24: #NAME? | E24: #NAME? | G24: =SUM(G22:G23) -> #NAME? | H24: =SUM(H22:H23) -> #NAME? | J24: #NAME? | K24: #NAME?
D25: =SUM(_xlfn.ANCHORARRAY(D22)) -> #NAME? | E25: =SUM(_xlfn.ANCHORARRAY(E22)) -> #NAME? | J25: #NAME? | K25: #NAME?
E26: =D25-E25 -> #NAME? | J26: #NAME? | K26: #NAME?
J27: =SUM(_xlfn.ANCHORARRAY(J22)) -> #NAME? | K27: =SUM(_xlfn.ANCHORARRAY(K22)) -> #NAME?
K28: =K27-J27 -> #NAME?
A31: ='Lista de Libros'!E17 -> MANTENIMIENTO MOBILIARIO | D31: ='Lista de Libros'!E18 -> ALQUILER DE OFICINA
A32: {=_xlfn._xlws.FILTER('Libro Diario 1'!C4:C56,'Libro Diario 1'!B4:B56=A31)} -> #NAME? | B32: {=_xlfn._xlws.FILTER('Libro Diario 1'!D4:D56,'Libro Diario 1'!B4:B56=A31)} -> #NAME? | D32: {=_xlfn._xlws.FILTER('Libro Diario 1'!C4:C56,'Libro Diario 1'!B4:B56=D31)} -> #NAME? | E32: {=_xlfn._xlws.FILTER('Libro Diario 1'!D4:D56,'Libro Diario 1'!B4:B56=D31)} -> #NAME?
A33: =SUM(A32) -> #NAME? | B33: =SUM(B32) -> #NAME? | D33: =SUM(D32) -> #NAME? | E33: =SUM(E32) -> #NAME?
D65: =IF(OR(ISNUMBER(FIND("CT",'Libro Diario 1'!B56)), ISNUMBER(FIND("CI",'Libro Diario 1'!B56)), ISNUMBER(FIND("Glosa", 'Libro Diario 1'!B56))), "", 'Libro Diario 1'!B56)
D66: =IF(OR(ISNUMBER(FIND("CT",'Libro Diario 1'!#REF!)), ISNUMBER(FIND("CI",'Libro Diario 1'!#REF!)), ISNUMBER(FIND("Glosa", 'Libro Diario 1'!#REF!))), "", 'Libro Diario 1'!#REF!) -> #REF!
D67: =IF(OR(ISNUMBER(FIND("CT",'Libro Diario 1'!#REF!)), ISNUMBER(FIND("CI",'Libro Diario 1'!#REF!)), ISNUMBER(FIND("Glosa", 'Libro Diario 1'!#REF!))), "", 'Libro Diario 1'!#REF!) -> #REF!
D68: =IF(OR(ISNUMBER(FIND("CT",'Libro Diario 1'!#REF!)), ISNUMBER(FIND("CI",'Libro Diario 1'!#REF!)), ISNUMBER(FIND("Glosa", 'Libro Diario 1'!#REF!))), "", 'Libro Diario 1'!#REF!) -> #REF!
D69: =IF(OR(ISNUMBER(FIND("CT",'Libro Diario 1'!#REF!)), ISNUMBER(FIND("CI",'Libro Diario 1'!#REF!)), ISNUMBER(FIND("Glosa", 'Libro Diario 1'!#REF!))), "", 'Libro Diario 1'!#REF!) -> #REF!
D70: =IF(OR(ISNUMBER(FIND("CT",'Libro Diario 1'!B57)), ISNUMBER(FIND("CI",'Libro Diario 1'!B57)), ISNUMBER(FIND("Glosa", 'Libro Diario 1'!B57))), "", 'Libro Diario 1'!B57)
D71: =IF(OR(ISNUMBER(FIND("CT",'Libro Diario 1'!B58)), ISNUMBER(FIND("CI",'Libro Diario 1'!B58)), ISNUMBER(FIND("Glosa", 'Libro Diario 1'!B58))), "", 'Libro Diario 1'!B58) -> DEBITO FISCAL
D72: =IF(OR(ISNUMBER(FIND("CT",'Libro Diario 1'!B59)), ISNUMBER(FIND("CI",'Libro Diario 1'!B59)), ISNUMBER(FIND("Glosa", 'Libro Diario 1'!B59))), "", 'Libro Diario 1'!B59) -> CREDITO FISCAL

Sheet Blce. Apertura (2)
A1: Comercial "LOS ROBLES"
A2: BALANCE DE APERTURA
A3: Practicado al 01 de Enero de 2023
A4: (Expresado en bolivianos)
A6: ACTIVO
B7: ACTIVO CORRIENTE | D7: =SUM(D8:D11) -> 494000
B8: Banco Ganadero M/N | D8: 255000
B9: Caja M/N | D9: 100000
B10: Inventario de Mercaderia | D10: 84000
B11: Alquileres pagados por anticipado | D11: 55000
B13: ACTIVO NO CORRIENTE | D13: =D14+D15 -> 57000
B14: Muebles y enseres | D14: 12000
B15: Equipos de computación | D15: 45000
B17: TOTAL ACTIVO | D17: =D7+D13 -> 551000
H18: |
A19: PASIVO
B20: PASIVO CORRIENTE | D20: =SUM(D21:D21) -> 35000
B21: Documentos por Pagar | D21: 35000
B23: PASIVO NO CORRIENTE | D23: =D24 -> 350000
B24: PRESTAMO BANCARIO | D24: 350000
A25: PATRIMONIO
B26: Capital Social | D26: =SUM(D17-(D20+D23)) -> 166000
B28: TOTAL PASIVO Y PATRIMONIO | D28: =SUM(D20+D26+D23) -> 551000

Sheet HOJA DE TRABAJO
A1: COMERCIAL "LOS ROBLES"
A2: HOJA DE TRABAJO PARA LA PREPARACIÓN DE LOS ESTADOS FINANCIEROS
A3: DEL 01 AL 30 DE ABRIL DE 2023
A4: EXPRESADO EN BOLIVIANOS
A6: NRO | B6: CUENTAS | C6: TIPO | D6: SUMAS | F6: SALDOS | H6: ESTADO DE RESULTADOS | J6: BALANCE GENERAL
D7: DEBE | E7: HABER | F7: DEUDOR | G7: ACREEDOR | H7: EGRE/COSTO | I7: INGRESOS | J7: ACTIVOS | K7: PAS/PAT
A8: 1 | B8: BANCO GANADERO M/N | C8: A | D8: =Mayores!A8 -> #NAME? | E8: =Mayores!B8 -> #NAME? | F8: =IF(D8>E8,D8-E8,"") -> #NAME? | G8: =IF(E8>D8,E8-D8,"") -> #NAME? | H8: =IF(C8="E",F8,) -> 0 | I8: =IF(C8="I",G8,0) -> 0 | J8: =IF(C8="A",F8,0) -> #NAME? | K8: =IF(OR(C8="P",C8="PAT"),G8,0) -> 0
A9: 2 | B9: INVENTARIO DE MERCADERIAS | C9: A | D9: =Mayores!D7 -> #NAME? | F9: =IF(D9>E9,D9-E9,"") -> #NAME? | G9: =IF(E9>D9,E9-D9,"") -> #NAME? | H9: =IF(C9="E",F9,) -> 0 | I9: =IF(C9="I",G9,0) -> 0 | J9: =IF(C9="A",F9,0) -> #NAME? | K9: =IF(OR(C9="P",C9="PAT"),G9,0) -> 0
A10: 3 | B10: MUEBLES Y ENSERES | C10: A | D10: =Mayores!G7 -> #NAME? | F10: =IF(D10>E10,D10-E10,"") -> #NAME? | G10: =IF(E10>D10,E10-D10,"") -> #NAME? | H10: =IF(C10="E",F10,) -> 0 | I10: =IF(C10="I",G10,0) -> 0 | J10: =IF(C10="A",F10,0) -> #NAME? | K10: =IF(OR(C10="P",C10="PAT"),G10,0) -> 0
A11: 4 | B11: CUENTAS POR COBRAR | C11: A | D11: =Mayores!J6 -> #NAME? | F11: =IF(D11>E11,D11-E11,"") -> #NAME? | G11: =IF(E11>D11,E11-D11,"") -> #NAME? | H11: =IF(C11="E",F11,) -> 0 | I11: =IF(C11="I",G11,0) -> 0 | J11: =IF(C11="A",F11,0) -> #NAME? | K11: =IF(OR(C11="P",C11="PAT"),G11,0) -> 0
A12: 5 | B12: ALQUILERES PAGADOS POR ANTICIPADO | C12: A | D12: =Mayores!M6 -> #NAME? | F12: =IF(D12>E12,D12-E12,"") -> #NAME? | G12: =IF(E12>D12,E12-D12,"") -> #NAME? | H12: =IF(C12="E",F12,) -> 0 | I12: =IF(C12="I",G12,0) -> 0 | J12: =IF(C12="A",F12,0) -> #NAME? | K12: =IF(OR(C12="P",C12="PAT"),G12,0) -> 0
A13: 6 | B13: DOCUMENTOS POR PAGAR | C13: P | E13: =Mayores!B13 -> #NAME? | F13: =IF(D13>E13,D13-E13,"") -> #NAME? | G13: =IF(E13>D13,E13-D13,"") -> #NAME? | H13: =IF(C13="E",F13,) -> 0 | I13: =IF(C13="I",G13,0) -> 0 | J13: =IF(C13="A",F13,0) -> 0 | K13: =IF(OR(C13="P",C13="PAT"),G13,0) -> #NAME?
A14: 7 | B14: DEUDAS POR PAGAR | C14: P | D14: =Mayores!D15 -> #NAME? | E14: =Mayores!E15 -> #NAME? | F14: =IF(D14>E14,D14-E14,"") -> #NAME? | G14: =IF(E14>D14,E14-D14,"") -> #NAME? | H14: =IF(C14="E",F14,) -> 0 | I14: =IF(C14="I",G14,0) -> 0 | J14: =IF(C14="A",F14,0) -> 0 | K14: =IF(OR(C14="P",C14="PAT"),G14,0) -> #NAME?
A15: 8 | B15: CAPITAL SOCIAL | C15: PAT | E15: =Mayores!H13 -> #NAME? | F15: =IF(D15>E15,D15-E15,"") -> #NAME? | G15: =IF(E15>D15,E15-D15,"") -> #NAME? | H15: =IF(C15="E",F15,) -> 0 | I15: =IF(C15="I",G15,0) -> 0 | J15: =IF(C15="A",F15,0) -> 0 | K15: =IF(OR(C15="P",C15="PAT"),G15,0) -> #NAME?
A16: 9 | B16: CAJA M/N | C16: A | D16: =Mayores!J19 -> #NAME? | E16: =Mayores!K19 -> #NAME? | F16: =IF(D16>E16,D16-E16,"") -> #NAME? | G16: =IF(E16>D16,E16-D16,"") -> #NAME? | H16: =IF(C16="E",F16,) -> 0 | I16: =IF(C16="I",G16,0) -> 0 | J16: =IF(C16="A",F16,0) -> #NAME? | K16: =IF(OR(C16="P",C16="PAT"),G16,0) -> 0
A17: 10 | B17: IMPUESTO A LAS TRANSACCIONES | C17: E | D17: =Mayores!M14 -> #NAME? | F17: =IF(D17>E17,D17-E17,"") -> #NAME? | G17: =IF(E17>D17,E17-D17,"") -> #NAME? | H17: =IF(C17="E",F17,) -> #NAME? | I17: =IF(C17="I",G17,0) -> 0 | J17: =IF(C17="A",F17,0) -> 0 | K17: =IF(OR(C17="P",C17="PAT"),G17,0) -> 0
A18: 11 | B18: VENTAS | C18: I | E18: =Mayores!B24 -> #NAME? | F18: =IF(D18>E18,D18-E18,"") -> #NAME? | G18: =IF(E18>D18,E18-D18,"") -> #NAME? | H18: =IF(C18="E",F18,) -> 0 | I18: =IF(C18="I",G18,0) -> #NAME? | J18: =IF(C18="A",F18,0) -> 0 | K18: =IF(OR(C18="P",C18="PAT"),G18,0) -> 0
A19: 12 | B19: DEBITO FISCAL | C19: P | D19: =Mayores!D25 -> #NAME? | E19: =Mayores!E25 -> #NAME? | F19: =IF(D19>E19,D19-E19,"") -> #NAME? | G19: =IF(E19>D19,E19-D19,"") -> #NAME? | H19: =IF(C19="E",F19,) -> 0 | I19: =IF(C19="I",G19,0) -> 0 | J19: =IF(C19="A",F19,0) -> 0 | K19: =IF(OR(C19="P",C19="PAT"),G19,0) -> #NAME?
A20: 13 | B20: IT POR PAGAR | C20: P | E20: =Mayores!H24 -> #NAME? | F20: =IF(D20>E20,D20-E20,"") -> #NAME? | G20: =IF(E20>D20,E20-D20,"") -> #NAME? | H20: =IF(C20="E",F20,) -> 0 | I20: =IF(C20="I",G20,0) -> 0 | J20: =IF(C20="A",F20,0) -> 0 | K20: =IF(OR(C20="P",C20="PAT"),G20,0) -> #NAME?
A21: 14 | B21: CREDITO FISCAL | C21: A | D21: =Mayores!J27 -> #NAME? | E21: =Mayores!K27 -> #NAME? | F21: =IF(D21>E21,D21-E21,"") -> #NAME? | G21: =IF(E21>D21,E21-D21,"") -> #NAME? | H21: =IF(C21="E",F21,) -> 0 | I21: =IF(C21="I",G21,0) -> 0 | J21: =IF(C21="A",F21,0) -> #NAME? | K21: =G21 -> #NAME?
A22: 15 | B22: DOCUMENTOS POR COBRAR | C22: A | D22: =Mayores!M23 -> #NAME? | F22: =IF(D22>E22,D22-E22,"") -> #NAME? | G22: =IF(E22>D22,E22-D22,"") -> #NAME? | H22: =IF(C22="E",F22,) -> 0 | I22: =IF(C22="I",G22,0) -> 0 | J22: =IF(C22="A",F22,0) -> #NAME? | K22: =IF(OR(C22="P",C22="PAT"),G22,0) -> 0
A23: 16 | B23: MANTENIMIENTO MOBILIARIO | C23: E | D23: =Mayores!A33 -> #NAME? | F23: =IF(D23>E23,D23-E23,"") -> #NAME? | G23: =IF(E23>D23,E23-D23,"") -> #NAME? | H23: =IF(C23="E",F23,) -> #NAME? | I23: =IF(C23="I",G23,0) -> 0 | J23: =IF(C23="A",F23,0) -> 0 | K23: =IF(OR(C23="P",C23="PAT"),G23,0) -> 0
A24: 17 | B24: ALQUILER DE OFICINA | C24: E | D24: =Mayores!D33 -> #NAME? | F24: =IF(D24>E24,D24-E24,"") -> #NAME? | G24: =IF(E24>D24,E24-D24,"") -> #NAME? | H24: =IF(C24="E",F24,) -> #NAME? | I24: =IF(C24="I",G24,0) -> 0 | J24: =IF(C24="A",F24,0) -> 0 | K24: =IF(OR(C24="P",C24="PAT"),G24,0) -> 0
D25: =SUM(D8:D24) -> #NAME? | E25: =SUM(E8:E24) -> #NAME? | F25: =SUM(F8:F24) -> #NAME? | G25: =SUM(G8:G24) -> #NAME? | H25: =SUM(H8:H24) -> #NAME? | I25: =SUM(I8:I24) -> #NAME? | J25: =SUM(J8:J24) -> #NAME? | K25: =SUM(K8:K24) -> #NAME?
I26: =I25-H25 -> #NAME? | J26: =J25-K25 -> #NAME?
H27: =SUM(H25:H26) -> #NAME? | I27: =I25-I26 -> #NAME? | J27: =J25-J26 -> #NAME? | K27: =SUM(K25:K26) -> #NAME?

Sheet ER
A1: COMERCIAL"LOS ROBLES"
A3: ESTADO DE RESULTADOS
A4: Del 01 al 30 de abril de 2023
A5: (Expresado en bolivianos)
A7: VENTAS NETAS | D7: =SUM(C8:C10) -> #NAME?
B8: Ventas | C8: ='HOJA DE TRABAJO'!E18 -> #NAME?
A9: (-) | B9: Devoluciones s/ventas | C9: 0
A10: (-) | B10: Descuento s/ventas | C10: 0
A12: COSTO DE VENTAS | D12: 0
B13: Costo de ventas | C13: 0
B15: UTILIDAD BRUTA EN VENTAS | D15: =+D7-D12 -> #NAME?
A17: GASTOS OPERATIVOS | D17: =SUM(C18:C20) -> #NAME?
B18: =+'[1]HOJA DE TRABAJO'!B16 -> I.T. | C18: ='HOJA DE TRABAJO'!D17 -> #NAME?
B19: ='HOJA DE TRABAJO'!B23 -> MANTENIMIENTO MOBILIARIO | C19: 70
B20: ='HOJA DE TRABAJO'!B24 -> ALQUILER DE OFICINA | C20: ='HOJA DE TRABAJO'!D24 -> #NAME?
B22: GANANCIA OPERATIVA | D22: =D15-D17 -> #NAME?
B25: GANANCIA DEL EJERCICIO | D25: =D22 -> #NAME?
B30: GERENTE GENERAL | C30: CONTADOR

Sheet BG
A1: COMERCIAL "LOS ROBLES"
A3: BALANCE GENERAL
A4: Al 30 de abril de 2023
A5: (Expresado en bolivianos)
A7: ACTIVO
B8: ACTIVO CORRIENTE | D8: =SUM(C9:C14) -> #NAME?
B9: CAJA MN | C9: ='HOJA DE TRABAJO'!F16 -> #NAME?
B10: BANCO GANADERO M/N | C10: ='HOJA DE TRABAJO'!F8 -> #NAME?
B11: INVENTARIO DE MERCADERIAS | C11: ='HOJA DE TRABAJO'!F9 -> #NAME?
B12: CUENTAS POR COBRAR | C12: ='HOJA DE TRABAJO'!J11 -> #NAME?
B13: DOCUMENTOS POR COBRAR | C13: ='HOJA DE TRABAJO'!F22 -> #NAME?
B14: ALQUILERES PAGADOS POR ANTICIPADO | C14: ='HOJA DE TRABAJO'!F12 -> #NAME?
B16: ACTIVO NO CORRIENTE | D16: =SUM(C17:C17) -> #NAME?
B17: MUEBLES Y ENSERES | C17: ='HOJA DE TRABAJO'!F10 -> #NAME?
B19: TOTAL ACTIVO | D19: =+D8+D16 -> #NAME?
A21: PASIVO
B22: PASIVO CORRIENTE | D22: =SUM(C23:C26) -> #NAME?
B23: I.T. POR PAGAR | C23: ='HOJA DE TRABAJO'!G20 -> #NAME?
B24: DOCUMENTOS POR PAGAR | C24: ='HOJA DE TRABAJO'!G13 -> #NAME? | H24: I.T. POR PAGAR
B25: DEUDAS POR PAGAR | C25: ='HOJA DE TRABAJO'!G14 -> #NAME? | H25: APORTE LABORAL GESTORA POR PAGAR
B26: DEBITO FISCAL | C26: ='HOJA DE TRABAJO'!K19 -> #NAME? | H26: PRIMAS POR PAGAR
A28: PATRIMONIO
B29: CAPITAL | D29: =+C31+C30 -> #NAME?
B30: =+'[1]HOJA DE TRABAJO'!B12 -> CAPITAL SOCIAL | C30: ='HOJA DE TRABAJO'!G15 -> #NAME?
B31: GANANCIA DEL EJERCICIO | C31: =ER!D25 -> #NAME?
B34: TOTAL PASIVO Y PATRIMONIO | D34: =D22+D29 -> #NAME?
B39: GERENTE GENERAL | D39: CONTADOR
