Workbook

Sheet datos
A1: Marca temporal | B1: ¿Cual es tu edad? | C1: ¿Cual es tu sexo? | D1: ¿En que horario estas pasando clase en la UPDS? | E1: ¿Actualmente trabajas mientras estudias? | F1: ¿Que carrera estas estudiando ? | G1: ¿Cual es tu horario laboral? | H1: ¿ Has tenido dificultades para encontrar clases que se ajusten a tu horario laboral? | I1: ¿Crees que la falta de flexibilidad en los horarios de clases afectan tu desempeño académico? | J1: ¿Has dejado de estudiar debido al cruce de horarios entre el trabajo y la universidad? | K1: ¿Cuánto dinero inviertes en transporte y alimentación al mes asistiendo en la modalidad presencial?
A2: 45440.558 | B2: 21 | C2: Hombre | D2: Noche | E2: no | F2: otros | G2: medio dia 4 horas | H2: No | I2: Si | J2: 1 vez en el mes | K2: 103
A3: 45440.522 | B3: 20 | C3: Hombre | D3: Mañana | E3: no | F3: Ing. Industrial | G3: Horario continua 3 - 9 horas | H3: No | I3: No | J3: 1 vez en el mes | K3: 120
A4: 45440.578 | B4: 33 | C4: Hombre | D4: Noche | E4: si | F4: Ing. Industrial | G4: Horario continua 8 - 4 horas | H4: No | I4: Si | J4: 1 vez en el mes | K4: 150
A5: 45440.46 | B5: 26 | C5: Hombre | D5: Mañana | E5: si | F5: Ing. Industrial | G5: Horario continua 3 - 9 horas | H5: No | I5: Si | J5: 1 vez en el mes | K5: 210
A6: 45440.532 | B6: 19 | C6: Hombre | D6: Mañana | E6: si | F6: Ing. de Sistemas | G6: medio dia 4 horas | H6: No | I6: No | J6: 1 vez en el mes | K6: 220
A7: 45440.815 | B7: 21 | C7: Hombre | D7: Noche | E7: si | F7: Ing. Redes Y telecomunicaciones | G7: Horario continua 8 - 4 horas | H7: No | I7: Si | J7: 1 vez en el mes | K7: 290
A8: 45440.453 | B8: 19 | C8: Hombre | D8: Mañana | E8: no | F8: Ing. de Sistemas | G8: medio dia 4 horas | H8: No | I8: Si | J8: 1 vez en el mes | K8: 300
A9: 45440.63 | B9: 20 | C9: Hombre | D9: Noche | E9: si | F9: Ing. Industrial | G9: medio dia 4 horas | H9: No | I9: No | J9: 1 vez en el mes | K9: 370
A10: 45440.66 | B10: 30 | C10: Hombre | D10: Mañana | E10: si | F10: Ing. de Sistemas | G10: Horario continua 3 - 9 horas | H10: No | I10: Si | J10: 1 vez en el mes | K10: 500
A11: 45440.772 | B11: 20 | C11: Hombre | D11: Mañana | E11: si | F11: Ing. de Sistemas | G11: medio dia 4 horas | H11: Si | I11: Si | J11: 1 vez en el mes | K11: 100
A12: 45441.411 | B12: 19 | C12: Hombre | D12: Mañana | E12: si | F12: Ing. de Sistemas | G12: medio dia 4 horas | H12: Si | I12: No | J12: 1 vez en el mes | K12: 120
A13: 45440.891 | B13: 26 | C13: Hombre | D13: Mañana | E13: si | F13: Ing. de Sistemas | G13: Horario de oficina 8 - 12 a 2 - 6 horas | H13: Si | I13: Si | J13: 1 vez en el mes | K13: 200
... A51: 45440.532 | B51: 19 | C51: otros | D51: Mañana | E51: si | F51: otros | G51: medio dia 4 horas | H51: No | I51: Si | J51: 1 vez en el mes | K51: 155

Sheet TABLA-MTC
B2: =+datos!B1 -> ¿Cual es tu edad?
B4: 24 | C4: 22 | D4: 21 | E4: 20 | F4: 31 | H4: calculos previos
B5: 24 | C5: 29 | D5: 26 | E5: 24 | F5: 23 | H5: n°datos | I5: =COUNT(B4:F13) -> 50
B6: 20 | C6: 19 | D6: 19 | E6: 24 | F6: 20 | H6: limite inferior | I6: =MIN(B4:F13) -> 19 | Q6: 24
B7: 24 | C7: 20 | D7: 33 | E7: 20 | F7: 24 | H7: limite superior | I7: =MAX(B4:F13) -> 33 | M7: =STDEV(Q6:Q55) -> 3.8138309 | Q7: 24
B8: 25 | C8: 20 | D8: 20 | E8: 24 | F8: 22 | H8: rango | I8: =I7-I6 -> 14 | Q8: 20
B9: 27 | C9: 23 | D9: 27 | E9: 25 | F9: 19 | H9: N°clases | I9: =ROUNDUP(1+3.322*LOG(I5),0) -> 7 | Q9: 24
B10: 30 | C10: 28 | D10: 19 | E10: 27 | F10: 21 | H10: Amplitud | I10: =I8/I9 -> 2 | Q10: 25
B11: 20 | C11: 19 | D11: 19 | E11: 30 | F11: 25 | Q11: 27
B12: 20 | C12: 19 | D12: 22 | E12: 20 | F12: 26 | H12: medidas de tendencia central | Q12: 30
B13: 31 | C13: 21 | D13: 23 | E13: 20 | F13: 19 | H13: media | I13: =P29/I5 -> 23 | Q13: 20
H14: mediana | I14: =C23+(((I5/2)-J22)/G23)*I10 -> 22 | Q14: 20
H15: moda | I15: =C22+((G22-0)/((G22-0)+(G22-G23)))*I10 -> 20.157895 | Q15: 31
Q16: 22
Q17: 29
B18: 1 | D18: 2 | E18: 4 | F18: 5 | G18: 6 | H18: 7 | I18: 8 | J18: 9 | K18: 10 | L18: 11 | M18: 12 | N18: 13 | O18: 14 | Q18: 19
J19: Frec. Abs. Acumulada MENOR QUE | M19: Frec. Acumulada MAYOR QUE | Q19: 20
B20: N intervalo | C20: limites | E20: reconteo de datos | F20: marca de clase | G20: frec. Absoluta | H20: frec. Relativa | I20: frec.porcentual | J20: frec. Absoluta | K20: frec. Relativa | L20: frec.porcentual | M20: frec. Absoluta | N20: frec. Relativa | O20: frec.porcentual | Q20: 20
B21: K | C21: Li | D21: Ls | E21: conteo | F21: yi | G21: ni | H21: hi | I21: pi | J21: Ni | K21: Hi | L21: Pi | M21: Ni* | N21: Hi* | O21: Pi* | P21: yi*ni | Q21: 23
B22: 1 | C22: =I6 -> 19 | D22: 21 | E22: IIIIIIIIIIIIIIIIIIIIIII | F22: =(C22+D22)/2 -> 20 | G22: 22 | H22: =G22/G29 -> 0.44 | I22: =H22 -> 0.44 | J22: =G22 -> 22 | K22: =H22 -> 0.44 | L22: =I22 -> 0.44 | M22: =M23+G22 -> 50 | N22: =N23+H22 -> 1 | O22: =O23+I22 -> 1 | P22: =F22*G22 -> 440 | Q22: 28
B23: 2 | C23: =D22 -> 21 | D23: =D22+$I$10 -> 23 | E23: IIIIII | F23: =(C23+D23)/2 -> 22 | G23: 6 | H23: =G23/G29 -> 0.12 | I23: =H23 -> 0.12 | J23: =J22+G23 -> 28 | K23: =K22+H23 -> 0.56 | L23: =L22+I23 -> 0.56 | M23: =M24+G23 -> 28 | N23: =N24+H23 -> 0.56 | O23: =O24+I23 -> 0.56 | P23: =F23*G23 -> 132 | Q23: 19
B24: 3 | C24: =D23 -> 23 | D24: =D23+$I$10 -> 25 | E24: IIIIIIIIIII | F24: =(C24+D24)/2 -> 24 | G24: 10 | H24: =G24/G29 -> 0.2 | I24: =H24 -> 0.2 | J24: =J23+G24 -> 38 | K24: =K23+H24 -> 0.76 | L24: =L23+I24 -> 0.76 | M24: =M25+G24 -> 22 | N24: =N25+H24 -> 0.44 | O24: =O25+I24 -> 0.44 | P24: =F24*G24 -> 240 | Q24: 19
B25: 4 | C25: =D24 -> 25 | D25: =D24+$I$10 -> 27 | E25: IIIII | F25: =(C25+D25)/2 -> 26 | G25: 5 | H25: =G25/G29 -> 0.1 | I25: =H25 -> 0.1 | J25: =J24+G25 -> 43 | K25: =K24+H25 -> 0.86 | L25: =L24+I25 -> 0.86 | M25: =M26+G25 -> 12 | N25: =N26+H25 -> 0.24 | O25: =O26+I25 -> 0.24 | P25: =F25*G25 -> 130 | Q25: 21
B26: 5 | C26: =D25 -> 27 | D26: =D25+$I$10 -> 29 | E26: II | F26: =(C26+D26)/2 -> 28 | G26: 2 | H26: =G26/G29 -> 0.04 | I26: =H26 -> 0.04 | J26: =J25+G26 -> 45 | K26: =K25+H26 -> 0.9 | L26: =L25+I26 -> 0.9 | M26: =M27+G26 -> 7 | N26: =N27+H26 -> 0.14 | O26: =O27+I26 -> 0.14 | P26: =F26*G26 -> 56 | Q26: 21
B27: 6 | C27: =D26 -> 29 | D27: =D26+$I$10 -> 31 | E27: IIII | F27: =(C27+D27)/2 -> 30 | G27: 4 | H27: =G27/G29 -> 0.08 | I27: =H27 -> 0.08 | J27: =J26+G27 -> 49 | K27: =K26+H27 -> 0.98 | L27: =L26+I27 -> 0.98 | M27: =M28+G27 -> 5 | N27: =N28+H27 -> 0.1 | O27: =O28+I27 -> 0.1 | P27: =F27*G27 -> 120 | Q27: 26
B28: 7 | C28: =D27 -> 31 | D28: =D27+$I$10 -> 33 | E28: I | F28: =(C28+D28)/2 -> 32 | G28: 1 | H28: =G28/G29 -> 0.02 | I28: =H28 -> 0.02 | J28: =J27+G28 -> 50 | K28: =K27+H28 -> 1 | L28: =L27+I28 -> 1 | M28: =G28 -> 1 | N28: =H28 -> 0.02 | O28: =I28 -> 0.02 | P28: =F28*G28 -> 32 | Q28: 19
G29: =SUM(G22:G28) -> 50 | H29: =SUM(H22:H28) -> 1 | I29: =SUM(I22:I28) -> 1 | P29: =SUM(P22:P28) -> 1150 | Q29: 33
Q30: 20
Q31: 27
Q32: 19
Q33: 19
Q34: 22
Q35: 23
Q36: 20
Q37: 24
Q38: 24
Q39: 20
Q40: 24
Q41: 25
... Q51: 19
...

Sheet MED-DISPERSION
A1: =+D3 -> ¿Cual es tu edad?
A2: MEDIDAS DE DISPERSION
A3: Media | B3: 23.16 | D3: =+datos!B1 -> ¿Cual es tu edad?
A4: Error típico | B4: 0.53935714
A5: Mediana | B5: 22.5
A6: Moda | B6: 20 | D6: N intervalo | E6: limites | F6: marca de clase | G6: frec. Absoluta
A7: Desviación estándar | B7: 3.8138309 | F7: yi | G7: ni | H7: yi * ni | I7: (x-x)^2 | J7: (x-x)^2*ni
A8: Varianza de la muestra | B8: 14.545306 | D8: 1 | E8: 19 - 21 | F8: 20 | G8: 22 | H8: =G8*F8 -> 440 | I8: =POWER((F8-B3),2) -> 9.9856 | J8: =I8*G8 -> 219.6832
A9: Curtosis | B9: -0.20479433 | D9: 2 | E9: 21 - 23 | F9: 22 | G9: 6 | H9: =G9*F9 -> 132 | I9: =POWER((F9-B3),2) -> 1.3456 | J9: =I9*G9 -> 8.0736
A10: Coeficiente de asimetría | B10: 0.82380447 | D10: 3 | E10: 23 - 25 | F10: 24 | G10: 10 | H10: =G10*F10 -> 240 | I10: =POWER((F10-B3),2) -> 0.7056 | J10: =I10*G10 -> 7.056
A11: Rango | B11: 14 | D11: 4 | E11: 25 - 27 | F11: 26 | G11: 5 | H11: =G11*F11 -> 130 | I11: =POWER((F11-B3),2) -> 8.0656 | J11: =I11*G11 -> 40.328
A12: Mínimo | B12: 19 | D12: 5 | E12: 27 - 29 | F12: 28 | G12: 2 | H12: =G12*F12 -> 56 | I12: =POWER((F12-B3),2) -> 23.4256 | J12: =I12*G12 -> 46.8512
A13: Máximo | B13: 33 | D13: 6 | E13: 29 - 31 | F13: 30 | G13: 4 | H13: =G13*F13 -> 120 | I13: =POWER((F13-B3),2) -> 46.7856 | J13: =I13*G13 -> 187.1424
A14: Suma | B14: 1158 | D14: 7 | E14: 31 - 33 | F14: 33 | G14: 1 | H14: =G14*F14 -> 33 | I14: =POWER((F14-B3),2) -> 96.8256 | J14: =I14*G14 -> 96.8256
A15: Cuenta | B15: 50 | G15: 50 | H15: 1158 | I15: =SUM(I8:I14) -> 187.1392 | J15: =SUM(J8:J14) -> 605.96
C16: s
A23: ¿Cuánto dinero inviertes en transporte y alimentación al mes asistiendo en la modalidad presencial, considerando arriba de 100bs ?
A24: MEDIDAS DE DISPERSION
A26: Media | B26: 270.66 | D26: N intervalo | E26: limites | F26: marca de clase | G26: frec. Absoluta
A27: Error típico | B27: 18.901627 | F27: yi | G27: ni | H27: yi * ni | I27: (x-x)^2 | J27: (x-x)^2*ni
A28: Mediana | B28: 250 | D28: 1 | E28: 100 - 171 | F28: =(100+171)/2 -> 135.5 | G28: 15 | H28: =G28*F28 -> 2032.5 | I28: =POWER((F28-B23),2) -> 18360.25 | J28: =I28*G28 -> 275403.75
A29: Moda | B29: 150 | D29: 2 | E29: 171 - 243 | F29: =(171+243)/2 -> 207 | G29: 9 | H29: =G29*F29 -> 1863 | I29: =POWER((F29-B23),2) -> 42849 | J29: =I29*G29 -> 385641
A30: Desviación estándar | B30: 133.65469 | D30: 3 | E30: 243 - 314 | F30: =(243+314)/2 -> 278.5 | G30: 10 | H30: =G30*F30 -> 2785 | I30: =POWER((F30-B23),2) -> 77562.25 | J30: =I30*G30 -> 775622.5
A31: Varianza de la muestra | B31: 17863.576 | D31: 4 | E31: 314 - 386 | F31: =(314+386)/2 -> 350 | G31: 5 | H31: =G31*F31 -> 1750 | I31: =POWER((F31-B23),2) -> 122500 | J31: =I31*G31 -> 612500
A32: Curtosis | B32: -0.5387839 | D32: 5 | E32: 386 - 457 | F32: =(386+457)/2 -> 421.5 | G32: 4 | H32: =G32*F32 -> 1686 | I32: =POWER((F32-B23),2) -> 177662.25 | J32: =I32*G32 -> 710649
A33: Coeficiente de asimetría | B33: 0.6315577 | D33: 6 | E33: 457 - 529 | F33: =(457+529)/2 -> 493 | G33: 6 | H33: =G33*F33 -> 2958 | I33: =POWER((F33-B23),2) -> 243049 | J33: =I33*G33 -> 1458294
A34: Rango | B34: 500 | D34: 7 | E34: 529 - 600 | F34: =(529+600)/2 -> 564.5 | G34: 1 | H34: =G34*F34 -> 564.5 | I34: =POWER((F34-B23),2) -> 318660.25 | J34: =I34*G34 -> 318660.25
A35: Mínimo | B35: 100 | G35: 50 | H35: =SUM(H28:H34) -> 13639 | I35: =SUM(I28:I34) -> 1000643 | J35: =SUM(J28:J34) -> 4536770.5
A36: Máximo | B36: 600
A37: Suma | B37: 13533
A38: Cuenta | B38: 50

Sheet Output
E11: 3
A25: Normal distribution
C26: P(lower) | D26: P(upper) | E26: z | F26: X | G26: mean | H26: std.dev
C27: 0.15865525 | D27: 0.84134475 | E27: -1 | F27: 19 | G27: 23 | H27: 4
C28: 0.84134475 | D28: 0.15865525 | E28: 1 | F28: 27 | G28: 23 | H28: 4
E43: 3
A57: Normal distribution
C58: P(lower) | D58: P(upper) | E58: z | F58: X | G58: mean | H58: std.dev
C59: 0.30853754 | D59: 0.69146246 | E59: -0.5 | F59: 21 | G59: 23 | H59: 4
C60: 0.84134475 | D60: 0.15865525 | E60: 1 | F60: 27 | G60: 23 | H60: 4
E75: 3
A89: Normal distribution
C90: P(lower) | D90: P(upper) | E90: z | F90: X | G90: mean | H90: std.dev
C91: 0.40129367 | D91: 0.59870633 | E91: -0.25 | F91: 22 | G91: 23 | H91: 4
C92: 0.69146246 | D92: 0.30853754 | E92: 0.5 | F92: 25 | G92: 23 | H92: 4
E107: 2
A121: Normal distribution
C122: P(lower) | D122: P(upper) | E122: z | F122: X | G122: mean | H122: std.dev
C123: 0.72016554 | D123: 0.27983446 | E123: 0.58333333 | F123: 350 | G123: 273 | H123: 132

Sheet normal distribucion
B3: En una encuesta se a determinado las edades de 50 estudiantes normalmente distribuido con una media de 23 años y una desviación típica de 4 ¿ cuantos estudiantes tienen las edades
B4: a) mayor a 29 años
B7: datos | F7: =_xlfn.NORM.DIST(29,23,4,TRUE) -> 0.9331928 | G7: =1-F7 -> 0.066807201 | H7: =G7*50 -> 3.3403601
B9: m | C9: =23 -> 23
B10: s | C10: 4
B11: P | C11: (X > 29)
B24: b) Menor o igual a 21 años
B26: datos | F26: =_xlfn.NORM.DIST(21,23,4,TRUE) -> 0.30853754 | G26: =1-F26 -> 0.69146246 | H26: =G26*50 -> 34.573123
B28: m | C28: =23 -> 23
B29: s | C29: 4
B30: P | C30: (X ≤ 21)
B39: c) entre 19 y 27 años
B41: datos | F41: =_xlfn.NORM.DIST(22,23,4,TRUE) -> 0.40129367 | G41: =1-F41 -> 0.59870633 | H41: =G41*-50 -> -29.935316
B43: m | C43: =23 -> 23
B44: s | C44: 4 | F44: =_xlfn.NORM.DIST(25,23,4,TRUE) -> 0.69146246 | G44: =1-F44 -> 0.30853754 | H44: =G44*50 -> 15.426877
B45: P | C45: (22 ≤ X ≤ 25)
F46: =F41-F44 -> -0.29016879 | G46: =G41-G44 -> 0.29016879 | H46: =G46*50 -> 14.508439

Sheet Hoja2
B2: Los gastos de 50 alumnos de la UPDS se distribuyen normalmente con una media de 273bs con una desviacion estandar de 132bs hallar
B4: a)cual es la probabilidad de que los gastos de un alumno elegido al azar sea mayor o igual a 350 bs
B7: datos | F7: =_xlfn.NORM.DIST(350,273,132,TRUE) -> 0.72016554 | G7: =1-F7 -> 0.27983446 | H7: =G7 -> 0.27983446 | I7: proporcion
H8: =G7*50 -> 13.991723 | I8: alumnos
B9: m | C9: 273
B10: s | C10: 132
B11: P | C11: ( X > 350)
B18: b)
