Workbook

Sheet BALANCE DE APERTURA
C1: Empresa: LOS ANGELES S.A.
C3: Balance de Apertura
C4: Prácticado al: 1 de Febrero del 2023
C5: (Expresado en Bolivianos)
B7: ACTIVO
C8: ACTIVO CORRIENTE | F8: =SUM(E10:E12) -> 300000
C10: Caja M/N | E10: 100000
C11: Banco Mercantil Scz M/N | E11: 120000
C12: Inventario de Mercadería | E12: 80000
C14: ACTIVO NO CORRIENTE | F14: =SUM(E15) -> 95000
C15: Vehículos | E15: 95000
C16: TOTAL ACTIVO | E16: =SUM(F8+F14) -> 395000
B18: PASIVO
C19: PASIVO CORRIENTE | F19: =SUM(E20) -> 0
E20: 0
C22: PASIVO NO CORRIENTE | F22: =SUM(E23) -> 75000
C23: Cuentas por pagar | E23: 75000
C24: TOTAL PASIVO | E24: =SUM(F19+F22) -> 75000
C26: PATRIMONIO | G26: =F27 -> 320000
C27: Capital Social | F27: =SUM(E16-E24) -> 320000
C29: TOTAL PASIVO Y PATRIMONIO | G29: =SUM(E24+G26) -> 395000
C34: CONTADOR | F34: GERENTE

Sheet LIBRO DIARIO
A1: Empresa: LOS ANGELES S.A.
A2: LIBRO DIARIO (COMPROBANTES)
A3: DEL 01 AL 28 FEBRERO DE 2023
A4: (EXPRESADO EN BOLIVIANOS)
A9: FECHA | B9: DETALLE | C9: DEBE | D9: HABER
A10: 44958 | B10: ------------ CT-01 ----------
B11: CAJA M/N | C11: 100000
B12: BANCO Mercantil Scz M/N | C12: 120000
B13: INVENTARIO DE MERCADERÍA | C13: 80000
B14: VEHÍCULOS | C14: 95000
B15: CUENTAS POR PAGAR | D15: 75000
B16: CAPITAL SOCIAL | D16: 320000
B17: Glosa: Por inicio de actividad
A18: 44959 | B18: ------------ CE-01 ----------
B19: GASTOS LEGALES | C19: =D21-C20 -> 6960
B20: CREDITO FISCAL | C20: =D21*13% -> 1040
B21: CAJA M/N | D21: 8000
B22: Glosa: Por pago al abogado según F-545
A23: 44960 | B23: ------------ CE-02 ----------
B24: INVENTARIO DE MERCADERÍA | C24: =D26-C25 -> 4872
B25: CREDITO FISCAL | C25: =D26*13% -> 728
B26: BANCO Mercantil Scz M/N | D26: 5600
B27: Glosa: por compra de mercaderia según F-254
A28: 44962 | B28: ------------ CE-03 ----------
B29: SEGURO PAGADO POR ADELANTADO | C29: =D31*87% -> 2088
B30: CREDITO FISCAL | C30: =D31-C29 -> 312
B31: BANCO Mercantil Scz M/N | D31: 2400
B32: Glosa: por pago de seguro a BISA SEGUROS
B33: por 1 año según F-2541
A34: 44965 | B34: ------------ CI-01 ----------
B35: BANCO Mercantil Scz M/N | C35: 3800
B36: I.T. | C36: =C35*3% -> 114
B37: VENTAS | D37: =C35*87% -> 3306
B38: DEBITO FISCAL | D38: =C35-D37 -> 494
B39: I.T. POR PAGAR | D39: =(D37+D38)*3% -> 114
B40: Glosa: Por Venta de mercadería según F-0001
A41: 44967 | B41: ------------ CE-04 ----------
B42: MANTENIMIENTO MUEBLES Y ENSERES | C42: =D44*87% -> 1044
B43: CREDITO FISCAL | C43: =D44-C42 -> 156
B44: CAJA M/N | D44: 1200
...

Sheet MAYORES
F4: Empresa: LOS ANGELES S.A.
F5: LIBRO MAYORES
F6: DEL 01 AL 28 DE FEBRERO DE 2023
F7: (EXPRESADO EN BOLIVIANOS)
B10: BANCO Mercantil Scz M/N | E10: CAJA M/N | H10: CUENTAS POR PAGAR | K10: CREDITO FISCAL | N10: ASEO Y LIMPIEZA
B11: 120000 | E11: 100000 | I11: 75000 | K11: 1040 | N11: 217.5
C12: 5600 | F12: 8000 | I12: 7200 | K12: 728
C13: 2400 | F13: 1200 | H13: 0 | I13: =SUM(I11:I12) -> 82200 | K13: 312
B14: 3800 | F14: 250 | I14: =I13-H13 -> 82200 | K14: 156
C15: 550 | E15: =SUM(E11:E14) -> 100000 | F15: =SUM(F12:F14) -> 9450 | K15: 936
B16: =SUM(B11:B15) -> 123800 | C16: =SUM(C12:C15) -> 8550 | E16: =E15-F15 -> 90550 | K16: 32.5
B17: =B16-C16 -> 115250 | K17: 71.5
K18: =SUM(K11:K17) -> 3276 | L18: 0
K19: =K18-L18 -> 3276
B23: DEBITO FISCAL | E23: ENERGIA ELECTRICA | H23: GASTOS LEGALES | K23: I.T | N23: I.T. POR PAGAR
C24: 494 | E24: 478.5 | H24: 6960 | K24: 114 | O24: 114
B29: INVENTARIO DE MERCADERIA | E29: MENTENIIENTO DE MUEBLES Y ENSERES | H29: SEGURO PAGADO POR ADELANTADO | K29: VEHÍCULOS | N29: VENTAS
B30: 80000 | E30: 1044 | H30: 2088 | K30: 95000 | O30: 3306
B31: 4872
B32: 6264
B33: =SUM(B30:B32) -> 91136 | C33: 0
B34: =B33-C33 -> 91136
B37: CAPITAL SOCIAL
C38: 320000

Sheet BAL. SUMAS Y SALDOS - HOJA DE T
A1: Empresa: LOS ROBLES LTDA.
A2: BALANCE DE COMPROBACION DE SUMAS Y SALDOS
A3: DEL 01 AL 30 DE ABRIL DE 2023
A4: (EXPRESADO EN BOLIVIANOS)
A6: NRO | B6: CUENTAS | C6: TIPO | D6: SUMAS | F6: SALDOS | H6: ESTADO DE RESULTADO | J6: BALANCE GENERAL
D7: DEBE | E7: HABER | F7: DEUDOR | G7: ACREEDOR | H7: EGRESO/COSTO | I7: INGRESOS | J7: ACTIVOS | K7: PAS/PAT
A8: 1 | B8: =+MAYORES!B10 -> BANCO Mercantil Scz M/N | C8: A | D8: =+MAYORES!B16 -> 123800 | E8: =+MAYORES!C16 -> 8550 | F8: =IF(D8>E8,D8-E8,"") -> 115250 | G8: =IF(E8>D8,E8-D8,"") | J8: =F8 -> 115250
A9: 2 | B9: =MAYORES!E10 -> CAJA M/N | C9: A | D9: =+MAYORES!E15 -> 100000 | E9: =+MAYORES!F15 -> 9450 | F9: =IF(D9>E9,D9-E9,"") -> 90550 | G9: =IF(E9>D9,E9-D9,"") | J9: =F9 -> 90550
A10: 3 | B10: =MAYORES!H10 -> CUENTAS POR PAGAR | C10: P | E10: =+MAYORES!I13 -> 82200 | F10: =IF(D10>E10,D10-E10,"") | G10: =IF(E10>D10,E10-D10,"") -> 82200 | H10: =F10 | K10: =G10 -> 82200
A11: 4 | B11: =MAYORES!K10 -> CREDITO FISCAL | C11: A | D11: =+MAYORES!K18 -> 3276 | F11: =IF(D11>E11,D11-E11,"") -> 3276 | G11: =IF(E11>D11,E11-D11,"") | J11: =F11 -> 3276
A12: 5 | B12: =MAYORES!N10 -> ASEO Y LIMPIEZA | C12: E | D12: =+MAYORES!N11 -> 217.5 | F12: =IF(D12>E12,D12-E12,"") -> 217.5 | G12: =IF(E12>D12,E12-D12,"") | H12: =F12 -> 217.5 | K12: =G12
A13: 6 | B13: =+MAYORES!B23 -> DEBITO FISCAL | C13: P | E13: =+MAYORES!C24 -> 494 | F13: =IF(D13>E13,D13-E13,"") | G13: =IF(E13>D13,E13-D13,"") -> 494 | H13: =F13 | K13: =G13 -> 494
A14: 7 | B14: =+MAYORES!E23 -> ENERGIA ELECTRICA | C14: E | D14: =+MAYORES!E24 -> 478.5 | F14: =IF(D14>E14,D14-E14,"") -> 478.5 | G14: =IF(E14>D14,E14-D14,"") | H14: =F14 -> 478.5
A15: 8 | B15: =+MAYORES!H23 -> GASTOS LEGALES | C15: E | D15: =+MAYORES!H24 -> 6960 | F15: =IF(D15>E15,D15-E15,"") -> 6960 | G15: =IF(E15>D15,E15-D15,"") | H15: =F15 -> 6960
A16: 9 | B16: =+MAYORES!K23 -> I.T | C16: E | D16: =+MAYORES!K24 -> 114 | F16: =IF(D16>E16,D16-E16,"") -> 114 | G16: =IF(E16>D16,E16-D16,"") | H16: =F16 -> 114 | K16: =G16
A17: 10 | B17: =+MAYORES!N23 -> I.T. POR PAGAR | C17: P | E17: =+MAYORES!O24 -> 114 | F17: =IF(D17>E17,D17-E17,"") | G17: =IF(E17>D17,E17-D17,"") -> 114 | J17: =F17 | K17: =G17 -> 114
A18: 11 | B18: =+MAYORES!B29 -> INVENTARIO DE MERCADERIA | C18: A | D18: =+MAYORES!B33 -> 91136 | F18: =IF(D18>E18,D18-E18,"") -> 91136 | G18: =IF(E18>D18,E18-D18,"") | J18: =F18 -> 91136
A19: 12 | B19: =+MAYORES!E29 -> MENTENIIENTO DE MUEBLES Y ENSERES | C19: E | D19: =+MAYORES!E30 -> 1044 | F19: =IF(D19>E19,D19-E19,"") -> 1044 | G19: =IF(E19>D19,E19-D19,"") | H19: =F19 -> 1044
A20: 13 | B20: =+MAYORES!H29 -> SEGURO PAGADO POR ADELANTADO | C20: A | D20: =+MAYORES!H30 -> 2088 | F20: =IF(D20>E20,D20-E20,"") -> 2088 | G20: =IF(E20>D20,E20-D20,"") | J20: =F20 -> 2088
A21: 14 | B21: =MAYORES!K29 -> VEHÍCULOS | C21: A | D21: =+MAYORES!K30 -> 95000 | F21: =IF(D21>E21,D21-E21,"") -> 95000 | G21: =IF(E21>D21,E21-D21,"") | J21: =F21 -> 95000
A22: 15 | B22: =MAYORES!N29 -> VENTAS | C22: I | E22: =+MAYORES!O30 -> 3306 | F22: =IF(D22>E22,D22-E22,"") | G22: =IF(E22>D22,E22-D22,"") -> 3306 | H22: =F22 | I22: =G22 -> 3306
A23: 16 | B23: =MAYORES!B37 -> CAPITAL SOCIAL | C23: PAT | E23: =+MAYORES!C38 -> 320000 | F23: =IF(D23>E23,D23-E23,"") | G23: =+E23 -> 320000 | K23: =E23 -> 320000
B24: SUMAS IGUALES | D24: =SUM(D8:D23) -> 424114 | E24: =SUM(E8:E23) -> 424114 | F24: =SUM(F8:F23) -> 406114 | G24: =SUM(G8:G23) -> 406114 | H24: =SUM(H8:H23) -> 8814 | I24: =SUM(I8:I23) -> 3306 | J24: =SUM(J8:J23) -> 397300 | K24: =SUM(K8:K23) -> 402808
B25: RESULTADO DEL PERIODO | I25: =H24-I24 -> 5508 | J25: =K24-J24 -> 5508
B26: SUMAS IGUALES | H26: =H24 -> 8814 | I26: =I24+I25 -> 8814 | J26: =J25+J24 -> 402808 | K26: =K24+K25 -> 402808

Sheet ESTADO DE RESULTADOS
B2: Empresa: LOS ROBLES LTDA.
B4: ESTADO DE RESULTADOS
B5: Del 01 al 30 de abril de 2023
B6: (Expresado en bolivianos)
B8: VENTAS NETAS | F8: =SUM(E9:E11) -> 3306
C9: Ventas | E9: =+MAYORES!O30 -> 3306
B10: (-) | C10: Devoluciones s/ventas | E10: 0
B11: (-) | C11: Descuento s/ventas | E11: 0
B13: COSTO DE VENTAS | F13: =SUM(E14) -> 0
C14: Costo de ventas | E14: 0
C16: UTILIDAD BRUTA EN VENTAS | F16: =F8-F13 -> 3306
B18: GASTOS OPERATIVOS | F18: =SUM(E19:E23) -> 8814
C19: =+MAYORES!N10 -> ASEO Y LIMPIEZA | E19: =+MAYORES!N11 -> 217.5
C20: ENERGIA ELECTRICA | E20: =+'BAL. SUMAS Y SALDOS - HOJA DE T'!H14 -> 478.5
C21: GASTOS LEGALES | E21: =+'BAL. SUMAS Y SALDOS - HOJA DE T'!H15 -> 6960
C22: MANTENIMIENTO MUEBLES Y ENSERES | E22: =+MAYORES!E30 -> 1044
C23: I.T. | E23: =+MAYORES!K24 -> 114
C25: UTILIDAD NETA | F25: =F16-F18 -> -5508
B27: (+) | C27: OTROS INGRESOS | F27: 0
C28: DESCUENTO EN COMPRAS | E28: 0
C30: PÉRDIDA DEL EJERCICIO | F30: =F25-F27 -> -5508
C35: GERENTE GENERAL | E35: CONTADOR

Sheet BALANCE GENERAL
B2: Empresa: LOS ANGELES S.A.
B4: BALANCE GENERAL
B5: Al 30 de abril de 2023
B6: (Expresado en bolivianos)
B8: ACTIVO
C9: ACTIVO CORRIENTE | F9: =SUM(E10:E14) -> 302300
C10: CAJA MN | E10: ='BAL. SUMAS Y SALDOS - HOJA DE T'!J9 -> 90550
C11: BANCO Mercantil Scz M/N | E11: ='BAL. SUMAS Y SALDOS - HOJA DE T'!J8 -> 115250
C12: CREDITO FISCAL | E12: =+'BAL. SUMAS Y SALDOS - HOJA DE T'!J11 -> 3276
C13: =+'BAL. SUMAS Y SALDOS - HOJA DE T'!B20 -> SEGURO PAGADO POR ADELANTADO | E13: =+'BAL. SUMAS Y SALDOS - HOJA DE T'!J20 -> 2088
C14: INVENTARIO DE MERCADERIAS | E14: =+'BAL. SUMAS Y SALDOS - HOJA DE T'!J18 -> 91136
C16: ACTIVO NO CORRIENTE | F16: =SUM(E17) -> 95000
C17: VEHÍCULOS | E17: =+'BAL. SUMAS Y SALDOS - HOJA DE T'!J21 -> 95000
C19: TOTAL ACTIVO | F19: =F9+F16 -> 397300
B21: PASIVO
C22: PASIVO CORRIENTE | F22: =SUM(E23:E25) -> 82808
C23: I.T. POR PAGAR | E23: =+'BAL. SUMAS Y SALDOS - HOJA DE T'!K17 -> 114
C24: =+'BAL. SUMAS Y SALDOS - HOJA DE T'!B13 -> DEBITO FISCAL | E24: =+'BAL. SUMAS Y SALDOS - HOJA DE T'!K13 -> 494
C25: CUENTAS POR PAGAR | E25: =+'BAL. SUMAS Y SALDOS - HOJA DE T'!K10 -> 82200
C27: PASIVO NO CORRIENTE | F27: =SUM(E28) -> 0
B30: PATRIMONIO
C31: CAPITAL | F31: =E32+E33 -> 314492
C32: CAPITAL SOCIAL | E32: =+'BAL. SUMAS Y SALDOS - HOJA DE T'!K23 -> 320000
C33: PÉRDIDA DEL EJERCICIO | E33: =+'ESTADO DE RESULTADOS'!F30 -> -5508
C36: TOTAL PASIVO Y PATRIMONIO | F36: =F22+F27+F31 -> 397300
C41: GERENTE GENERAL | E41: CONTADOR
